Workbook
Name ross: ' AUG IL'!$C$21
Name sam: ' AUG IL'!$C$22

Sheet  AUG AZ
A1: 46241
A3: ARIZONA DIV00 | H3: NET
C4: SALES $ | D4: COGS | E4: M/U | F4: RTNS | G4: COLLECTIONS | H4: SALES | I4: RTN %
A5: ADAM R | B5: A550 | C5: =6086+5275.96+4225 -> 15586.96 | D5: =3393+2361.7+2435 -> 8189.7 | E5: =C5/D5 -> 1.9032394 | F5: 0 | G5: =0 -> 0 | H5: =+C5-F5-G5 -> 15586.96 | I5: =F5/C5 -> 0
A6: LEANDER H | B6: A605 | C6: 0 | D6: 0 | E6: =C6/D6 -> #DIV/0! | F6: 0 | G6: =0 -> 0 | H6: =+C6-F6-G6 -> 0 | I6: =F6/C6 -> #DIV/0!
A7: JACOB M | B7: A607 | C7: =370+260 -> 630 | D7: =192+118 -> 310 | E7: =C7/D7 -> 2.0322581 | F7: 0 | G7: =0 -> 0 | H7: =+C7-F7-G7 -> 630 | I7: =F7/C7 -> 0
A8: CHARLES R | B8: A609 | C8: =140 -> 140 | D8: =57 -> 57 | E8: =C8/D8 -> 2.4561404 | F8: =0 -> 0 | G8: =0 -> 0 | H8: =+C8-F8-G8 -> 140
A9: LARRY A | B9: A654 | C9: =21933.1+6799.95+3052.5 -> 31785.55 | D9: =12005.25+3878+1893.2 -> 17776.45 | E9: =C9/D9 -> 1.7880707 | F9: 0 | G9: =0 -> 0 | H9: =+C9-F9-G9 -> 31785.55 | I9: =F9/C9 -> 0
A10: MARK F | B10: A701 | C10: =62.99+5250.49+1052 -> 6365.48 | D10: =33+2778.25+526 -> 3337.25 | E10: =C10/D10 -> 1.9074028 | F10: =195.96+33.98+197.94 -> 427.88 | G10: =0 -> 0 | H10: =+C10-F10-G10 -> 5937.6 | I10: =F10/C10 -> 0.067218811
A11: OLIN M | B11: A702 | C11: =772+2648+1320+6655 -> 11395 | D11: =370+1062+660.5+4220.5 -> 6313 | E11: =C11/D11 -> 1.8050055 | F11: 0 | G11: =0 -> 0 | H11: =+C11-F11-G11 -> 11395 | I11: =F11/C11 -> 0
A12: ALEX B | B12: A777 | C12: 0 | D12: 0 | E12: =C12/D12 -> #DIV/0! | F12: 0 | G12: =0 -> 0 | H12: =+C12-F12-G12 -> 0 | I12: =F12/C12 -> #DIV/0!
A13: AZ HOUSE | B13: A111 | C13: 0 | D13: 0 | E13: =C13/D13 -> #DIV/0! | F13: 0 | G13: =0 -> 0 | H13: =+C13-F13-G13 -> 0 | I13: =F13/C13 -> #DIV/0!
A14: TERM | C14: 0 | D14: 0 | E14: =C14/D14 -> #DIV/0! | F14: 0 | G14: =0 -> 0 | H14: =+C14-F14-G14 -> 0 | I14: =F14/C14 -> #DIV/0!
A15: AZ DIV 00 TOTAL | C15: =SUM(C5:C14) -> 65902.99 | D15: =SUM(D5:D14) -> 35983.4 | E15: =C15/D15 -> 1.8314831 | F15: =SUM(F5:F14) -> 427.88 | G15: =SUM(G5:G14) -> 0 | H15: =+C15-F15-G15 -> 65475.11 | I15: =F15/C15 -> 0.0064925734
A17: ARIZONA DIV22
A18: ADAM R | B18: A550 | C18: 0 | D18: 0 | E18: =C18/D18 -> #DIV/0! | F18: 0 | G18: 0 | H18: =+C18-F18-G18 -> 0 | I18: =F18/C18 -> #DIV/0!
A19: LARRY A | B19: A654 | C19: =289.8 -> 289.8 | D19: =170.4 -> 170.4 | E19: =C19/D19 -> 1.7007042 | F19: 0 | G19: 0 | H19: =+C19-F19-G19 -> 289.8 | I19: =F19/C19 -> 0
A20: MARK F | B20: A701 | C20: 0 | D20: 0 | E20: =C20/D20 -> #DIV/0! | F20: 0 | G20: 0 | H20: =+C20-F20-G20 -> 0 | I20: =F20/C20 -> #DIV/0!
A21: OLIN M | B21: A702 | C21: 0 | D21: 0 | E21: =C21/D21 -> #DIV/0! | F21: 0 | G21: 0 | H21: =+C21-F21-G21 -> 0 | I21: =F21/C21 -> #DIV/0!
A22: ALEX B | B22: A777 | C22: =972+65+764.25+8909+230 -> 10940.25 | D22: =565+42.5+467.67+4045.06+130 -> 5250.23 | E22: =C22/D22 -> 2.0837659 | F22: 0 | G22: 0 | H22: =+C22-F22-G22 -> 10940.25 | I22: =F22/C22 -> 0
A23: TERM | C23: 0 | D23: 0 | E23: =C23/D23 -> #DIV/0! | F23: 0 | G23: 0 | H23: =+C23-F23-G23 -> 0 | I23: =F23/C23 -> #DIV/0!
A24: AZ DIV 22 TOTAL | C24: =SUM(C18:C23) -> 11230.05 | D24: =SUM(D18:D23) -> 5420.63 | E24: =C24/D24 -> 2.0717241 | F24: =SUM(F18:F23) -> 0 | G24: =SUM(G18:G23) -> 0 | H24: =+C24-F24-G24 -> 11230.05 | I24: =F24/C24 -> 0
A26: AZ DIV 33
A27: ADAM R | B27: A550 | C27: 0 | D27: 0 | E27: =C27/D27 -> #DIV/0! | F27: 0 | G27: 0 | H27: =+C27-F27-G27 -> 0 | I27: =F27/C27 -> #DIV/0!
A28: MARK F | B28: A701 | C28: 0 | D28: 0 | E28: =C28/D28 -> #DIV/0! | F28: 0 | G28: 0 | H28: =+C28-F28-G28 -> 0 | I28: =F28/C28 -> #DIV/0!
A29: OLIN M | B29: A702 | C29: =1895.5 -> 1895.5 | D29: =1050.1 -> 1050.1 | E29: =C29/D29 -> 1.8050662 | F29: 0 | G29: 0 | H29: =+C29-F29-G29 -> 1895.5 | I29: =F29/C29 -> 0
A30: AZ DIV 33 TOTAL | C30: =SUM(C27:C29) -> 1895.5 | D30: =SUM(D27:D29) -> 1050.1 | E30: =C30/D30 -> 1.8050662 | F30: 0 | G30: 0 | H30: =SUM(H27:H29) -> 1895.5 | I30: =F30/C30 -> 0
A32: TOTAL AZ | C32: =C30+C24+C15 -> 79028.54 | D32: =D30+D24+D15 -> 42454.13 | E32: =C32/D32 -> 1.8615042 | F32: =F30+F24+F15 -> 427.88 | G32: =G30+G24+G15 -> 0 | H32: =+C32-F32-G32 -> 78600.66 | I32: =F32/C32 -> 0.0054142465

Sheet  AUG IL
A1: =' AUG AZ'!A1 -> 46241
A3: ILLINOIS DIV00 | H3: NET
C4: SALES | D4: COGS | E4: M/U | F4: RTNS | G4: COLLECTIONS | H4: SALES | I4: RTN %
A5: HOUSE | B5: I001 | C5: 0 | D5: =50 -> 50 | E5: =C5/D5 -> 0 | F5: 0 | G5: 0 | H5: =C5-F5-G5 -> 0 | I5: =F5/C5 -> #DIV/0!
A6: TOM C | B6: I033 | C6: 0 | D6: 0 | E6: =C6/D6 -> #DIV/0! | F6: 0 | G6: 0 | H6: =C6-F6-G6 -> 0 | I6: =F6/C6 -> #DIV/0!
A7: JASON M | B7: I069 | C7: 0 | D7: 0 | E7: =C7/D7 -> #DIV/0! | F7: 0 | G7: 0 | H7: =C7-F7-G7 -> 0 | I7: =F7/C7 -> #DIV/0!
A8: FRANK S | B8: I155 | C8: 0 | D8: 0 | E8: =C8/D8 -> #DIV/0! | F8: 0 | G8: 0 | H8: =C8-F8-G8 -> 0 | I8: =F8/C8 -> #DIV/0!
A9: JORDAN M | B9: I272 | C9: =10395.2+7358.55+3961+15355.5+4783.8 -> 41854.05 | D9: =6906.5+5230+2642.78+10082+2823.06 -> 27684.34 | E9: =C9/D9 -> 1.5118312 | F9: 0 | G9: 0 | H9: =C9-F9-G9 -> 41854.05 | I9: =F9/C9 -> 0
A10: JIMMY M | B10: I281 | C10: =1379+1485 -> 2864 | D10: =1221+847 -> 2068 | E10: =C10/D10 -> 1.384913 | F10: =1375 -> 1375 | G10: 0 | H10: =C10-F10-G10 -> 1489 | I10: =F10/C10 -> 0.48009777
A11: CHRIS Z | B11: I393 | C11: =35526.06+20063.65+13666.05+10104.6+5086 -> 84446.36 | D11: =23141.1+12090.25+9032.28+6675.7+3203 -> 54142.33 | E11: =C11/D11 -> 1.5597105 | F11: 0 | G11: 0 | H11: =C11-F11-G11 -> 84446.36 | I11: =F11/C11 -> 0
A12: JEFF J | B12: I436 | C12: =15050+1989.99+10604.8+3395 -> 31039.79 | D12: =9592+1468+6661.5+2118 -> 19839.5 | E12: =C12/D12 -> 1.564545 | F12: 0 | G12: 0 | H12: =C12-F12-G12 -> 31039.79 | I12: =F12/C12 -> 0
A13: IAIR Z | B13: I462 | C13: 0 | D13: 0 | E13: =C13/D13 -> #DIV/0! | F13: 0 | G13: 0 | H13: =C13-F13-G13 -> 0 | I13: =F13/C13 -> #DIV/0!
A14: RICO C | B14: I478 | C14: =5083.2 -> 5083.2 | D14: =2972 -> 2972 | E14: =C14/D14 -> 1.7103634 | F14: 0 | G14: 0 | H14: =C14-F14-G14 -> 5083.2 | I14: =F14/C14 -> 0
A15: DAN M | B15: I501 | C15: =6401+6937.8+3305.5+7658.6+8498 -> 32800.9 | D15: =3771+4735.2+2351+5532.4+6380.68 -> 22770.28 | E15: =C15/D15 -> 1.4405137 | F15: 0 | G15: 0 | H15: =C15-F15-G15 -> 32800.9 | I15: =F15/C15 -> 0
A16: CHRIS T | B16: I664 | C16: =5869.8+367.5 -> 6237.3 | D16: =3609+232.5 -> 3841.5 | E16: =C16/D16 -> 1.6236626 | F16: 0 | G16: 0 | H16: =C16-F16-G16 -> 6237.3 | I16: =F16/C16 -> 0
A17: MARK S | B17: I729 | C17: 0 | D17: 0 | E17: =C17/D17 -> #DIV/0! | F17: 0 | G17: 0 | H17: =C17-F17-G17 -> 0 | I17: =F17/C17 -> #DIV/0!
A18: JAY M | B18: I769 | C18: 0 | D18: 0 | E18: =C18/D18 -> #DIV/0! | F18: 0 | G18: 0 | H18: =C18-F18-G18 -> 0 | I18: =F18/C18 -> #DIV/0!
A19: AL S | B19: I801 | C19: =3250 -> 3250 | D19: =2489 -> 2489 | E19: =C19/D19 -> 1.3057453 | F19: 0 | G19: 0 | H19: =C19-F19-G19 -> 3250 | I19: =F19/C19 -> 0
A20: SAMUEL J | B20: I815 | C20: =1439.91+1478+177+15117.5 -> 18212.41 | D20: =795+871+117+10500.5 -> 12283.5 | E20: =C20/D20 -> 1.4826727 | F20: 0 | G20: 0 | H20: =C20-F20-G20 -> 18212.41 | I20: =F20/C20 -> 0
A21: DAVID S | B21: I830 | C21: 0 | D21: 0 | E21: =C21/D21 -> #DIV/0! | F21: 0 | G21: 0 | H21: =C21-F21-G21 -> 0 | I21: =F21/C21 -> #DIV/0!
A22: ROSS S | B22: I848 | C22: =1175+175 -> 1350 | D22: =564+96 -> 660 | E22: =C22/D22 -> 2.0454545 | F22: 0 | G22: 0 | H22: =C22-F22-G22 -> 1350 | I22: =F22/C22 -> 0
A23: CARL L | B23: I850 | C23: 0 | D23: 0 | E23: =C23/D23 -> #DIV/0! | F23: =554.95 -> 554.95 | G23: 0 | H23: =C23-F23-G23 -> -554.95 | I23: =F23/C23 -> #DIV/0!
A24: ANTOINETTE V | B24: I856 | C24: =567.95+293.97+281.97 -> 1143.89 | D24: =344.5+171+171 -> 686.5 | E24: =C24/D24 -> 1.6662637 | F24: 0 | G24: 0 | H24: =C24-F24-G24 -> 1143.89 | I24: =F24/C24 -> 0
A25: JAVIER C | B25: I865 | C25: =1188+3985.5+1276.5+951 -> 7401 | D25: =702+2339+634.5+541.5 -> 4217 | E25: =C25/D25 -> 1.7550391 | F25: 0 | G25: 0 | H25: =C25-F25-G25 -> 7401 | I25: =F25/C25 -> 0
A26: TIMOTHY C | B26: I867 | C26: =1020+93+504+322.5+351 -> 2290.5 | D26: =512+57+298.5+202.5+199.5 -> 1269.5 | E26: =C26/D26 -> 1.8042536 | F26: 0 | G26: 0 | H26: =C26-F26-G26 -> 2290.5 | I26: =F26/C26 -> 0
A27: KELLSTEIN G | B27: I879 | C27: 0 | D27: 0 | E27: =C27/D27 -> #DIV/0! | F27: 0 | G27: 0 | H27: =C27-F27-G27 -> 0 | I27: =F27/C27 -> #DIV/0!
A28: JOSE S | B28: I887 | C28: 0 | D28: 0 | E28: =C28/D28 -> #DIV/0! | F28: 0 | G28: 0 | H28: =C28-F28-G28 -> 0 | I28: =F28/C28 -> #DIV/0!
A29: BRONSON B | B29: I893 | C29: =230 -> 230 | D29: =86 -> 86 | E29: =C29/D29 -> 2.6744186 | F29: 0 | G29: 0 | H29: =C29-F29-G29 -> 230 | I29: =F29/C29 -> 0
A30: NICO L | B30: I896 | C30: 0 | D30: 0 | E30: =C30/D30 -> #DIV/0! | F30: 0 | G30: 0 | H30: =C30-F30-G30 -> 0 | I30: =F30/C30 -> #DIV/0!
A31: VINCENZO G | B31: I897 | C31: 0 | D31: 0 | E31: =C31/D31 -> #DIV/0! | F31: 0 | G31: 0 | H31: =C31-F31-G31 -> 0 | I31: =F31/C31 -> #DIV/0!
A32: MARTIN A | B32: I898 | C32: =199 -> 199 | D32: =145 -> 145 | E32: =C32/D32 -> 1.3724138 | F32: 0 | G32: 0 | H32: =C32-F32-G32 -> 199 | I32: =F32/C32 -> 0
A33: MATT G | B33: I902 | C33: 0 | D33: 0 | E33: =C33/D33 -> #DIV/0! | F33: 0 | G33: 0 | H33: =C33-F33-G33 -> 0 | I33: =F33/C33 -> #DIV/0!
A34: JERRY S | B34: I924 | C34: 0 | D34: 0 | E34: =C34/D34 -> #DIV/0! | F34: 0 | G34: 0 | H34: =C34-F34-G34 -> 0 | I34: =F34/C34 -> #DIV/0!
A35: TERM S/P | C35: 0 | D35: 0 | E35: =C35/D35 -> #DIV/0! | F35: =1199.85 -> 1199.85 | G35: 0 | H35: =C35-F35-G35 -> -1199.85 | I35: =F35/C35 -> #DIV/0!
A36: IL DIV 00 TOTAL | C36: =SUM(C5:C35) -> 238402.4 | D36: =SUM(D5:D35) -> 155204.45 | E36: =C36/D36 -> 1.5360539 | F36: =SUM(F5:F35) -> 3129.8 | G36: =SUM(G5:G35) -> 0 | H36: =C36-F36-G36 -> 235272.6 | I36: =F36/C36 -> 0.013128224
A38: ILLINOIS DIV22
A39: TOM C | B39: I033 | C39: 0 | D39: 0 | E39: =C39/D39 -> #DIV/0! | F39: 0 | G39: 0 | H39: =C39-F39-G39 -> 0 | I39: =F39/C39 -> #DIV/0!
A40: JASON M | B40: I069 | C40: 0 | D40: 0 | E40: =C40/D40 -> #DIV/0! | F40: 0 | G40: 0 | H40: =C40-F40-G40 -> 0 | I40: =F40/C40 -> #DIV/0!
A41: JORDAN M. | B41: I272 | C41: =2400 -> 2400 | D41: =1800 -> 1800 | E41: =C41/D41 -> 1.3333333 | F41: 0 | G41: 0 | H41: =C41-F41-G41 -> 2400 | I41: =F41/C41 -> 0
A42: JIMMY M | B42: I281 | C42: =945.74+3587.5+341.7+3937+3732.89 -> 12544.83 | D42: =594.1+2270.98+201+2545.1+2091.6 -> 7702.78 | E42: =C42/D42 -> 1.6286107 | F42: 0 | G42: 0 | H42: =C42-F42-G42 -> 12544.83 | I42: =F42/C42 -> 0
...

Sheet AUG WI
A1: =+' AUG AZ'!A1 -> 46241
A3: WISCONSIN DIV00 | H3: NET
C4: SALES $ | D4: COGS | E4: M/U | F4: RTNS | G4: COLLECTIONS | H4: SALES | I4: RTN %
A5: ADAM W | B5: W603 | C5: =2394+3272.88 -> 5666.88 | D5: =1007+1846 -> 2853 | E5: =C5/D5 -> 1.9862881 | F5: 0 | G5: 0 | H5: =C5-F5-G5 -> 5666.88 | I5: =F5/C5 -> 0
A6: KERRY S | B6: W762 | C6: =712.2 -> 712.2 | D6: =376 -> 376 | E6: =C6/D6 -> 1.8941489 | F6: 0 | G6: 0 | H6: =C6-F6-G6 -> 712.2 | I6: =F6/C6 -> 0
A7: JUSTIN | B7: W784 | C7: =16719.78+165+5760+9198.25 -> 31843.03 | D7: =9504+88+3840+6799 -> 20231 | E7: =C7/D7 -> 1.5739721 | F7: 0 | G7: 0 | H7: =C7-F7-G7 -> 31843.03 | I7: =F7/C7 -> 0
A8: RON B | B8: W839 | C8: =24820+16829.5+3742.5+3305+3228 -> 51925 | D8: =14590+10177+2086.42+2015.5+2148 -> 31016.92 | E8: =C8/D8 -> 1.6740863 | F8: 0 | G8: 0 | H8: =C8-F8-G8 -> 51925 | I8: =F8/C8 -> 0
A9: JOHN B | B9: W849 | C9: =7629.75+4039.04+1385.79 -> 13054.58 | D9: =5515+2021+505.8 -> 8041.8 | E9: =C9/D9 -> 1.6233405 | F9: 0 | G9: 0 | H9: =C9-F9-G9 -> 13054.58 | I9: =F9/C9 -> 0
A10: LUIS M | B10: W909 | C10: =3866.2 -> 3866.2 | D10: =2274 -> 2274 | E10: =C10/D10 -> 1.7001759 | F10: 0 | G10: 0 | H10: =C10-F10-G10 -> 3866.2 | I10: =F10/C10 -> 0
A11: ADAM M | B11: W930 | C11: =4049.99+4354.82+18219.85+799.99 -> 27424.65 | D11: =1298+2086.8+10457+335 -> 14176.8 | E11: =C11/D11 -> 1.9344739 | F11: 0 | G11: 0 | H11: =C11-F11-G11 -> 27424.65 | I11: =F11/C11 -> 0
A12: LES K | B12: W934 | C12: =548.97+3580 -> 4128.97 | D12: =249+1945 -> 2194 | E12: =C12/D12 -> 1.8819371 | F12: 0 | G12: 0 | H12: =C12-F12-G12 -> 4128.97 | I12: =F12/C12 -> 0
A13: GEOFFREY N | B13: W938 | C13: 0 | D13: 0 | E13: =C13/D13 -> #DIV/0! | F13: 0 | G13: 0 | H13: =C13-F13-G13 -> 0 | I13: =F13/C13 -> #DIV/0!
A14: JAMEL L | B14: W953 | C14: 0 | D14: 0 | E14: =C14/D14 -> #DIV/0! | F14: 0 | G14: 0 | H14: =C14-F14-G14 -> 0 | I14: =F14/C14 -> #DIV/0!
A15: CASSANDRA K | B15: W959 | C15: 0 | D15: 0 | E15: =C15/D15 -> #DIV/0! | F15: 0 | G15: 0 | H15: =C15-F15-G15 -> 0 | I15: =F15/C15 -> #DIV/0!
A16: CHRIS K | B16: W962 | C16: =546+853.8+799.95+847 -> 3046.75 | D16: =318+418.8+480+305.25 -> 1522.05 | E16: =C16/D16 -> 2.0017411 | F16: 0 | G16: 0 | H16: =C16-F16-G16 -> 3046.75 | I16: =F16/C16 -> 0
A17: NICO T | B17: W963 | C17: 0 | D17: 0 | E17: =C17/D17 -> #DIV/0! | F17: 0 | G17: 0 | H17: =C17-F17-G17 -> 0 | I17: =F17/C17 -> #DIV/0!
A18: BLAKE M | B18: W966 | C18: 0 | D18: 0 | E18: =C18/D18 -> #DIV/0! | F18: 0 | G18: 0 | H18: =C18-F18-G18 -> 0 | I18: =F18/C18 -> #DIV/0!
A19: JAMES B | B19: W967 | C19: 0 | D19: 0 | E19: =C19/D19 -> #DIV/0! | F19: 0 | G19: 0 | H19: =C19-F19-G19 -> 0 | I19: =F19/C19 -> #DIV/0!
A20: ANTHONYS | B20: W973 | C20: 0 | D20: 0 | E20: =C20/D20 -> #DIV/0! | F20: 0 | G20: 0 | H20: =C20-F20-G20 -> 0 | I20: =F20/C20 -> #DIV/0!
A21: SCOT T | B21: W983 | C21: =5144+4249.75+550+1198.52 -> 11142.27 | D21: =3721+2435+180+602.9 -> 6938.9 | E21: =C21/D21 -> 1.6057689 | F21: 0 | G21: 0 | H21: =C21-F21-G21 -> 11142.27 | I21: =F21/C21 -> 0
A22: TERMINATED | C22: 0 | D22: 0 | E22: =C22/D22 -> #DIV/0! | F22: 0 | G22: 0 | H22: =C22-F22-G22 -> 0 | I22: =F22/C22 -> #DIV/0!
A23: WI DIV 00 TOTAL | C23: =SUM(C5:C22) -> 152810.53 | D23: =SUM(D5:D22) -> 89624.47 | E23: =C23/D23 -> 1.705009 | F23: =SUM(F5:F22) -> 0 | G23: =SUM(G5:G22) -> 0 | H23: =C23-F23-G23 -> 152810.53 | I23: =F23/C23 -> 0
A25: WISCONSIN DIV22
A26: ADAM W | B26: W603 | C26: 0 | D26: 0 | E26: =C26/D26 -> #DIV/0! | F26: 0 | G26: 0 | H26: =C26-F26-G26 -> 0 | I26: =F26/C26 -> #DIV/0!
A27: KERRY S | B27: W762 | C27: 0 | D27: 0 | E27: =C27/D27 -> #DIV/0! | F27: 0 | G27: 0 | H27: =C27-F27-G27 -> 0 | I27: =F27/C27 -> #DIV/0!
A28: JUSTIN G | B28: W784 | C28: =899.9 -> 899.9 | D28: =383 -> 383 | E28: =C28/D28 -> 2.3496084 | F28: 0 | G28: 0 | H28: =C28-F28-G28 -> 899.9 | I28: =F28/C28 -> 0
A29: RONALD B | B29: W839 | C29: 0 | D29: 0 | E29: =C29/D29 -> #DIV/0! | F29: 0 | G29: 0 | H29: =C29-F29-G29 -> 0 | I29: =F29/C29 -> #DIV/0!
A30: JOHN B | B30: W849 | C30: 0 | D30: 0 | E30: =C30/D30 -> #DIV/0! | F30: 0 | G30: 0 | H30: =C30-F30-G30 -> 0 | I30: =F30/C30 -> #DIV/0!
A31: FOREST C | B31: W923 | C31: 0 | D31: 0 | E31: =C31/D31 -> #DIV/0! | F31: 0 | G31: 0 | H31: =C31-F31-G31 -> 0 | I31: =F31/C31 -> #DIV/0!
A32: ADAM M | B32: W930 | C32: 0 | D32: 0 | E32: =C32/D32 -> #DIV/0! | F32: 0 | G32: 0 | H32: =C32-F32-G32 -> 0 | I32: =F32/C32 -> #DIV/0!
A33: LES K | B33: W934 | C33: 0 | D33: 0 | E33: =C33/D33 -> #DIV/0! | F33: 0 | G33: 0 | H33: =C33-F33-G33 -> 0 | I33: =F33/C33 -> #DIV/0!
A34: GEOFFREY N | B34: W938 | C34: 0 | D34: 0 | E34: =C34/D34 -> #DIV/0! | F34: 0 | G34: 0 | H34: =C34-F34-G34 -> 0 | I34: =F34/C34 -> #DIV/0!
A35: ANTHONYS | B35: W973 | C35: 0 | D35: 0 | E35: =C35/D35 -> #DIV/0! | F35: 0 | G35: 0 | H35: =C35-F35-G35 -> 0 | I35: =F35/C35 -> #DIV/0!
A36: SCOT T | B36: W983 | C36: =1069.2 -> 1069.2 | D36: =712.8 -> 712.8 | E36: =C36/D36 -> 1.5 | F36: 0 | G36: 0 | H36: =C36-F36-G36 -> 1069.2 | I36: =F36/C36 -> 0
A37: TERM | C37: 0 | D37: 0 | E37: =C37/D37 -> #DIV/0! | F37: 0 | G37: 0 | H37: =C37-F37-G37 -> 0 | I37: =F37/C37 -> #DIV/0!
A38: WI DIV 22 TOTAL | C38: =SUM(C26:C37) -> 1969.1 | D38: =SUM(D26:D37) -> 1095.8 | E38: =C38/D38 -> 1.796952 | F38: =SUM(F26:F37) -> 0 | G38: =SUM(G26:G37) -> 0 | H38: =C38-F38-G38 -> 1969.1 | I38: =F38/C38 -> 0
A40: WISCONSIN DIV33
A41: ADAM W | B41: W603 | C41: 0 | D41: 0 | E41: =C41/D41 -> #DIV/0! | F41: 0 | G41: 0 | H41: =C41-F41-G41 -> 0 | I41: =F41/C41 -> #DIV/0!
A42: KERRY S | B42: W762 | C42: 0 | D42: 0 | E42: =C42/D42 -> #DIV/0! | F42: 0 | G42: 0 | H42: =C42-F42-G42 -> 0 | I42: =F42/C42 -> #DIV/0!
A43: FRANK G | B43: W784 | C43: 0 | D43: 0 | E43: =C43/D43 -> #DIV/0! | F43: 0 | G43: 0 | H43: =C43-F43-G43 -> 0 | I43: =F43/C43 -> #DIV/0!
...

Sheet AUG 2026 Div Totals
A4: =+' AUG AZ'!A1 -> 46241 | H4: NET
C5: SALES | D5: COGS | E5: M/U | F5: RETURNS | G5: COLLECTIONS | H5: SALES | I5: RTN %
A7: DBW | C7: =+' AUG AZ'!C15+' AUG IL'!C36+'AUG WI'!C23 -> 457115.92 | D7: =+' AUG AZ'!D15+' AUG IL'!D36+'AUG WI'!D23 -> 280812.32 | E7: =+C7/D7 -> 1.6278343 | F7: =+' AUG AZ'!F15+' AUG IL'!F36+'AUG WI'!F23 -> 3557.68 | G7: =' AUG AZ'!G15+' AUG IL'!G36+'AUG WI'!G23 -> 0 | H7: =+C7-F7-G7 -> 453558.24 | I7: =+F7/C7 -> 0.0077828836
A9: HELIX | C9: =+' AUG AZ'!C24+' AUG IL'!C68+'AUG WI'!C38 -> 82181.85 | D9: =+' AUG AZ'!D24+' AUG IL'!D68+'AUG WI'!D38 -> 49440.01 | E9: =+C9/D9 -> 1.6622539 | F9: =+' AUG AZ'!F24+' AUG IL'!F68+'AUG WI'!F38 -> 929.9 | G9: =+' AUG AZ'!G24+' AUG IL'!G68+'AUG WI'!G38 -> 0 | H9: =+C9-F9-G9 -> 81251.95 | I9: =+F9/C9 -> 0.01131515
A11: HELIX FLOORS | C11: =' AUG IL'!C89+' AUG AZ'!C30+'AUG WI'!C49 -> 28219.95 | D11: =' AUG IL'!D89+' AUG AZ'!D30+'AUG WI'!D49 -> 16572.09 | E11: =+C11/D11 -> 1.70286 | F11: =' AUG IL'!F89+' AUG AZ'!F30+'AUG WI'!F51 -> 1879 | G11: =' AUG IL'!G89+' AUG AZ'!G30+'AUG WI'!G49 -> 0 | H11: =+C11-F11-G11 -> 26340.95 | I11: =+F11/C11 -> 0.066584101
A13: HELIX TOOLING | C13: =+'AUG WI'!C57 -> 0 | D13: =+'AUG WI'!D57 -> 0 | E13: =+C13/D13 -> #DIV/0! | F13: =+'AUG WI'!F57 -> 0 | G13: =+'AUG WI'!G57 -> 0 | H13: =+C13-F13-G13 -> 0 | I13: =+F13/C13 -> #DIV/0!
A15: 4COREBIZ | C15: =' AUG IL'!C97 -> 17483.1 | D15: =' AUG IL'!D97 -> 10300 | E15: =' AUG IL'!E97 -> 1.6973883 | F15: =' AUG IL'!F97 -> 0 | G15: =' AUG IL'!G97 -> 0 | H15: =+C15-F15-G15 -> 17483.1 | I15: =' AUG IL'!I92 -> 0
A17: STRATUS | C17: =+' AUG IL'!C104 -> 2259.88 | D17: =+' AUG IL'!D104 -> 1119 | E17: =+C17/D17 -> 2.0195532 | F17: =+' AUG IL'!F104 -> 0 | G17: =+' AUG IL'!G104 -> 0 | H17: =+C17-F17-G17 -> 2259.88 | I17: =+F17/C17 -> 0
A19: TOTAL | C19: =SUM(C3:C18) -> 587260.7 | D19: =SUM(D3:D18) -> 358243.42 | E19: =C19/D19 -> 1.6392784 | F19: =SUM(F3:F18) -> 6366.58 | G19: =SUM(G3:G18) -> 0 | H19: =+C19-F19-G19 -> 580894.12 | I19: =+F19/C19 -> 0.010841148
D59: =60027.25+0.25+80760.66+0.56+67271.79+0.27+81921.85+0.5+92023.63+0.02+97834.55+0.37+109385.67+0.56+84643.82+0.12+78182.76+0.19+60257.96+0.8+102419.9+0.24+109077.88-11838.27+64161.9+0.12+79479.04+0.55+88154.63+0.05 -> 1243769.6
A71: W/D 8/22
A72: RETURNS 12/27 | B72: -2939

Sheet INDIVIDUAL NET TOTALS 
A1: =' AUG AZ'!A1 -> 46241
A4: AZ SALESMEN | C4: SALES | D4: COGS | E4: M/U | F4: RETURNS | G4: COLLECTIONS | H4: NET SALES
A5: ADAM R | B5: A550 | C5: =' AUG AZ'!C5+' AUG AZ'!C18+' AUG AZ'!C27 -> 15586.96 | D5: =' AUG AZ'!D5+' AUG AZ'!D18+' AUG AZ'!D27 -> 8189.7 | E5: =SUM(C5/D5) -> 1.9032394 | F5: =' AUG AZ'!F5+' AUG AZ'!F18+' AUG AZ'!F27 -> 0 | G5: =' AUG AZ'!G5+' AUG AZ'!G18+' AUG AZ'!G27 -> 0 | H5: =' AUG AZ'!H5+' AUG AZ'!H18+' AUG AZ'!H27 -> 15586.96
A6: LEANDER H | B6: A605 | C6: =' AUG AZ'!C6 -> 0 | D6: =' AUG AZ'!D6 -> 0 | E6: =SUM(C6/D6) -> #DIV/0! | F6: =' AUG AZ'!F6 -> 0 | G6: =' AUG AZ'!G6 -> 0 | H6: =' AUG AZ'!H6 -> 0
A7: JACOB M | B7: A607 | C7: =' AUG AZ'!C7 -> 630 | D7: =' AUG AZ'!D7 -> 310 | E7: =SUM(C7/D7) -> 2.0322581 | F7: =' AUG AZ'!F7 -> 0 | G7: =' AUG AZ'!G7 -> 0 | H7: =' AUG AZ'!H7 -> 630
A8: CHARLES R | B8: A609 | C8: =' AUG AZ'!C8 -> 140 | D8: =' AUG AZ'!D8 -> 57 | E8: =SUM(C8/D8) -> 2.4561404 | F8: =' AUG AZ'!F8 -> 0 | G8: =' AUG AZ'!G8 -> 0 | H8: =' AUG AZ'!H8 -> 140
A9: LARRY A | B9: A654 | C9: =' AUG AZ'!C9+' AUG AZ'!C19 -> 32075.35 | D9: =' AUG AZ'!D9+' AUG AZ'!D19 -> 17946.85 | E9: =SUM(C9/D9) -> 1.7872412 | F9: =' AUG AZ'!F9+' AUG AZ'!F19 -> 0 | G9: =' AUG AZ'!G9+' AUG AZ'!G19 -> 0 | H9: =' AUG AZ'!H9+' AUG AZ'!H19 -> 32075.35
A10: MARK F | B10: A701 | C10: =' AUG AZ'!C10+' AUG AZ'!C20+' AUG AZ'!C28 -> 6365.48 | D10: =' AUG AZ'!D10+' AUG AZ'!D20+' AUG AZ'!D28 -> 3337.25 | E10: =SUM(C10/D10) -> 1.9074028 | F10: =' AUG AZ'!F10+' AUG AZ'!F20+' AUG AZ'!F28 -> 427.88 | G10: =' AUG AZ'!G10+' AUG AZ'!G20+' AUG AZ'!G28 -> 0 | H10: =' AUG AZ'!H10+' AUG AZ'!H20+' AUG AZ'!H28 -> 5937.6
A11: OLIN M | B11: A702 | C11: =' AUG AZ'!C11+' AUG AZ'!C21+' AUG AZ'!C29 -> 13290.5 | D11: =' AUG AZ'!D11+' AUG AZ'!D21+' AUG AZ'!D29 -> 7363.1 | E11: =SUM(C11/D11) -> 1.8050142 | F11: =' AUG AZ'!F11+' AUG AZ'!F21+' AUG AZ'!F29 -> 0 | G11: =' AUG AZ'!G11+' AUG AZ'!G21+' AUG AZ'!G29 -> 0 | H11: =' AUG AZ'!H11+' AUG AZ'!H21+' AUG AZ'!H29 -> 13290.5
A12: ALEX B | B12: A777 | C12: =' AUG AZ'!C12+' AUG AZ'!C22 -> 10940.25 | D12: =' AUG AZ'!D12+' AUG AZ'!D22 -> 5250.23 | E12: =SUM(C12/D12) -> 2.0837659 | F12: =' AUG AZ'!F12+' AUG AZ'!F22 -> 0 | G12: =' AUG AZ'!G12+' AUG AZ'!G22 -> 0 | H12: =' AUG AZ'!H12+' AUG AZ'!H22 -> 10940.25
A13: AZ HOUSE | B13: A111 | C13: =' AUG AZ'!C13 -> 0 | D13: =' AUG AZ'!D13 -> 0 | E13: =SUM(C13/D13) -> #DIV/0! | F13: =' AUG AZ'!F13 -> 0 | G13: =' AUG AZ'!G13 -> 0 | H13: =' AUG AZ'!H13 -> 0
A14: TERM | C14: =' AUG AZ'!C14 -> 0 | D14: =' AUG AZ'!D14 -> 0 | F14: =' AUG AZ'!F14 -> 0 | G14: =' AUG AZ'!G14 -> 0 | H14: =' AUG AZ'!H14 -> 0
A15: AZ TOTALS | C15: =SUM(C5:C14) -> 79028.54 | D15: =SUM(D5:D14) -> 42454.13 | E15: =+C15/D15 -> 1.8615042 | F15: =SUM(F5:F14) -> 427.88 | G15: =SUM(G5:G14) -> 0 | H15: =SUM(H5:H14) -> 78600.66
A18: IL SALESMEN | C18: SALES | D18: COGS | E18: M/U | F18: RETURNS | G18: COLLECTIONS | H18: NET SALES
A19: HOUSE | B19: I001 | C19: =' AUG IL'!C5 -> 0 | D19: =' AUG IL'!D5 -> 50 | E19: =SUM(C19/D19) -> 0 | F19: =' AUG IL'!F5 -> 0 | G19: =' AUG IL'!G5 -> 0 | H19: =' AUG IL'!H5 -> 0
A20: TOM C | B20: I033 | C20: =' AUG IL'!C6+' AUG IL'!C39+' AUG IL'!C101+' AUG IL'!C72 -> 0 | D20: =' AUG IL'!D6+' AUG IL'!D39+' AUG IL'!D101+' AUG IL'!D72 -> 0 | E20: =SUM(C20/D20) -> #DIV/0! | F20: =' AUG IL'!F6+' AUG IL'!F39+' AUG IL'!F100+' AUG IL'!F72 -> 0 | G20: =' AUG IL'!G6+' AUG IL'!G39+' AUG IL'!G100+' AUG IL'!G72 -> 0 | H20: =' AUG IL'!H6+' AUG IL'!H39+' AUG IL'!H100+' AUG IL'!H101+' AUG IL'!H72 -> 0
A21: JASON M | B21: I069 | C21: =+' AUG IL'!C7+' AUG IL'!C40 -> 0 | D21: =' AUG IL'!D7+' AUG IL'!D40 -> 0 | E21: =SUM(C21/D21) -> #DIV/0! | F21: =+' AUG IL'!F7+' AUG IL'!F40 -> 0 | G21: =+' AUG IL'!G7+' AUG IL'!G40 -> 0 | H21: =' AUG IL'!H7+' AUG IL'!H40 -> 0
A22: FRANK S | B22: I155 | C22: =' AUG IL'!C8 -> 0 | D22: =' AUG IL'!D8 -> 0 | E22: =SUM(C22/D22) -> #DIV/0! | F22: =' AUG IL'!F8 -> 0 | G22: =' AUG IL'!G8 -> 0 | H22: =' AUG IL'!H8 -> 0
A23: JORDAN M | B23: I272 | C23: =' AUG IL'!C9+' AUG IL'!C41+' AUG IL'!C73 -> 49573.6 | D23: =' AUG IL'!D9+' AUG IL'!D41+' AUG IL'!D73 -> 32769.76 | E23: =SUM(C23/D23) -> 1.512785 | F23: =' AUG IL'!F9+' AUG IL'!F41+' AUG IL'!F73 -> 0 | G23: =' AUG IL'!G9+' AUG IL'!G41+' AUG IL'!G73 -> 0 | H23: =' AUG IL'!H9+' AUG IL'!H41+' AUG IL'!H73 -> 49573.6
A24: JIMMY M | B24: I281 | C24: =' AUG IL'!C10+' AUG IL'!C42+' AUG IL'!C74 -> 15408.83 | D24: =' AUG IL'!D10+' AUG IL'!D42+' AUG IL'!D74 -> 9770.78 | E24: =SUM(C24/D24) -> 1.5770317 | F24: =' AUG IL'!F10+' AUG IL'!F42+' AUG IL'!F74 -> 1375 | G24: =' AUG IL'!G10+' AUG IL'!G42+' AUG IL'!G74 -> 0 | H24: =' AUG IL'!H10+' AUG IL'!H42+' AUG IL'!H74 -> 14033.83
A25: CHRIS Z | B25: I393 | C25: =' AUG IL'!C11+' AUG IL'!C43+' AUG IL'!C75+' AUG IL'!C102+' AUG IL'!C93 -> 84446.36 | D25: =' AUG IL'!D11+' AUG IL'!D43+' AUG IL'!D75+' AUG IL'!D102+' AUG IL'!D93 -> 54142.33 | E25: =SUM(C25/D25) -> 1.5597105 | F25: =' AUG IL'!F11+' AUG IL'!F43+' AUG IL'!F75+' AUG IL'!F93 -> 0 | G25: =' AUG IL'!G11+' AUG IL'!G43+' AUG IL'!G75+' AUG IL'!G93 -> 0 | H25: =' AUG IL'!H11+' AUG IL'!H43+' AUG IL'!H75+' AUG IL'!H102+' AUG IL'!H93 -> 84446.36
A26: JEFF J | B26: I436 | C26: =' AUG IL'!C12+' AUG IL'!C44+' AUG IL'!C76+' AUG IL'!C103 -> 33362.02 | D26: =' AUG IL'!D12+' AUG IL'!D44+' AUG IL'!D76+' AUG IL'!D103 -> 20996.63 | E26: =SUM(C26/D26) -> 1.5889226 | F26: =' AUG IL'!F12+' AUG IL'!F76 -> 0 | G26: =' AUG IL'!G12+' AUG IL'!G76 -> 0 | H26: =' AUG IL'!H12+' AUG IL'!H44+' AUG IL'!H76+' AUG IL'!H103 -> 33362.02
A27: IAIR Z | B27: I462 | C27: =' AUG IL'!C13+' AUG IL'!C45 -> 0 | D27: =' AUG IL'!D13+' AUG IL'!D45 -> 0 | E27: =SUM(C27/D27) -> #DIV/0! | F27: =' AUG IL'!F13+' AUG IL'!F45 -> 0 | G27: =' AUG IL'!G13+' AUG IL'!G45 -> 0 | H27: =' AUG IL'!H13+' AUG IL'!H45 -> 0
A28: RICO | B28: I478 | C28: =' AUG IL'!C46+' AUG IL'!C14 -> 5083.2 | D28: =' AUG IL'!D14+' AUG IL'!D46 -> 2972 | E28: =SUM(C28/D28) -> 1.7103634 | F28: =' AUG IL'!F14+' AUG IL'!F46 -> 0 | G28: =' AUG IL'!G14+' AUG IL'!G46 -> 0 | H28: =' AUG IL'!H14+' AUG IL'!H46 -> 5083.2
A29: DAN M | B29: I501 | C29: =' AUG IL'!C15+' AUG IL'!C77+' AUG IL'!C47 -> 40621.45 | D29: =' AUG IL'!D15+' AUG IL'!D47+' AUG IL'!D77 -> 27697.48 | E29: =SUM(C29/D29) -> 1.4666118 | F29: =' AUG IL'!F15+' AUG IL'!F47+' AUG IL'!F77 -> 0 | G29: =' AUG IL'!G15+' AUG IL'!G47+' AUG IL'!G77 -> 0 | H29: =' AUG IL'!H15+' AUG IL'!H47+' AUG IL'!H77 -> 40621.45
A30: CHRIS T | B30: I664 | C30: =' AUG IL'!C16+' AUG IL'!C78+' AUG IL'!C48 -> 6237.3 | D30: =+' AUG IL'!D16+' AUG IL'!D48+' AUG IL'!D78 -> 3841.5 | E30: =SUM(C30/D30) -> 1.6236626 | F30: =+' AUG IL'!F16+' AUG IL'!F48+' AUG IL'!F78 -> 0 | G30: =+' AUG IL'!G16+' AUG IL'!G48+' AUG IL'!G78 -> 0 | H30: =' AUG IL'!H16+' AUG IL'!H78+' AUG IL'!H48 -> 6237.3
A31: MARK S | B31: I729 | C31: =+' AUG IL'!C17+' AUG IL'!C49+' AUG IL'!C79 -> 13089.82 | D31: =+' AUG IL'!D17+' AUG IL'!D49+' AUG IL'!D79 -> 8446.5 | E31: =SUM(C31/D31) -> 1.549733 | F31: =+' AUG IL'!F17+' AUG IL'!F49+' AUG IL'!F79 -> 0 | G31: =+' AUG IL'!G17+' AUG IL'!G49+' AUG IL'!G79 -> 0 | H31: =+' AUG IL'!H17+' AUG IL'!H49+' AUG IL'!H79 -> 13089.82
A32: ALAN S | B32: I801 | C32: =' AUG IL'!C19+' AUG IL'!C81+' AUG IL'!C92+' AUG IL'!C50 -> 19527.7 | D32: =' AUG IL'!D19+' AUG IL'!D81+' AUG IL'!D92+' AUG IL'!D50 -> 12311 | E32: =SUM(C32/D32) -> 1.5861993 | F32: =' AUG IL'!F81+' AUG IL'!F50+' AUG IL'!F92+' AUG IL'!F19 -> 0 | G32: =' AUG IL'!G81+' AUG IL'!G50+' AUG IL'!G92+' AUG IL'!G19 -> 0 | H32: =' AUG IL'!H19+' AUG IL'!H81+' AUG IL'!H92+' AUG IL'!H50 -> 19527.7
A33: SAMUEL J | B33: I815 | C33: =' AUG IL'!C20+' AUG IL'!C82+' AUG IL'!C51 -> 18212.41 | D33: =' AUG IL'!D20+' AUG IL'!D82+' AUG IL'!D51 -> 12283.5 | E33: =SUM(C33/D33) -> 1.4826727 | F33: =' AUG IL'!F82+' AUG IL'!F20+' AUG IL'!F51 -> 0 | G33: =' AUG IL'!G82+' AUG IL'!G20+' AUG IL'!G51 -> 0 | H33: =' AUG IL'!H20+' AUG IL'!H82+' AUG IL'!H51 -> 18212.41
A34: ANDREY K | B34: I816 | C34: =' AUG IL'!C52 -> 993.8 | D34: =' AUG IL'!D52 -> 582.6 | E34: =SUM(C34/D34) -> 1.7058016 | F34: =' AUG IL'!F52 -> 0 | G34: =' AUG IL'!G52 -> 0 | H34: =' AUG IL'!H52 -> 993.8
A35: DAVID S | B35: I830 | C35: =' AUG IL'!C53+' AUG IL'!C21+' AUG IL'!C83 -> 3562.99 | D35: =' AUG IL'!D53+' AUG IL'!D21+' AUG IL'!D83 -> 2084.58 | E35: =SUM(C35/D35) -> 1.7092124 | F35: =' AUG IL'!F53+' AUG IL'!F21+' AUG IL'!F83 -> 0 | G35: =' AUG IL'!G53+' AUG IL'!G21+' AUG IL'!G83 -> 0 | H35: =' AUG IL'!H53+' AUG IL'!H21+' AUG IL'!H83 -> 3562.99
A36: ROSS S | B36: I848 | C36: =' AUG IL'!C22 -> 1350 | D36: =' AUG IL'!D22 -> 660 | E36: =SUM(C36/D36) -> 2.0454545 | F36: =' AUG IL'!F22 -> 0 | G36: =' AUG IL'!G22 -> 0 | H36: =' AUG IL'!H22 -> 1350
A37: CARL L | B37: I850 | C37: =' AUG IL'!C23+' AUG IL'!C54 -> 0 | D37: =' AUG IL'!D23+' AUG IL'!D54 -> 0 | E37: =SUM(C37/D37) -> #DIV/0! | F37: =' AUG IL'!F23+' AUG IL'!F54 -> 554.95 | G37: =' AUG IL'!G23+' AUG IL'!G54 -> 0 | H37: =' AUG IL'!H23+' AUG IL'!H54 -> -554.95
A38: ANTOINETTE V | B38: I856 | C38: =' AUG IL'!C94+' AUG IL'!C24+' AUG IL'!C84 -> 3963.29 | D38: =' AUG IL'!D94+' AUG IL'!D24+' AUG IL'!D84 -> 2118.5 | E38: =SUM(C38/D38) -> 1.8708001 | F38: =' AUG IL'!F94+' AUG IL'!F24+' AUG IL'!F84 -> 0 | G38: =' AUG IL'!G94+' AUG IL'!G24+' AUG IL'!G84 -> 0 | H38: =' AUG IL'!H94+' AUG IL'!H24+' AUG IL'!H84 -> 3963.29
A39: JAVIER C | B39: I865 | C39: =' AUG IL'!C25+' AUG IL'!C55+' AUG IL'!C85 -> 7401 | D39: =' AUG IL'!D25+' AUG IL'!D55+' AUG IL'!D85 -> 4217 | E39: =SUM(C39/D39) -> 1.7550391 | F39: =' AUG IL'!F25+' AUG IL'!F55+' AUG IL'!F85 -> 0 | G39: =' AUG IL'!G25+' AUG IL'!G55+' AUG IL'!G85 -> 0 | H39: =' AUG IL'!H25+' AUG IL'!H55+' AUG IL'!H85 -> 7401
A40: TIMOTHY C | B40: I867 | C40: =' AUG IL'!C26 -> 2290.5 | D40: =' AUG IL'!D26 -> 1269.5 | E40: =SUM(C40/D40) -> 1.8042536 | F40: =' AUG IL'!F26 -> 0 | G40: =' AUG IL'!G26 -> 0 | H40: =' AUG IL'!H26 -> 2290.5
A41: KELLSTEIN G | B41: I879 | C41: =' AUG IL'!C86+' AUG IL'!C27+' AUG IL'!C56 -> 0 | D41: =' AUG IL'!D86+' AUG IL'!D27+' AUG IL'!D56 -> 0 | E41: =SUM(C41/D41) -> #DIV/0! | F41: =' AUG IL'!F86+' AUG IL'!F27+' AUG IL'!F56 -> 0 | G41: =' AUG IL'!G86+' AUG IL'!G27+' AUG IL'!G56 -> 0 | H41: =' AUG IL'!H86+' AUG IL'!H27+' AUG IL'!H56 -> 0
A42: JOSE S | B42: I887 | C42: =' AUG IL'!C57+' AUG IL'!C28 -> 3365.58 | D42: =' AUG IL'!D57+' AUG IL'!D28 -> 2015.41 | E42: =SUM(C42/D42) -> 1.6699232 | F42: =' AUG IL'!F57+' AUG IL'!F28 -> 0 | G42: =' AUG IL'!G57+' AUG IL'!G28 -> 0 | H42: =' AUG IL'!H57+' AUG IL'!H28 -> 3365.58
A43: MARSHALL H | B43: I891 | C43: =' AUG IL'!C58 -> 3619.51 | D43: =' AUG IL'!D58 -> 1924.97 | E43: =SUM(C43/D43) -> 1.8802942 | F43: =' AUG IL'!F58 -> 0 | G43: =' AUG IL'!G58 -> 0 | H43: =' AUG IL'!H58 -> 3619.51
A44: BENJI C | B44: I892 | C44: =' AUG IL'!C59 -> 1584.97 | D44: =' AUG IL'!D59 -> 1128.9 | E44: =SUM(C44/D44) -> 1.403995 | F44: =' AUG IL'!F59 -> 0 | G44: =' AUG IL'!G59 -> 0 | H44: =' AUG IL'!H59 -> 1584.97
...

Sheet AUG 2026 Totals
A1: =' AUG AZ'!A1 -> 46241
A2: TOTALS
A4: DBW
A6: AZ | C6: =' AUG AZ'!H15 -> 65475.11
A7: IL | C7: =' AUG IL'!H36 -> 235272.6
A8: WI | C8: ='AUG WI'!H23 -> 152810.53
C10: =SUM(C6:C9) -> 453558.24
A12: HELIX -22
A14: AZ | C14: =' AUG AZ'!H24 -> 11230.05
A15: IL | C15: =' AUG IL'!H68 -> 68052.8
A16: WI | C16: ='AUG WI'!H38 -> 1969.1
C17: =SUM(C14:C16) -> 81251.95
A19: HELIX FL - 33
A21: AZ | C21: =' AUG AZ'!H30 -> 1895.5
A22: IL | C22: =' AUG IL'!H89 -> 24445.45
A23: WI | C23: ='AUG WI'!H49 -> 0
C24: =SUM(C21:C23) -> 26340.95
A26: HELIX TOOL - 44
A28: WI | C28: ='AUG WI'!H57 -> 0
C30: =SUM(C28:C29) -> 0
A32: 4COREBIZ-55
A34: IL | C34: =' AUG IL'!H97 -> 17483.1
A36: STRATUS -77
A38: IL | C38: =' AUG IL'!H104 -> 2259.88
C40: =SUM(C38:C39) -> 2259.88
A43: TOTAL | C43: =C10+C17+C24+C40+C30+C34 -> 580894.12
A51: BATCH/DATE
A52: 8/3 W/D | B52: 146843.49
A53: 8/4 RETURNS | B53: -3504.75
A54: 8/4 W/D | B54: 155915.12
A55: 8/5 W/D | B55: 80550.09
A56: 8/6 W/D | B56: 123123.98
A57: 8/7 RETURNS | B57: -2861.83
A58: 8/7 W/D | B58: 80825.71
D59: =146843.49+0.72-3504.75+155915.12+1.47+80550.09+0.01+123123.98+0.11-2861.83+80825.71 -> 580894.12 | E59: SHIPSHEETS
D60: =C43 -> 580894.12
D62: =+D59-D60 -> 0 | E62: DIFF
