Workbook
Name CurrentRow: 1

Sheet IL WEEK 2
A1: WEEK 2 | B1: ILLINOIS SALES TOTALS | H1: UPGRADE | K1: AUGUST 2026 | M1: #VALUE!
C2: DAY | D2: 6 | E2: 7 | F2: 8 | G2: 9 | H2: 10 | J2: # of selling days: | K2: =SUM('IL WEEK 1'!K2) -> 25
A3: WEEK OF: 08/10/26 - 08/14/26 | D3: 46244 | E3: 46245 | F3: 46246 | G3: 46247 | H3: 46248 | J3: # days used: | K3: 6
A4: PREV WK TTL | B4: SALESPERSON | C4: S/P# | D4: MON | E4: TUE | F4: WED | G4: THURS | H4: FRI | I4: WKLY TTL | J4: TOTAL | K4: PACE
A5: =SUM('IL WEEK 1'!J5) -> 46869.8 | B5: JORDAN M | C5: I272 | D5: 606 | I5: =SUM(D5:H5) -> 606 | J5: =SUM(I5+A5) -> 47475.8 | K5: =SUM(J5/$K$3*'IL WEEK 1'!$K$2) -> 197815.83
A6: =SUM('IL WEEK 1'!J6) -> 14347.3 | B6: JIMMY M | C6: I281 | D6: 5630.1 | I6: =SUM(D6:H6) -> 5630.1 | J6: =SUM(I6+A6) -> 19977.4 | K6: =SUM(J6/$K$3*'IL WEEK 1'!$K$2) -> 83239.167
A7: =SUM('IL WEEK 1'!J7) -> 105745.6 | B7: CHRIS Z | C7: I393 | D7: 9250.2 | I7: =SUM(D7:H7) -> 9250.2 | J7: =SUM(I7+A7) -> 114995.8 | K7: =SUM(J7/$K$3*'IL WEEK 1'!$K$2) -> 479149.17
A8: =SUM('IL WEEK 1'!J8) -> 40837.66 | B8: JEFF J | C8: I436 | D8: 15283.18 | I8: =SUM(D8:H8) -> 15283.18 | J8: =SUM(I8+A8) -> 56120.84 | K8: =SUM(J8/$K$3*'IL WEEK 1'!$K$2) -> 233836.83
A9: =SUM('IL WEEK 1'!J9) -> 0 | B9: IAIR Z | C9: I462 | D9: 0 | I9: =SUM(D9:H9) -> 0 | J9: =SUM(I9+A9) -> 0 | K9: =SUM(J9/$K$3*'IL WEEK 1'!$K$2) -> 0
A10: =SUM('IL WEEK 1'!J10) -> 7198 | B10: RICO | C10: I478 | D10: 0 | I10: =SUM(D10:H10) -> 0 | J10: =SUM(I10+A10) -> 7198 | K10: =SUM(J10/$K$3*'IL WEEK 1'!$K$2) -> 29991.667
A11: =SUM('IL WEEK 1'!J11) -> 42638.95 | B11: DAN M | C11: I501 | D11: 6352.5 | I11: =SUM(D11:H11) -> 6352.5 | J11: =SUM(I11+A11) -> 48991.45 | K11: =SUM(J11/$K$3*'IL WEEK 1'!$K$2) -> 204131.04
A12: =SUM('IL WEEK 1'!J12) -> 8525 | B12: CHRIS T | C12: I664 | D12: 429 | I12: =SUM(D12:H12) -> 429 | J12: =SUM(I12+A12) -> 8954 | K12: =SUM(J12/$K$3*'IL WEEK 1'!$K$2) -> 37308.333 | M12: WEEK 1 | N12: 08/03/26 - 08/07/26 | O12: WEEK 1 ORDERS | P12: ='IL WEEK 1'!$P$12 -> 371 | Q12: =SUM('IL WEEK 1'!I42) -> 760397.58
A13: =SUM('IL WEEK 1'!J13) -> 10689.39 | B13: MARK S | C13: I729 | D13: 1092.5 | I13: =SUM(D13:H13) -> 1092.5 | J13: =SUM(I13+A13) -> 11781.89 | K13: =SUM(J13/$K$3*'IL WEEK 1'!$K$2) -> 49091.208 | M13: WEEK 2 | N13: 08/10/26 - 08/14/26 | O13: WEEK 2 ORDERS | P13: =SUM('IL WEEK 2'!I47) -> 51 | Q13: =SUM(I42) -> 101771.22
A14: =SUM('IL WEEK 1'!J14) -> 21372.7 | B14: ALAN S | C14: I801 | D14: 2147.7 | I14: =SUM(D14:H14) -> 2147.7 | J14: =SUM(I14+A14) -> 23520.4 | K14: =SUM(J14/$K$3*'IL WEEK 1'!$K$2) -> 98001.667 | M14: WEEK 3 | N14: 08/17/26 - 08/21/26 | O14: WEEK 3 ORDERS | P14: =SUM('[1]IL WEEK 3'!I47) -> 0 | Q14: =SUM('[1]IL WEEK 3'!I42) -> 0
A15: =SUM('IL WEEK 1'!J15) -> 22272.14 | B15: SAMUEL J | C15: I815 | D15: 1130.94 | I15: =SUM(D15:H15) -> 1130.94 | J15: =SUM(I15+A15) -> 23403.08 | K15: =SUM(J15/$K$3*'IL WEEK 1'!$K$2) -> 97512.833 | M15: WEEK 4 | N15: 08/24/26 - 08/28/26 | O15: WEEK 4 ORDERS | P15: =SUM('[1]IL WEEK 4'!I47) -> 0 | Q15: =SUM('[1]IL WEEK 4'!I42) -> 0
A16: =SUM('IL WEEK 1'!J16) -> 6211.55 | B16: DAVID S | C16: I830 | D16: 11395.7 | I16: =SUM(D16:H16) -> 11395.7 | J16: =SUM(I16+A16) -> 17607.25 | K16: =SUM(J16/$K$3*'IL WEEK 1'!$K$2) -> 73363.542 | M16: WEEK 5 | N16: 08/31/26 - 09/04/26 | O16: WEEK 5 ORDERS | P16: =SUM('[1]IL WEEK 5'!I47) -> 0 | Q16: =SUM('[1]IL WEEK 5'!I42) -> 0
A17: =SUM('IL WEEK 1'!J17) -> 1350 | B17: ROSS S | C17: I848 | D17: 0 | I17: =SUM(D17:H17) -> 0 | J17: =SUM(I17+A17) -> 1350 | K17: =SUM(J17/$K$3*'IL WEEK 1'!$K$2) -> 5625 | P17: =SUM(P12:P16) -> 422 | Q17: =SUM(Q12:Q16) -> 862168.8
A18: =SUM('IL WEEK 1'!J18) -> 6686.49 | B18: ANTOINETTE V | C18: I856 | D18: 778 | I18: =SUM(D18:H18) -> 778 | J18: =SUM(I18+A18) -> 7464.49 | K18: =SUM(J18/$K$3*'IL WEEK 1'!$K$2) -> 31102.042
A19: =SUM('IL WEEK 1'!J19) -> 9638.88 | B19: JAVIER C | C19: I865 | D19: 0 | I19: =SUM(D19:H19) -> 0 | J19: =SUM(I19+A19) -> 9638.88 | K19: =SUM(J19/$K$3*'IL WEEK 1'!$K$2) -> 40162
A20: =SUM('IL WEEK 1'!J20) -> 5824.97 | B20: TIMOTHY C | C20: I867 | D20: 1095 | I20: =SUM(D20:H20) -> 1095 | J20: =SUM(I20+A20) -> 6919.97 | K20: =SUM(J20/$K$3*'IL WEEK 1'!$K$2) -> 28833.208 | M20: COMPANY DAILY WRITTEN AVERAGE PER DAY | P20: =SUM(J42/K3) -> 143694.8
A21: =SUM('IL WEEK 1'!J21) -> 0 | B21: KELLSTEIN G | C21: I879 | D21: 0 | I21: =SUM(D21:H21) -> 0 | J21: =SUM(I21+A21) -> 0 | K21: =SUM(J21/$K$3*'IL WEEK 1'!$K$2) -> 0 | M21: RETURNS THIS MONTH: | P21: 6366.58
A22: =SUM('IL WEEK 1'!J22) -> 5201.58 | B22: JOSE S. | C22: I887 | D22: 720 | I22: =SUM(D22:H22) -> 720 | J22: =SUM(I22+A22) -> 5921.58 | K22: =SUM(J22/$K$3*'IL WEEK 1'!$K$2) -> 24673.25 | M22: COMPANY WRITTEN MINUS RETURNS = | P22: =SUM(J42-P21) -> 855802.22 | Q22: PACE AFTER RETURNS | R22: WRITTEN AVERAGE AFTER RETURNS
A23: =SUM('IL WEEK 1'!J23) -> 2894.54 | B23: MARSHALL | C23: I891 | D23: 639 | I23: =SUM(D23:H23) -> 639 | J23: =SUM(I23+A23) -> 3533.54 | K23: =SUM(J23/$K$3*'IL WEEK 1'!$K$2) -> 14723.083 | Q23: =SUM(P22/K3)*K2 -> 3565842.6 | R23: =SUM(Q23/K2) -> 142633.7
A24: =SUM('IL WEEK 1'!J24) -> 4887.35 | B24: AIDEN H | C24: I895 | D24: 0 | I24: =SUM(D24:H24) -> 0 | J24: =SUM(I24+A24) -> 4887.35 | K24: =SUM(J24/$K$3*'IL WEEK 1'!$K$2) -> 20363.958
A25: =SUM('IL WEEK 1'!J25) -> 199 | B25: MARTIN | C25: I898 | D25: 0 | I25: =SUM(D25:H25) -> 0 | J25: =SUM(I25+A25) -> 199 | K25: =SUM(J25/$K$3*'IL WEEK 1'!$K$2) -> 829.16667 | M25: SHIP #'S THROUGH August 7, 2026 : | P25: 580894.12
A26: =SUM('IL WEEK 1'!J26) -> 13262.78 | B26: MATT G | C26: I902 | D26: 859 | I26: =SUM(D26:H26) -> 859 | J26: =SUM(I26+A26) -> 14121.78 | K26: =SUM(J26/$K$3*'IL WEEK 1'!$K$2) -> 58840.75
A27: =SUM('IL WEEK 1'!J27) -> 87252.25 | B27: STOTTS | C27: I924 | D27: 17453 | I27: =SUM(D27:H27) -> 17453 | J27: =SUM(I27+A27) -> 104705.25 | K27: =SUM(J27/$K$3*'IL WEEK 1'!$K$2) -> 436271.88
A28: =SUM('IL WEEK 1'!J28) -> 2773.2 | B28: HELIX HSE | C28: I944 | D28: 0 | I28: =SUM(D28:H28) -> 0 | J28: =SUM(I28+A28) -> 2773.2 | K28: =SUM(J28/$K$3*'IL WEEK 1'!$K$2) -> 11555 | M28: GAP: | N28: =SUM(P22-P25) -> 274908.1
A29: =SUM('IL WEEK 1'!J29) -> 0 | I29: =SUM(D29:H29) -> 0 | J29: =SUM(I29+A29) -> 0 | K29: =SUM(J29/$K$3*'IL WEEK 1'!$K$2) -> 0
A30: =SUM('IL WEEK 1'!J30) -> 0 | I30: =SUM(D30:H30) -> 0 | J30: =SUM(I30+A30) -> 0 | K30: =SUM(J30/$K$3*'IL WEEK 1'!$K$2) -> 0
A31: =SUM('IL WEEK 1'!J31) -> 0 | I31: =SUM(D31:H31) -> 0 | J31: =SUM(I31+A31) -> 0 | K31: =SUM(J31/$K$3*'IL WEEK 1'!$K$2) -> 0
A32: =SUM('IL WEEK 1'!J32) -> 0 | I32: =SUM(D32:H32) -> 0 | J32: =SUM(I32+A32) -> 0 | K32: =SUM(J32/$K$3*'IL WEEK 1'!$K$2) -> 0 | M32: AZ | N32: =SUM('AZ WEEK 2'!I21+'AZ WEEK 1'!I21) -> 48.25 | O32: =SUM('AZ WEEK 2'!J18) -> 106017.48
A33: =SUM('IL WEEK 1'!J33) -> 0 | I33: =SUM(D33:H33) -> 0 | J33: =SUM(I33+A33) -> 0 | K33: =SUM(J33/$K$3*'IL WEEK 1'!$K$2) -> 0 | M33: IL | N33: =SUM(I45+'IL WEEK 1'!I45) -> 311.25 | O33: =SUM(J39) -> 542997.25
A34: =SUM('IL WEEK 1'!J34) -> 0 | I34: =SUM(D34:H34) -> 0 | J34: =SUM(I34+A34) -> 0 | K34: =SUM(J34/$K$3*'IL WEEK 1'!$K$2) -> 0 | M34: WI | N34: =SUM('WI WEEK 2'!I31+'WI WEEK 1'!I31) -> 62.5 | O34: =SUM('WI WEEK 2'!J28) -> 213154.07
A35: =SUM('IL WEEK 1'!J35) -> 0 | I35: =SUM(D35:H35) -> 0 | J35: =SUM(I35+A35) -> 0 | K35: =SUM(J35/$K$3*'IL WEEK 1'!$K$2) -> 0 | M35: TTL # OF ORDERS: | N35: =SUM(N32:N34) -> 422 | O35: =SUM(O32:O34) -> 862168.8
A36: =SUM('IL WEEK 1'!J36) -> 0 | B36: Jason | C36: I069 | I36: =SUM(D36:H36) -> 0 | J36: =SUM(I36+A36) -> 0 | K36: =SUM(J36/$K$3*'IL WEEK 1'!$K$2) -> 0
A37: =SUM('IL WEEK 1'!J37) -> 1456.3 | B37: MISC - IL | I37: =SUM(D37:H37) -> 0 | J37: =SUM(I37+A37) -> 1456.3 | K37: =SUM(J37/$K$3*'IL WEEK 1'!$K$2) -> 6067.9167 | M37: SHIPPED BY DIVISION
A38: =SUM('IL WEEK 1'!J38) -> 0 | B38: HOUSE - IL | I38: =SUM(D38:H38) -> 0 | J38: =SUM(I38+A38) -> 0 | K38: =SUM(J38/$K$3*'IL WEEK 1'!$K$2) -> 0 | M38: 00 | N38: 453558.24
A39: =SUM('IL WEEK 1'!I39) -> 468135.43 | B39: TOTALS | D39: =SUM(D5:D38) -> 74861.82 | E39: =SUM(E5:E38) -> 0 | F39: =SUM(F5:F38) -> 0 | G39: =SUM(G5:G38) -> 0 | H39: =SUM(H5:H38) -> 0 | I39: =SUM(I5:I38) -> 74861.82 | J39: =SUM(A39+I39) -> 542997.25 | K39: =SUM(J39/$K$3*'IL WEEK 1'!$K$2) -> 2262488.5 | M39: 22 | N39: 81251.95
A40: =SUM('IL WEEK 1'!J40) -> 101658.48 | B40: AZ TOTAL | D40: =SUM('AZ WEEK 2'!D18) -> 4359 | E40: =SUM('AZ WEEK 2'!E18) -> 0 | F40: =SUM('AZ WEEK 2'!F18) -> 0 | G40: =SUM('AZ WEEK 2'!G18) -> 0 | H40: =SUM('AZ WEEK 2'!H18) -> 0 | I40: =SUM('AZ WEEK 2'!I18) -> 4359 | J40: =SUM(A40+I40) -> 106017.48 | K40: =SUM(J40/$K$3*'IL WEEK 1'!$K$2) -> 441739.5 | M40: 33 | N40: 26340.95
...

Sheet AZ WEEK 2
A1: WEEK 2 | B1: ARIZONA SALES TOTALS | H1: UPGRADE | K1: AUGUST 2026 | M1: #VALUE!
C2: DAY | D2: 6 | E2: 7 | F2: 8 | G2: 9 | H2: 10 | J2: # of selling days: | K2: =SUM('IL WEEK 1'!K2) -> 25
A3: WEEK OF: 08/10/26 - 08/14/26 | D3: 46244 | E3: 46245 | F3: 46246 | G3: 46247 | H3: 46248 | J3: # days used: | K3: =SUM('IL WEEK 2'!K3) -> 6
A4: PREV WK TTL | B4: SALESPERSON | C4: S/P# | D4: MON | E4: TUES | F4: WED | G4: THURS | H4: FRI | I4: WKLY TTL | J4: TOTAL | K4: PACE
A5: =SUM('AZ WEEK 1'!J5) -> 17389.96 | B5: ADAM R | C5: A550 | D5: 340.5 | I5: =SUM(D5:H5) -> 340.5 | J5: =SUM(I5+A5) -> 17730.46 | K5: =SUM(J5/'IL WEEK 2'!$K$3*'IL WEEK 1'!$K$2) -> 73876.917
A6: =SUM('AZ WEEK 1'!J6) -> 630 | B6: JACOB M | C6: A607 | D6: 0 | I6: =SUM(D6:H6) -> 0 | J6: =SUM(I6+A6) -> 630 | K6: =SUM(J6/'IL WEEK 2'!$K$3*'IL WEEK 1'!$K$2) -> 2625
A7: =SUM('AZ WEEK 1'!J7) -> 36169.46 | B7: LARRY A | C7: A654 | D7: 1908 | I7: =SUM(D7:H7) -> 1908 | J7: =SUM(I7+A7) -> 38077.46 | K7: =SUM(J7/'IL WEEK 2'!$K$3*'IL WEEK 1'!$K$2) -> 158656.08
A8: =SUM('AZ WEEK 1'!J8) -> 4989.31 | B8: MARK F | C8: A701 | D8: 0 | I8: =SUM(D8:H8) -> 0 | J8: =SUM(I8+A8) -> 4989.31 | K8: =SUM(J8/'IL WEEK 2'!$K$3*'IL WEEK 1'!$K$2) -> 20788.792
A9: =SUM('AZ WEEK 1'!J9) -> 17687.5 | B9: OLIN M | C9: A702 | D9: 340.5 | I9: =SUM(D9:H9) -> 340.5 | J9: =SUM(I9+A9) -> 18028 | K9: =SUM(J9/'IL WEEK 2'!$K$3*'IL WEEK 1'!$K$2) -> 75116.667
A10: =SUM('AZ WEEK 1'!J10) -> 24652.25 | B10: ALEX B | C10: A777 | D10: 1770 | I10: =SUM(D10:H10) -> 1770 | J10: =SUM(I10+A10) -> 26422.25 | K10: =SUM(J10/'IL WEEK 2'!$K$3*'IL WEEK 1'!$K$2) -> 110092.71
A11: =SUM('AZ WEEK 1'!J11) -> 0 | I11: =SUM(D11:H11) -> 0 | J11: =SUM(I11+A11) -> 0 | K11: =SUM(J11/'IL WEEK 2'!$K$3*'IL WEEK 1'!$K$2) -> 0
A12: =SUM('AZ WEEK 1'!J12) -> 0 | I12: =SUM(D12:H12) -> 0 | J12: =SUM(I12+A12) -> 0 | K12: =SUM(J12/'IL WEEK 2'!$K$3*'IL WEEK 1'!$K$2) -> 0 | M12: WEEK 1 | N12: 08/03/26 - 08/07/26
A13: =SUM('AZ WEEK 1'!J13) -> 0 | I13: =SUM(D13:H13) -> 0 | J13: =SUM(I13+A13) -> 0 | K13: =SUM(J13/'IL WEEK 2'!$K$3*'IL WEEK 1'!$K$2) -> 0 | M13: WEEK 2 | N13: 08/10/26 - 08/14/26
A14: =SUM('AZ WEEK 1'!J14) -> 0 | I14: =SUM(D14:H14) -> 0 | J14: =SUM(I14+A14) -> 0 | K14: =SUM(J14/'IL WEEK 2'!$K$3*'IL WEEK 1'!$K$2) -> 0 | M14: WEEK 3 | N14: 08/17/26 - 08/21/26
A15: =SUM('AZ WEEK 1'!J15) -> 0 | I15: =SUM(D15:H15) -> 0 | J15: =SUM(I15+A15) -> 0 | K15: =SUM(J15/'IL WEEK 2'!$K$3*'IL WEEK 1'!$K$2) -> 0 | M15: WEEK 4 | N15: 08/24/26 - 08/28/26
A16: =SUM('AZ WEEK 1'!J16) -> 0 | I16: =SUM(D16:H16) -> 0 | J16: =SUM(I16+A16) -> 0 | K16: =SUM(J16/'IL WEEK 2'!$K$3*'IL WEEK 1'!$K$2) -> 0 | M16: WEEK 5 | N16: 08/31/26 - 09/04/26
A17: =SUM('AZ WEEK 1'!J17) -> 140 | B17: HOUSE - AZ | C17: A111 | I17: =SUM(D17:H17) -> 0 | J17: =SUM(I17+A17) -> 140 | K17: =SUM(J17/'IL WEEK 2'!$K$3*'IL WEEK 1'!$K$2) -> 583.33333
A18: =SUM(A5:A17) -> 101658.48 | B18: TOTALS | D18: =SUM(D5:D17) -> 4359 | E18: =SUM(E5:E17) -> 0 | F18: =SUM(F5:F17) -> 0 | G18: =SUM(G5:G17) -> 0 | H18: =SUM(H5:H17) -> 0 | I18: =SUM(I5:I17) -> 4359 | J18: =SUM(J5:J17) -> 106017.48 | K18: =SUM(J18/'IL WEEK 2'!$K$3*'IL WEEK 1'!$K$2) -> 441739.5
C19: DAY | D19: 6 | E19: 7 | F19: 8 | G19: 9 | H19: 10
D20: =D3 -> 46244 | E20: =E3 -> 46245 | F20: =F3 -> 46246 | G20: =G3 -> 46247 | H20: =H3 -> 46248
B21: # OF ORDERS - AZ OFFICE | D21: 4 | I21: =SUM(D21:H21) -> 4

Sheet WI WEEK 2
A1: WEEK 2 | B1: WISCONSIN SALES TOTALS | H1: UPGRADE | K1: AUGUST 2026 | M1: #VALUE!
C2: DAY | D2: 6 | E2: 7 | F2: 8 | G2: 9 | H2: 10 | J2: # of selling days: | K2: =SUM('IL WEEK 1'!K2) -> 25
A3: WEEK OF: 08/10/26 - 08/14/26 | D3: 46244 | E3: 46245 | F3: 46246 | G3: 46247 | H3: 46248 | J3: # days used: | K3: =SUM('IL WEEK 2'!K3) -> 6
A4: PREV WK TTL | B4: SALESPERSON | C4: S/P# | D4: MON | E4: TUES | F4: WED | G4: THURS | H4: FRI | I4: WKLY TTL | J4: TOTAL | K4: PACE
A5: =SUM('WI WEEK 1'!J5) -> 19096.88 | B5: ADAM WEST | C5: W603 | D5: 0 | I5: =SUM(D5:H5) -> 0 | J5: =SUM(I5+A5) -> 19096.88 | K5: =SUM(J5/'IL WEEK 2'!$K$3*'IL WEEK 1'!$K$2) -> 79570.333
A6: =SUM('WI WEEK 1'!J6) -> 547.2 | B6: KERRY SMITH | C6: W762 | D6: 0 | I6: =SUM(D6:H6) -> 0 | J6: =SUM(I6+A6) -> 547.2 | K6: =SUM(J6/'IL WEEK 2'!$K$3*'IL WEEK 1'!$K$2) -> 2280
A7: =SUM('WI WEEK 1'!J7) -> 32577.43 | B7: FROGGY | C7: W784 | D7: 8881.75 | I7: =SUM(D7:H7) -> 8881.75 | J7: =SUM(I7+A7) -> 41459.18 | K7: =SUM(J7/'IL WEEK 2'!$K$3*'IL WEEK 1'!$K$2) -> 172746.58
A8: =SUM('WI WEEK 1'!J8) -> 59985.1 | B8: RONNY B | C8: W839 | D8: 5525.05 | I8: =SUM(D8:H8) -> 5525.05 | J8: =SUM(I8+A8) -> 65510.15 | K8: =SUM(J8/'IL WEEK 2'!$K$3*'IL WEEK 1'!$K$2) -> 272958.96
A9: =SUM('WI WEEK 1'!J9) -> 14673.52 | B9: JOHN BAEMMERT | C9: W849 | D9: 0 | I9: =SUM(D9:H9) -> 0 | J9: =SUM(I9+A9) -> 14673.52 | K9: =SUM(J9/'IL WEEK 2'!$K$3*'IL WEEK 1'!$K$2) -> 61139.667
A10: =SUM('WI WEEK 1'!J10) -> 3866.2 | B10: LUIS MILLAN | C10: W909 | D10: 0 | I10: =SUM(D10:H10) -> 0 | J10: =SUM(I10+A10) -> 3866.2 | K10: =SUM(J10/'IL WEEK 2'!$K$3*'IL WEEK 1'!$K$2) -> 16109.167
A11: =SUM('WI WEEK 1'!J11) -> 27424.65 | B11: ADAM MISUREK | C11: W930 | D11: 0 | I11: =SUM(D11:H11) -> 0 | J11: =SUM(I11+A11) -> 27424.65 | K11: =SUM(J11/'IL WEEK 2'!$K$3*'IL WEEK 1'!$K$2) -> 114269.37
A12: =SUM('WI WEEK 1'!J12) -> 284.99 | B12: GEOFF NURSE | C12: W938 | D12: 0 | I12: =SUM(D12:H12) -> 0 | J12: =SUM(I12+A12) -> 284.99 | K12: =SUM(J12/'IL WEEK 2'!$K$3*'IL WEEK 1'!$K$2) -> 1187.4583 | M12: WEEK 1 | N12: 08/03/26 - 08/07/26
A13: =SUM('WI WEEK 1'!J13) -> 0 | B13: Cassie Kolhouse | C13: W959 | D13: 0 | I13: =SUM(D13:H13) -> 0 | J13: =SUM(I13+A13) -> 0 | K13: =SUM(J13/'IL WEEK 2'!$K$3*'IL WEEK 1'!$K$2) -> 0 | M13: WEEK 2 | N13: 08/10/26 - 08/14/26
A14: =SUM('WI WEEK 1'!J14) -> 3856.3 | B14: CHRIS K | C14: W962 | D14: 578 | I14: =SUM(D14:H14) -> 578 | J14: =SUM(I14+A14) -> 4434.3 | K14: =SUM(J14/'IL WEEK 2'!$K$3*'IL WEEK 1'!$K$2) -> 18476.25 | M14: WEEK 3 | N14: 08/17/26 - 08/21/26
A15: =SUM('WI WEEK 1'!J15) -> 0 | B15: BLAKE | C15: W966 | D15: 0 | I15: =SUM(D15:H15) -> 0 | J15: =SUM(I15+A15) -> 0 | K15: =SUM(J15/'IL WEEK 2'!$K$3*'IL WEEK 1'!$K$2) -> 0 | M15: WEEK 4 | N15: 08/24/26 - 08/28/26
A16: =SUM('WI WEEK 1'!J16) -> 0 | B16: JAMES B. | C16: W967 | D16: 0 | I16: =SUM(D16:H16) -> 0 | J16: =SUM(I16+A16) -> 0 | K16: =SUM(J16/'IL WEEK 2'!$K$3*'IL WEEK 1'!$K$2) -> 0 | M16: WEEK 5 | N16: 08/31/26 - 09/04/26
A17: =SUM('WI WEEK 1'!J17) -> 0 | B17: TJ SUTTON | C17: W973 | D17: 6987.6 | I17: =SUM(D17:H17) -> 6987.6 | J17: =SUM(I17+A17) -> 6987.6 | K17: =SUM(J17/'IL WEEK 2'!$K$3*'IL WEEK 1'!$K$2) -> 29115
A18: =SUM('WI WEEK 1'!J18) -> 20780.08 | B18: SCOT TOPORSH | C18: W983 | D18: 578 | I18: =SUM(D18:H18) -> 578 | J18: =SUM(I18+A18) -> 21358.08 | K18: =SUM(J18/'IL WEEK 2'!$K$3*'IL WEEK 1'!$K$2) -> 88992
A19: =SUM('WI WEEK 1'!J19) -> 0 | I19: =SUM(D19:H19) -> 0 | J19: =SUM(I19+A19) -> 0 | K19: =SUM(J19/'IL WEEK 2'!$K$3*'IL WEEK 1'!$K$2) -> 0
A20: =SUM('WI WEEK 1'!J20) -> 0 | I20: =SUM(D20:H20) -> 0 | J20: =SUM(I20+A20) -> 0 | K20: =SUM(J20/'IL WEEK 2'!$K$3*'IL WEEK 1'!$K$2) -> 0
A21: =SUM('WI WEEK 1'!J21) -> 0 | I21: =SUM(D21:H21) -> 0 | J21: =SUM(I21+A21) -> 0 | K21: =SUM(J21/'IL WEEK 2'!$K$3*'IL WEEK 1'!$K$2) -> 0
A22: =SUM('WI WEEK 1'!J22) -> 0 | I22: =SUM(D22:H22) -> 0 | J22: =SUM(I22+A22) -> 0 | K22: =SUM(J22/'IL WEEK 2'!$K$3*'IL WEEK 1'!$K$2) -> 0
A23: =SUM('WI WEEK 1'!J23) -> 0 | I23: =SUM(D23:H23) -> 0 | J23: =SUM(I23+A23) -> 0 | K23: =SUM(J23/'IL WEEK 2'!$K$3*'IL WEEK 1'!$K$2) -> 0
A24: =SUM('WI WEEK 1'!J24) -> 0 | I24: =SUM(D24:H24) -> 0 | J24: =SUM(I24+A24) -> 0 | K24: =SUM(J24/'IL WEEK 2'!$K$3*'IL WEEK 1'!$K$2) -> 0
A25: =SUM('WI WEEK 1'!J25) -> 0 | I25: =SUM(D25:H25) -> 0 | J25: =SUM(I25+A25) -> 0 | K25: =SUM(J25/'IL WEEK 2'!$K$3*'IL WEEK 1'!$K$2) -> 0
A26: =SUM('WI WEEK 1'!J26) -> 0 | I26: =SUM(D26:H26) -> 0 | J26: =SUM(I26+A26) -> 0 | K26: =SUM(J26/'IL WEEK 2'!$K$3*'IL WEEK 1'!$K$2) -> 0
A27: =SUM('WI WEEK 1'!J27) -> 7511.32 | B27: MISC - WI | I27: =SUM(D27:H27) -> 0 | J27: =SUM(I27+A27) -> 7511.32 | K27: =SUM(J27/'IL WEEK 2'!$K$3*'IL WEEK 1'!$K$2) -> 31297.167
A28: =SUM(A5:A27) -> 190603.67 | B28: TOTALS | D28: =SUM(D5:D27) -> 22550.4 | E28: =SUM(E5:E27) -> 0 | F28: =SUM(F5:F27) -> 0 | G28: =SUM(G5:G27) -> 0 | H28: =SUM(H5:H27) -> 0 | I28: =SUM(I5:I27) -> 22550.4 | J28: =SUM(J5:J27) -> 213154.07 | K28: =SUM(J28/'IL WEEK 2'!$K$3*'IL WEEK 1'!$K$2) -> 888141.96
C29: DAY | D29: 6 | E29: 7 | F29: 8 | G29: 9 | H29: 10
D30: =D3 -> 46244 | E30: =E3 -> 46245 | F30: =F3 -> 46246 | G30: =G3 -> 46247 | H30: =H3 -> 46248
B31: # OF ORDERS - WI OFFICE | D31: 6.5 | I31: =SUM(D31:H31) -> 6.5

Sheet IL WEEK 1
A1: WEEK 1 | B1: ILLINOIS SALES TOTALS | K1: AUGUST 2026 | M1: #VALUE!
C2: DAY | D2: 1 | E2: 2 | F2: 3 | G2: 4 | H2: 5 | J2: # of selling days: | K2: 25
A3: WEEK OF: 08/03/26 - 08/07/26 | D3: 46237 | E3: 46238 | F3: 46239 | G3: 46240 | H3: 46241 | J3: # days used: | K3: 5
A4: PREV WK TTL | B4: SALESPERSON | C4: S/P# | D4: MON | E4: TUES | F4: WED | G4: THURS | H4: FRI | I4: WKLY TTL | J4: TOTAL | K4: PACE
B5: JORDAN M | C5: I272 | D5: 14332.9 | E5: 9763.55 | F5: 3080.35 | G5: 14441.5 | H5: 5251.5 | I5: =SUM(D5:H5) -> 46869.8 | J5: =SUM(I5+A5) -> 46869.8 | K5: =SUM(J5/$K$3*$K$2) -> 234349
B6: JIMMY M | C6: I281 | D6: 1811 | E6: 4952.9 | F6: 831.9 | G6: 3937 | H6: 2814.5 | I6: =SUM(D6:H6) -> 14347.3 | J6: =SUM(I6+A6) -> 14347.3 | K6: =SUM(J6/$K$3*$K$2) -> 71736.5
B7: CHRIS Z | C7: I393 | D7: 41360.56 | E7: 16663.52 | F7: 18881.45 | G7: 4182.1 | H7: 24657.97 | I7: =SUM(D7:H7) -> 105745.6 | J7: =SUM(I7+A7) -> 105745.6 | K7: =SUM(J7/$K$3*$K$2) -> 528728
B8: JEFF J | C8: I436 | D8: 15049.64 | E8: 2496.99 | F8: 62.35 | G8: 12207.8 | H8: 11020.88 | I8: =SUM(D8:H8) -> 40837.66 | J8: =SUM(I8+A8) -> 40837.66 | K8: =SUM(J8/$K$3*$K$2) -> 204188.3
B9: IAIR Z | C9: I462 | D9: 0 | E9: 0 | F9: 0 | G9: 0 | H9: 0 | I9: =SUM(D9:H9) -> 0 | J9: =SUM(I9+A9) -> 0 | K9: =SUM(J9/$K$3*$K$2) -> 0
B10: RICO | C10: I478 | D10: 0 | E10: 1228.2 | F10: 0 | G10: 0 | H10: 5969.8 | I10: =SUM(D10:H10) -> 7198 | J10: =SUM(I10+A10) -> 7198 | K10: =SUM(J10/$K$3*$K$2) -> 35990
B11: DAN M | C11: I501 | D11: 13262 | E11: 4003.8 | F11: 7829.5 | G11: 12552.65 | H11: 4991 | I11: =SUM(D11:H11) -> 42638.95 | J11: =SUM(I11+A11) -> 42638.95 | K11: =SUM(J11/$K$3*$K$2) -> 213194.75
B12: CHRIS T | C12: I664 | D12: 5869.5 | E12: 2288 | F12: 367.5 | G12: 0 | H12: 0 | I12: =SUM(D12:H12) -> 8525 | J12: =SUM(I12+A12) -> 8525 | K12: =SUM(J12/$K$3*$K$2) -> 42625 | M12: WEEK 1 | N12: 08/03/26 - 08/07/26 | O12: WEEK 1 ORDERS | P12: =SUM(I47) -> 371 | Q12: =SUM(I42) -> 760397.58
B13: MARK S | C13: I729 | D13: 2611.97 | E13: 2647.12 | F13: 3475.3 | G13: 1590.3 | H13: 364.7 | I13: =SUM(D13:H13) -> 10689.39 | J13: =SUM(I13+A13) -> 10689.39 | K13: =SUM(J13/$K$3*$K$2) -> 53446.95 | M13: WEEK 2 | N13: 08/10/26 - 08/14/26 | O13: WEEK 2 ORDERS | P13: =SUM('IL WEEK 2'!I47) -> 51 | Q13: =SUM('IL WEEK 2'!I42) -> 101771.22
B14: ALAN S | C14: I801 | D14: 557.5 | E14: 1942 | F14: 12753.6 | G14: 6119.6 | H14: 0 | I14: =SUM(D14:H14) -> 21372.7 | J14: =SUM(I14+A14) -> 21372.7 | K14: =SUM(J14/$K$3*$K$2) -> 106863.5 | M14: WEEK 3 | N14: 08/17/26 - 08/21/26 | O14: WEEK 3 ORDERS | P14: =SUM('[1]IL WEEK 3'!I47) -> 0 | Q14: =SUM('[1]IL WEEK 3'!I42) -> 0
B15: SAMUEL J | C15: I815 | D15: 2425.41 | E15: 232.5 | F15: 2979.35 | G15: 1175.88 | H15: 15459 | I15: =SUM(D15:H15) -> 22272.14 | J15: =SUM(I15+A15) -> 22272.14 | K15: =SUM(J15/$K$3*$K$2) -> 111360.7 | M15: WEEK 4 | N15: 08/24/26 - 08/28/26 | O15: WEEK 4 ORDERS | P15: =SUM('[1]IL WEEK 4'!I47) -> 0 | Q15: =SUM('[1]IL WEEK 4'!I42) -> 0
B16: DAVID S | C16: I830 | D16: 473.79 | E16: 1710 | F16: 863.7 | G16: 0 | H16: 3164.06 | I16: =SUM(D16:H16) -> 6211.55 | J16: =SUM(I16+A16) -> 6211.55 | K16: =SUM(J16/$K$3*$K$2) -> 31057.75 | M16: WEEK 5 | N16: 08/31/26 - 09/04/26 | O16: WEEK 5 ORDERS | P16: =SUM('[1]IL WEEK 5'!I47) -> 0 | Q16: =SUM('[1]IL WEEK 5'!I42) -> 0
B17: ROSS S | C17: I848 | D17: 1175 | E17: 0 | F17: 0 | G17: 0 | H17: 175 | I17: =SUM(D17:H17) -> 1350 | J17: =SUM(I17+A17) -> 1350 | K17: =SUM(J17/$K$3*$K$2) -> 6750 | P17: =SUM(P12:P16) -> 422 | Q17: =SUM(Q12:Q16) -> 862168.8
B18: ANTOINETTE V | C18: I856 | D18: 2819.4 | E18: 0 | F18: 567.95 | G18: 639.17 | H18: 2659.97 | I18: =SUM(D18:H18) -> 6686.49 | J18: =SUM(I18+A19) -> 6686.49 | K18: =SUM(J18/$K$3*$K$2) -> 33432.45
B19: JAVIER C | C19: I865 | D19: 4231.5 | E19: 501 | F19: 2279.88 | G19: 1075.5 | H19: 1551 | I19: =SUM(D19:H19) -> 9638.88 | J19: =SUM(I19+A20) -> 9638.88 | K19: =SUM(J19/$K$3*$K$2) -> 48194.4
B20: TIMOTHY C | C20: I867 | D20: 1504 | E20: 0 | F20: 3413.47 | G20: 355.5 | H20: 552 | I20: =SUM(D20:H20) -> 5824.97 | J20: =SUM(I20+A21) -> 5824.97 | K20: =SUM(J20/$K$3*$K$2) -> 29124.85 | M20: COMPANY DAILY WRITTEN AVERAGE PER DAY | P20: =SUM(J42/K3) -> 152079.52
B21: KELLSTEIN G | C21: I879 | D21: 0 | E21: 0 | F21: 0 | G21: 0 | H21: 0 | I21: =SUM(D21:H21) -> 0 | J21: =SUM(I21+A22) -> 0 | K21: =SUM(J21/$K$3*$K$2) -> 0 | M21: RETURNS THIS MONTH: | P21: 6366.58
B22: JOSE S. | C22: I887 | D22: 1025.33 | E22: 1914.85 | F22: 612 | G22: 843 | H22: 806.4 | I22: =SUM(D22:H22) -> 5201.58 | J22: =SUM(I22+A23) -> 5201.58 | K22: =SUM(J22/$K$3*$K$2) -> 26007.9 | M22: COMPANY WRITTEN MINUS RETURNS = | P22: =SUM(J42-P21) -> 754031 | Q22: PACE AFTER RETURNS | R22: WRITTEN AVERAGE AFTER RETURNS
B23: MARSHALL | C23: I891 | D23: 50 | E23: 139.5 | F23: 132 | G23: 2297.54 | H23: 275.5 | I23: =SUM(D23:H23) -> 2894.54 | J23: =SUM(I23+A25) -> 2894.54 | K23: =SUM(J23/$K$3*$K$2) -> 14472.7 | Q23: =SUM(P22/K3)*K2 -> 3770155 | R23: =SUM(Q23/K2) -> 150806.2
B24: AIDEN H | C24: I895 | D24: 3982.35 | E24: 530 | F24: 0 | G24: 375 | H24: 0 | I24: =SUM(D24:H24) -> 4887.35 | J24: =SUM(I24+A26) -> 4887.35 | K24: =SUM(J24/$K$3*$K$2) -> 24436.75
B25: MARTIN | C25: I898 | D25: 0 | E25: 0 | F25: 0 | G25: 0 | H25: 199 | I25: =SUM(D25:H25) -> 199 | J25: =SUM(I25+A27) -> 199 | K25: =SUM(J25/$K$3*$K$2) -> 995 | M25: SHIP #'S THROUGH August 7, 2026 : | P25: 580894.12
B26: MATT G | C26: I902 | D26: 3945.78 | E26: 1049 | F26: 6471 | G26: 1061 | H26: 736 | I26: =SUM(D26:H26) -> 13262.78 | J26: =SUM(I26+A28) -> 13262.78 | K26: =SUM(J26/$K$3*$K$2) -> 66313.9
B27: STOTTS | C27: I924 | D27: 34958.5 | E27: 18191 | F27: 8501.75 | G27: 13159 | H27: 12442 | I27: =SUM(D27:H27) -> 87252.25 | J27: =SUM(I27+A29) -> 87252.25 | K27: =SUM(J27/$K$3*$K$2) -> 436261.25
B28: HELIX HSE | C28: I944 | D28: 0 | E28: 0 | F28: 1386.6 | G28: 0 | H28: 1386.6 | I28: =SUM(D28:H28) -> 2773.2 | J28: =SUM(I28+A31) -> 2773.2 | K28: =SUM(J28/$K$3*$K$2) -> 13866 | M28: GAP: | N28: =SUM(P22-P25) -> 173136.88
I29: =SUM(D29:H29) -> 0 | J29: =SUM(I29+A29) -> 0 | K29: =SUM(J29/$K$3*$K$2) -> 0
I30: =SUM(D30:H30) -> 0 | J30: =SUM(I30+A30) -> 0 | K30: =SUM(J30/$K$3*$K$2) -> 0
I31: =SUM(D31:H31) -> 0 | J31: =SUM(I31+A31) -> 0 | K31: =SUM(J31/$K$3*$K$2) -> 0
I32: =SUM(D32:H32) -> 0 | J32: =SUM(I32+A32) -> 0 | K32: =SUM(J32/$K$3*$K$2) -> 0 | M32: AZ | N32: =SUM('AZ WEEK 1'!I21) -> 44.25 | O32: =SUM('AZ WEEK 1'!I18) -> 101658.48
I33: =SUM(D33:H33) -> 0 | J33: =SUM(I33+A33) -> 0 | K33: =SUM(J33/$K$3*$K$2) -> 0 | M33: IL | N33: =SUM(I45) -> 270.75 | O33: =SUM(I39) -> 468135.43
I34: =SUM(D34:H34) -> 0 | J34: =SUM(I34+A34) -> 0 | K34: =SUM(J34/$K$3*$K$2) -> 0 | M34: WI | N34: =SUM('WI WEEK 1'!I31) -> 56 | O34: =SUM('WI WEEK 1'!I28) -> 190603.67
I35: =SUM(D35:H35) -> 0 | J35: =SUM(I35+A35) -> 0 | K35: =SUM(J35/$K$3*$K$2) -> 0 | M35: TTL # OF ORDERS: | N35: =SUM(N32:N34) -> 371 | O35: =SUM(O32:O34) -> 760397.58
B36: Jason | C36: I069 | I36: =SUM(D36:H36) -> 0 | J36: =SUM(I36+A36) -> 0 | K36: =SUM(J36/$K$3*$K$2) -> 0
B37: MISC - IL | E37: 232.5 | G37: 230 | H37: 993.8 | I37: =SUM(D37:H37) -> 1456.3 | J37: =SUM(I37+A37) -> 1456.3 | K37: =SUM(J37/$K$3*$K$2) -> 7281.5 | M37: DIVISION | N37: SHIPPED
B38: HOUSE - IL | I38: =SUM(D38:H38) -> 0 | J38: =SUM(I38+A38) -> 0 | K38: =SUM(J38/$K$3*$K$2) -> 0 | M38: 00 | N38: 453558.24
A39: =SUM(A5:A38) -> 0 | B39: IL TOTAL | D39: =SUM(D5:D38) -> 151446.13 | E39: =SUM(E5:E38) -> 70486.43 | F39: =SUM(F5:F38) -> 74489.65 | G39: =SUM(G5:G38) -> 76242.54 | H39: =SUM(H5:H38) -> 95470.68 | I39: =SUM(I5:I38) -> 468135.43 | J39: =SUM(A39+I39) -> 468135.43 | K39: =SUM(J39/$K$3*$K$2) -> 2340677.1 | M39: 22 | N39: 81251.95
A40: =SUM('AZ WEEK 1'!A18) -> 0 | B40: AZ TOTAL | D40: =SUM('AZ WEEK 1'!D18) -> 31184.3 | E40: =SUM('AZ WEEK 1'!E18) -> 11708.52 | F40: =SUM('AZ WEEK 1'!F18) -> 46179.36 | G40: =SUM('AZ WEEK 1'!G18) -> 9952.3 | H40: =SUM('AZ WEEK 1'!H18) -> 2634 | I40: =SUM('AZ WEEK 1'!I18) -> 101658.48 | J40: =SUM('AZ WEEK 1'!I18) -> 101658.48 | K40: =SUM(J40/$K$3*$K$2) -> 508292.4 | M40: 33 | N40: 26340.95
...

Sheet AZ WEEK 1
A1: WEEK 1 | B1: ARIZONA SALES TOTALS | K1: AUGUST 2026 | M1: #VALUE!
C2: DAY | D2: 1 | E2: 2 | F2: 3 | G2: 4 | H2: 5 | J2: # of selling days: | K2: =SUM('IL WEEK 1'!K2) -> 25
A3: WEEK OF: 08/03/26 - 08/07/26 | D3: 46237 | E3: 46238 | F3: 46239 | G3: 46240 | H3: 46241 | J3: # days used: | K3: =SUM('IL WEEK 1'!K3) -> 5
A4: PREV WK TTL | B4: SALESPERSON | C4: S/P# | D4: MON | E4: TUES | F4: WED | G4: THURS | H4: FRI | I4: WKLY TTL | J4: TOTAL | K4: PACE
B5: ADAM R | C5: A550 | D5: 1936 | E5: 0 | F5: 9248.96 | G5: 4225 | H5: 1980 | I5: =SUM(D5:H5) -> 17389.96 | J5: =SUM(I5+A5) -> 17389.96 | K5: =SUM(J5/'IL WEEK 1'!$K$3*'IL WEEK 1'!$K$2) -> 86949.8
B6: JACOB M | C6: A607 | D6: 370 | E6: 0 | F6: 0 | G6: 260 | H6: 0 | I6: =SUM(D6:H6) -> 630 | J6: =SUM(I6+A6) -> 630 | K6: =SUM(J6/'IL WEEK 1'!$K$3*'IL WEEK 1'!$K$2) -> 3150
B7: LARRY A | C7: A654 | D7: 21560.8 | E7: 5978.21 | F7: 6059.15 | G7: 2571.3 | H7: 0 | I7: =SUM(D7:H7) -> 36169.46 | J7: =SUM(I7+A7) -> 36169.46 | K7: =SUM(J7/'IL WEEK 1'!$K$3*'IL WEEK 1'!$K$2) -> 180847.3
B8: MARK F | C8: A701 | D8: 0 | E8: 3937.31 | F8: 0 | G8: 1052 | H8: 0 | I8: =SUM(D8:H8) -> 4989.31 | J8: =SUM(I8+A8) -> 4989.31 | K8: =SUM(J8/'IL WEEK 1'!$K$3*'IL WEEK 1'!$K$2) -> 24946.55
B9: OLIN M | C9: A702 | D9: 7317.5 | E9: 1728 | F9: 6538 | G9: 1680 | H9: 424 | I9: =SUM(D9:H9) -> 17687.5 | J9: =SUM(I9+A9) -> 17687.5 | K9: =SUM(J9/'IL WEEK 1'!$K$3*'IL WEEK 1'!$K$2) -> 88437.5
B10: ALEX B | C10: A777 | D10: 0 | E10: 65 | F10: 24333.25 | G10: 24 | H10: 230 | I10: =SUM(D10:H10) -> 24652.25 | J10: =SUM(I10+A10) -> 24652.25 | K10: =SUM(J10/'IL WEEK 1'!$K$3*'IL WEEK 1'!$K$2) -> 123261.25
I11: =SUM(D11:H11) -> 0 | J11: =SUM(I11+A11) -> 0 | K11: =SUM(J11/'IL WEEK 1'!$K$3*'IL WEEK 1'!$K$2) -> 0
I12: =SUM(D12:H12) -> 0 | J12: =SUM(I12+A12) -> 0 | K12: =SUM(J12/'IL WEEK 1'!$K$3*'IL WEEK 1'!$K$2) -> 0 | M12: WEEK 1 | N12: 08/03/26 - 08/07/26
I13: =SUM(D13:H13) -> 0 | J13: =SUM(I13+A13) -> 0 | K13: =SUM(J13/'IL WEEK 1'!$K$3*'IL WEEK 1'!$K$2) -> 0 | M13: WEEK 2 | N13: 08/10/26 - 08/14/26
I14: =SUM(D14:H14) -> 0 | J14: =SUM(I14+A14) -> 0 | K14: =SUM(J14/'IL WEEK 1'!$K$3*'IL WEEK 1'!$K$2) -> 0 | M14: WEEK 3 | N14: 08/17/26 - 08/21/26
I15: =SUM(D15:H15) -> 0 | J15: =SUM(I15+A15) -> 0 | K15: =SUM(J15/'IL WEEK 1'!$K$3*'IL WEEK 1'!$K$2) -> 0 | M15: WEEK 4 | N15: 08/24/26 - 08/28/26
I16: =SUM(D16:H16) -> 0 | J16: =SUM(I16+A16) -> 0 | K16: =SUM(J16/'IL WEEK 1'!$K$3*'IL WEEK 1'!$K$2) -> 0 | M16: WEEK 5 | N16: 08/31/26 - 09/04/26
B17: HOUSE - AZ | C17: A111 | G17: 140 | I17: =SUM(D17:H17) -> 140 | J17: =SUM(I17+A17) -> 140 | K17: =SUM(J17/'IL WEEK 1'!$K$3*'IL WEEK 1'!$K$2) -> 700
A18: =SUM(A5:A17) -> 0 | B18: TOTALS | D18: =SUM(D5:D17) -> 31184.3 | E18: =SUM(E5:E17) -> 11708.52 | F18: =SUM(F5:F17) -> 46179.36 | G18: =SUM(G5:G17) -> 9952.3 | H18: =SUM(H5:H17) -> 2634 | I18: =SUM(I5:I17) -> 101658.48 | J18: =SUM(J5:J17) -> 101658.48 | K18: =SUM(J18/'IL WEEK 1'!$K$3*'IL WEEK 1'!$K$2) -> 508292.4
C19: DAY | D19: 1 | E19: 2 | F19: 3 | G19: 4 | H19: 5
D20: =D3 -> 46237 | E20: =E3 -> 46238 | F20: =F3 -> 46239 | G20: =G3 -> 46240 | H20: =H3 -> 46241
B21: # OF ORDERS - AZ OFFICE | D21: 11 | E21: 4 | F21: 17.75 | G21: 9.5 | H21: 2 | I21: =SUM(D21:H21) -> 44.25

Sheet WI WEEK 1
A1: WEEK 1 | B1: WISCONSIN SALES TOTALS | K1: AUGUST 2026 | M1: #VALUE!
C2: DAY | D2: 1 | E2: 2 | F2: 3 | G2: 4 | H2: 5 | J2: # of selling days: | K2: =SUM('IL WEEK 1'!K2) -> 25
A3: WEEK OF: 08/03/26 - 08/07/26 | D3: 46237 | E3: 46238 | F3: 46239 | G3: 46240 | H3: 46241 | J3: # days used: | K3: =SUM('IL WEEK 1'!K3) -> 5
A4: PREV WK TTL | B4: SALESPERSON | C4: S/P# | D4: MON | E4: TUE | F4: WED | G4: THURS | H4: FRI | I4: WKLY TTL | J4: TOTAL | K4: PACE
B5: ADAM WEST | C5: W603 | D5: 13283.94 | E5: 5812.94 | F5: 0 | G5: 0 | H5: 0 | I5: =SUM(D5:H5) -> 19096.88 | J5: =SUM(A5+I5) -> 19096.88 | K5: =SUM(J5/'IL WEEK 1'!$K$3*'IL WEEK 1'!$K$2) -> 95484.4
B6: KERRY SMITH | C6: W762 | D6: 0 | E6: 0 | F6: 547.2 | G6: 0 | H6: 0 | I6: =SUM(D6:H6) -> 547.2 | J6: =SUM(A6+I6) -> 547.2 | K6: =SUM(J6/'IL WEEK 1'!$K$3*'IL WEEK 1'!$K$2) -> 2736
B7: FROGGY | C7: W784 | D7: 18719.53 | E7: 0 | F7: 0 | G7: 6659.9 | H7: 7198 | I7: =SUM(D7:H7) -> 32577.43 | J7: =SUM(A7+I7) -> 32577.43 | K7: =SUM(J7/'IL WEEK 1'!$K$3*'IL WEEK 1'!$K$2) -> 162887.15
B8: RONNY B | C8: W839 | D8: 31819.5 | E8: 14799.1 | F8: 3742.5 | G8: 4908 | H8: 4716 | I8: =SUM(D8:H8) -> 59985.1 | J8: =SUM(A8+I8) -> 59985.1 | K8: =SUM(J8/'IL WEEK 1'!$K$3*'IL WEEK 1'!$K$2) -> 299925.5
B9: JOHN BAEMMERT | C9: W849 | D9: 11018.79 | E9: 1734.94 | F9: 893.79 | G9: 1026 | H9: 0 | I9: =SUM(D9:H9) -> 14673.52 | J9: =SUM(A9+I9) -> 14673.52 | K9: =SUM(J9/'IL WEEK 1'!$K$3*'IL WEEK 1'!$K$2) -> 73367.6
B10: LUIS MILLAN | C10: W909 | D10: 3866.2 | E10: 0 | F10: 0 | G10: 0 | H10: 0 | I10: =SUM(D10:H10) -> 3866.2 | J10: =SUM(A10+I10) -> 3866.2 | K10: =SUM(J10/'IL WEEK 1'!$K$3*'IL WEEK 1'!$K$2) -> 19331
B11: ADAM MISUREK | C11: W930 | D11: 6649.92 | E11: 2554.88 | F11: 18219.85 | G11: 0 | H11: 0 | I11: =SUM(D11:H11) -> 27424.65 | J11: =SUM(A11+I11) -> 27424.65 | K11: =SUM(J11/'IL WEEK 1'!$K$3*'IL WEEK 1'!$K$2) -> 137123.25
B12: GEOFF NURSE | C12: W938 | D12: 0 | E12: 284.99 | F12: 0 | G12: 0 | H12: 0 | I12: =SUM(D12:H12) -> 284.99 | J12: =SUM(A12+I12) -> 284.99 | K12: =SUM(J12/'IL WEEK 1'!$K$3*'IL WEEK 1'!$K$2) -> 1424.95 | M12: WEEK 1 | N12: 08/03/26 - 08/07/26
B13: Cassie Kolhouse | C13: W959 | D13: 0 | E13: 0 | F13: 0 | G13: 0 | H13: 0 | I13: =SUM(D13:H13) -> 0 | J13: =SUM(A13+I13) -> 0 | K13: =SUM(J13/'IL WEEK 1'!$K$3*'IL WEEK 1'!$K$2) -> 0 | M13: WEEK 2 | N13: 08/10/26 - 08/14/26
B14: CHRIS K | C14: W962 | D14: 545.94 | E14: 2343.88 | F14: 669.48 | G14: 297 | H14: 0 | I14: =SUM(D14:H14) -> 3856.3 | J14: =SUM(A14+I14) -> 3856.3 | K14: =SUM(J14/'IL WEEK 1'!$K$3*'IL WEEK 1'!$K$2) -> 19281.5 | M14: WEEK 3 | N14: 08/17/26 - 08/21/26
B15: BLAKE | C15: W966 | D15: 0 | E15: 0 | F15: 0 | G15: 0 | H15: 0 | I15: =SUM(D15:H15) -> 0 | J15: =SUM(A15+I15) -> 0 | K15: =SUM(J15/'IL WEEK 1'!$K$3*'IL WEEK 1'!$K$2) -> 0 | M15: WEEK 4 | N15: 08/24/26 - 08/28/26
B16: JAMES B. | C16: W967 | D16: 0 | E16: 0 | F16: 0 | G16: 0 | H16: 0 | I16: =SUM(D16:H16) -> 0 | J16: =SUM(A16+I16) -> 0 | K16: =SUM(J16/'IL WEEK 1'!$K$3*'IL WEEK 1'!$K$2) -> 0 | M16: WEEK 5 | N16: 08/31/26 - 09/04/26
B17: TJ SUTTON | C17: W973 | D17: 0 | E17: 0 | F17: 0 | G17: 0 | H17: 0 | I17: =SUM(D17:H17) -> 0 | J17: =SUM(A17+I17) -> 0 | K17: =SUM(J17/'IL WEEK 1'!$K$3*'IL WEEK 1'!$K$2) -> 0
B18: SCOT TOPORSH | C18: W983 | D18: 6999.5 | E18: 2522.48 | F18: 10688.13 | G18: 0 | H18: 569.97 | I18: =SUM(D18:H18) -> 20780.08 | J18: =SUM(A18+I18) -> 20780.08 | K18: =SUM(J18/'IL WEEK 1'!$K$3*'IL WEEK 1'!$K$2) -> 103900.4
I19: =SUM(D19:H19) -> 0 | J19: =SUM(A19+I19) -> 0 | K19: =SUM(J19/'IL WEEK 1'!$K$3*'IL WEEK 1'!$K$2) -> 0
I20: =SUM(D20:H20) -> 0 | J20: =SUM(A20+I20) -> 0 | K20: =SUM(J20/'IL WEEK 1'!$K$3*'IL WEEK 1'!$K$2) -> 0
I21: =SUM(D21:H21) -> 0 | J21: =SUM(A21+I21) -> 0 | K21: =SUM(J21/'IL WEEK 1'!$K$3*'IL WEEK 1'!$K$2) -> 0
I22: =SUM(D22:H22) -> 0 | J22: =SUM(A22+I22) -> 0 | K22: =SUM(J22/'IL WEEK 1'!$K$3*'IL WEEK 1'!$K$2) -> 0
I23: =SUM(D23:H23) -> 0 | J23: =SUM(A23+I23) -> 0 | K23: =SUM(J23/'IL WEEK 1'!$K$3*'IL WEEK 1'!$K$2) -> 0
I24: =SUM(D24:H24) -> 0 | J24: =SUM(A24+I24) -> 0 | K24: =SUM(J24/'IL WEEK 1'!$K$3*'IL WEEK 1'!$K$2) -> 0
I25: =SUM(D25:H25) -> 0 | J25: =SUM(A25+I25) -> 0 | K25: =SUM(J25/'IL WEEK 1'!$K$3*'IL WEEK 1'!$K$2) -> 0
I26: =SUM(D26:H26) -> 0 | J26: =SUM(A26+I26) -> 0 | K26: =SUM(J26/'IL WEEK 1'!$K$3*'IL WEEK 1'!$K$2) -> 0
B27: MISC - WI | F27: 3931.32 | G27: 3580 | I27: =SUM(D27:H27) -> 7511.32 | J27: =SUM(A27+I27) -> 7511.32 | K27: =SUM(J27/'IL WEEK 1'!$K$3*'IL WEEK 1'!$K$2) -> 37556.6
A28: =SUM(A5:A27) -> 0 | B28: TOTALS | D28: =SUM(D5:D27) -> 92903.32 | E28: =SUM(E5:E27) -> 30053.21 | F28: =SUM(F5:F27) -> 38692.27 | G28: =SUM(G5:G27) -> 16470.9 | H28: =SUM(H5:H27) -> 12483.97 | I28: =SUM(I5:I27) -> 190603.67 | J28: =SUM(J5:J27) -> 190603.67 | K28: =SUM(J28/'IL WEEK 1'!$K$3*'IL WEEK 1'!$K$2) -> 953018.35
C29: DAY | D29: 1 | E29: 2 | F29: 3 | G29: 4 | H29: 5
D30: =D3 -> 46237 | E30: =E3 -> 46238 | F30: =F3 -> 46239 | G30: =G3 -> 46240 | H30: =H3 -> 46241
B31: # OF ORDERS - WI OFFICE | D31: 17.5 | E31: 13 | F31: 15.5 | G31: 5 | H31: 5 | I31: =SUM(D31:H31) -> 56
