Workbook

Sheet 00W603
A1: SALES COMMISSION RECAP
A2: HIRE DATE | C2: 41029
A3: Salesman Name | C3: ADAM WEST
A4: Salesman # | C4: W603
A5: Payperiod Ending | C5: 46280
E6: COMMISSIONS
C7: DBW | D7: HELIX | E7: Miscellaneous | F7: Total
A8: Sales
B9: 46267 | C9: 227.32 | D9: 0 | E9: 0 | F9: =SUM(C9:E9) -> 227.32
B10: 46268 | C10: 202.176 | D10: 0 | E10: 0 | F10: =SUM(C10:E10) -> 202.176
B11: 46269 | C11: 361.2 | D11: 0 | E11: 0 | F11: =SUM(C11:E11) -> 361.2
B12: 46272 | C12: 0 | D12: 0 | E12: 0 | F12: =SUM(C12:E12) -> 0
B13: 46273 | C13: 0 | D13: 0 | E13: 0 | F13: =SUM(C13:E13) -> 0
B14: 46274 | C14: 1729.384 | D14: 0 | E14: 0 | F14: =SUM(C14:E14) -> 1729.384
B15: 46275 | C15: 264.02 | D15: 0 | E15: 0 | F15: =SUM(C15:E15) -> 264.02
B16: 46276 | C16: 1.38 | D16: 0 | E16: 0 | F16: =SUM(C16:E16) -> 1.38
B17: 46279 | C17: 98.38 | D17: 0 | E17: 0 | F17: =SUM(C17:E17) -> 98.38
B18: 46280 | C18: 0 | D18: 0 | E18: 0 | F18: =SUM(C18:E18) -> 0
B19: Extra 1
B20: Extra 2
B21: Extra 3
B22: Extra 4
B23: Extra 5
B24: Total | C24: =SUM(C9:C23) -> 2883.86 | D24: =SUM(D9:D23) -> 0 | E24: =SUM(E9:E23) -> 0 | F24: =SUM(F9:F23) -> 2883.86
A26: Returns
A27: Cust # | B27: Inv #
F28: 0
F29: 0
F30: 0
F31: 0
F32: =SUM(F28:F31) -> 0
A34: 120 Day Chews
A35: Cust # | B35: Inv #
F36: 0
F37: 0
F38: 0
F39: 0
F40: 0
F41: 0
F42: 0
...

Sheet 00W762
A1: SALES COMMISSION RECAP
A2: HIRE DATE | C2: 37503
A3: Salesman Name | C3: Kerry Smith
A4: Salesman # | C4: W762
A5: Payperiod Ending | C5: ='00W603'!C5 -> 46280
E6: COMMISSIONS
C7: DBW | D7: HELIX | E7: MISC | F7: Total
A8: Sales
B9: ='00W603'!B9 -> 46267 | C9: 0 | D9: 0 | E9: 0 | F9: =SUM(C9:E9) -> 0
B10: ='00W603'!B10 -> 46268 | C10: 0 | D10: 0 | E10: 0 | F10: =SUM(C10:E10) -> 0
B11: ='00W603'!B11 -> 46269 | C11: 0 | D11: 0 | E11: 0 | F11: =SUM(C11:E11) -> 0
B12: ='00W603'!B12 -> 46272 | C12: 0 | D12: 0 | E12: 0 | F12: =SUM(C12:E12) -> 0
B13: ='00W603'!B13 -> 46273 | C13: 0 | D13: 0 | E13: 0 | F13: =SUM(C13:E13) -> 0
B14: ='00W603'!B14 -> 46274 | C14: 18 | D14: 0 | E14: 0 | F14: =SUM(C14:E14) -> 18
B15: ='00W603'!B15 -> 46275 | C15: 171.185 | D15: 0 | E15: 0 | F15: =SUM(C15:E15) -> 171.185
B16: ='00W603'!B16 -> 46276 | C16: 0 | D16: 0 | E16: 0 | F16: =SUM(C16:E16) -> 0
B17: ='00W603'!B17 -> 46279 | C17: 0 | D17: 0 | E17: 0 | F17: =SUM(C17:E17) -> 0
B18: ='00W603'!B18 -> 46280 | C18: 0 | D18: 0 | E18: 0 | F18: =SUM(C18:E18) -> 0
B19: =+'00W603'!B19 -> Extra 1
B20: =+'00W603'!B20 -> Extra 2
B21: Extra 3
B22: Extra 4
B23: Extra 5
B24: Total | C24: =SUM(C9:C23) -> 189.185 | D24: =SUM(D9:D23) -> 0 | E24: =SUM(E9:E23) -> 0 | F24: =SUM(F9:F23) -> 189.185
A26: Returns
A27: Cust # | B27: Inv #
F28: 0
F29: 0
F30: 0
F31: 0
F32: 0
F33: =SUM(F28:F32) -> 0
A35: 120 day chews
A36: Cust # | B36: Inv #
F37: 0
F38: 0
F39: 0
F40: =SUM(F37:F39) -> 0
A41: Adjustments
A42: 09/01 payroll shortfall | F42: -15.12
...

Sheet 00W784
A1: SALES COMMISSION RECAP
A2: Start Date | C2: 42375
A3: Salesman Name | C3: JUSTIN GRECO
A4: Salesman # | C4: W784
A5: Payperiod Ending | C5: =+'00W603'!C5 -> 46280
E6: COMMISSIONS
C7: DBW | D7: HELIX | E7: MISC | F7: Total
A8: Sales
B9: =+'00W603'!B9 -> 46267 | C9: 478.0528 | D9: 0 | E9: 0 | F9: =SUM(C9:E9) -> 478.0528
B10: =+'00W603'!B10 -> 46268 | C10: 202.176 | D10: 0 | E10: 0 | F10: =SUM(C10:E10) -> 202.176
B11: =+'00W603'!B11 -> 46269 | C11: 272.1164 | D11: 0 | E11: 0 | F11: =SUM(C11:E11) -> 272.1164
B12: =+'00W603'!B12 -> 46272 | C12: 0 | D12: 0 | E12: 0 | F12: =SUM(C12:E12) -> 0
B13: =+'00W603'!B13 -> 46273 | C13: 825.96 | D13: 0 | E13: 0 | F13: =SUM(C13:E13) -> 825.96
B14: ='00W603'!B14 -> 46274 | C14: 0 | D14: 0 | E14: 0 | F14: =SUM(C14:E14) -> 0
B15: ='00W603'!B15 -> 46275 | C15: 0 | D15: 0 | E15: 0 | F15: =SUM(C15:E15) -> 0
B16: ='00W603'!B16 -> 46276 | C16: 712.05 | D16: 0 | E16: 0 | F16: =SUM(C16:E16) -> 712.05
B17: ='00W603'!B17 -> 46279 | C17: 84.8 | D17: 0 | E17: 0 | F17: =SUM(C17:E17) -> 84.8
B18: ='00W603'!B18 -> 46280 | C18: 0 | D18: 0 | E18: 0 | F18: =SUM(C18:E18) -> 0
B19: =+'00W603'!B19 -> Extra 1
B20: =+'00W603'!B20 -> Extra 2
B21: =+'00W603'!B21 -> Extra 3
B22: =+'00W603'!B22 -> Extra 4
B23: Total | C23: =SUM(C9:C22) -> 2575.1552 | D23: =SUM(D9:D22) -> 0 | E23: =SUM(E9:E22) -> 0 | F23: =SUM(F9:F22) -> 2575.1552
A25: Returns
A26: Cust # | B26: Inv #
A27: MID4444 | B27: 633991 | F27: -253.14
F28: 0
F29: 0
F30: 0
F31: 0
F32: =SUM(F27:F31) -> -253.14
A34: 120 day chews
A35: Cust # | B35: Inv #
F36: 0
F37: 0
F38: 0
F39: 0
F40: =SUM(F36:F39) -> 0
A41: Adjustments
A42: 9/3 spiff | F42: 100
...

Sheet 00W839
A1: SALES COMMISSION RECAP
A2: HIRE DATE | C2: 42830
A3: Salesman Name | C3: RONALD BONICH
A4: Salesman # | C4: W839
A5: Payperiod Ending | C5: ='00W603'!C5 -> 46280
E6: COMMISSIONS
C7: DBW | D7: HELIX | E7: HELIX TOOLS | F7: Total
A8: Sales
B9: ='00W603'!B9 -> 46267 | C9: -93.96 | D9: 0 | E9: 0 | F9: =SUM(C9:E9) -> -93.96
B10: =+'00W603'!B10 -> 46268 | C10: 0 | D10: 0 | E10: 0 | F10: =SUM(C10:E10) -> 0
B11: ='00W603'!B11 -> 46269 | C11: 323.81 | D11: 0 | E11: 0 | F11: =SUM(C11:E11) -> 323.81
B12: ='00W603'!B12 -> 46272 | C12: 0 | D12: 0 | E12: 0 | F12: =SUM(C12:E12) -> 0
B13: ='00W603'!B13 -> 46273 | C13: 1158.42 | D13: 0 | E13: 0 | F13: =SUM(C13:E13) -> 1158.42
B14: ='00W603'!B14 -> 46274 | C14: 0 | D14: 0 | E14: 0 | F14: =SUM(C14:E14) -> 0
B15: ='00W603'!B15 -> 46275 | C15: 0 | D15: 0 | E15: 0 | F15: =SUM(C15:E15) -> 0
B16: ='00W603'!B16 -> 46276 | C16: 0 | D16: 0 | E16: 0 | F16: =SUM(C16:E16) -> 0
B17: ='00W603'!B17 -> 46279 | C17: 0 | D17: 0 | E17: 0 | F17: =SUM(C17:E17) -> 0
B18: ='00W603'!B18 -> 46280 | C18: 0 | D18: 0 | E18: 0 | F18: =SUM(C18:E18) -> 0
B19: =+'00W603'!B19 -> Extra 1
B20: =+'00W603'!B20 -> Extra 2
B21: Extra 3
B22: Extra 4
B23: Extra 5
B24: Total | C24: =SUM(C9:C23) -> 1388.27 | D24: =SUM(D9:D23) -> 0 | E24: =SUM(E9:E23) -> 0 | F24: =SUM(F9:F23) -> 1388.27
A26: Returns
A27: Cust # | B27: Inv #
F28: 0
F29: 0
F30: 0
F31: =SUM(F28:F30) -> 0
A33: 120 Day Chews
A34: Cust # | B34: Inv #
F35: 0
F36: 0
F37: 0
F38: 0
F39: =SUM(F35:F38) -> 0
A40: Adjustments
A41: Cust # | B41: Inv #
F42: 0
...

Sheet 00W909
A1: SALES COMMISSION RECAP
A2: HIRE DATE | C2: 45819
A3: Salesperson Name | C3: LUIS MILLAN
A4: Salesperson # | C4: W909
A5: Payperiod Ending | C5: ='00W603'!C5 -> 46280
C7: DBW | D7: HELIX | E7: HELIX TOOLS | F7: Total
A8: Sales
B9: ='00W603'!B9 -> 46267 | C9: 0 | D9: 0 | E9: 0 | F9: =SUM(C9:E9) -> 0
B10: =+'00W603'!B10 -> 46268 | C10: 0 | D10: 0 | E10: 0 | F10: =SUM(C10:E10) -> 0
B11: ='00W603'!B11 -> 46269 | C11: 0 | D11: 0 | E11: 0 | F11: =SUM(C11:E11) -> 0
B12: ='00W603'!B12 -> 46272 | C12: 0 | D12: 0 | E12: 0 | F12: =SUM(C12:E12) -> 0
B13: ='00W603'!B13 -> 46273 | C13: 0 | D13: 0 | E13: 0 | F13: =SUM(C13:E13) -> 0
B14: ='00W603'!B14 -> 46274 | C14: 44.6775 | D14: 0 | E14: 0 | F14: =SUM(C14:E14) -> 44.6775
B15: ='00W603'!B15 -> 46275 | C15: 8.1 | D15: 0 | E15: 0 | F15: =SUM(C15:E15) -> 8.1
B16: ='00W603'!B16 -> 46276 | C16: 0 | D16: 0 | E16: 0 | F16: =SUM(C16:E16) -> 0
B17: =+'00W603'!B17 -> 46279 | C17: 0 | D17: 0 | E17: 0 | F17: =SUM(C17:E17) -> 0
B18: ='00W603'!B18 -> 46280 | C18: 970.655 | D18: 0 | E18: 0 | F18: =SUM(C18:E18) -> 970.655
B19: =+'00W603'!B19 -> Extra 1
B20: =+'00W603'!B20 -> Extra 2
B21: Extra 3
B22: Extra 4
B23: Extra 5
B24: Total | C24: =SUM(C9:C23) -> 1023.4325 | D24: =SUM(D9:D23) -> 0 | E24: =SUM(E9:E23) -> 0 | F24: =SUM(F9:F23) -> 1023.4325
A26: Returns
A27: Cust # | B27: Inv #
F28: 0
F29: 0
F30: 0
F31: 0
F32: =SUM(F28:F31) -> 0
A34: 120 Day Chews
A35: Cust # | B35: Inv #
F37: 0
F38: 0
F39: 0
F40: 0
F41: 0
F42: =SUM(F36:F41) -> 0
A43: Adjustments
A44: Cust # | B44: Inv #
...

Sheet 00W849
A1: SALES COMMISSION RECAP
A2: HIRE DATE | C2: 44669
A3: Salesman Name | C3: John Baemmert
A4: Salesman # | C4: 00W849
A5: Payperiod Ending | C5: =+'00W603'!C5 -> 46280
C7: DBW | D7: HELIX | E7: HELIX TOOLS | F7: Total
A8: Sales
B9: ='00W603'!B9 -> 46267 | C9: 0 | D9: 0 | E9: 0 | F9: =SUM(C9:E9) -> 0
B10: =+'00W603'!B10 -> 46268 | C10: 599.95 | D10: 0 | E10: 0 | F10: =SUM(C10:E10) -> 599.95
B11: ='00W603'!B11 -> 46269 | C11: 97.7377 | D11: 0 | E11: 0 | F11: =SUM(C11:E11) -> 97.7377
B12: ='00W603'!B12 -> 46272 | C12: 0 | D12: 0 | E12: 0 | F12: =SUM(C12:E12) -> 0
B13: ='00W603'!B13 -> 46273 | C13: 0 | D13: 0 | E13: 0 | F13: =SUM(C13:E13) -> 0
B14: ='00W603'!B14 -> 46274 | C14: 0 | D14: 0 | E14: 0 | F14: =SUM(C14:E14) -> 0
B15: ='00W603'!B15 -> 46275 | C15: 0 | D15: 0 | E15: 0 | F15: =SUM(C15:E15) -> 0
B16: ='00W603'!B16 -> 46276 | C16: 0 | D16: 0 | E16: 0 | F16: =SUM(C16:E16) -> 0
B17: ='00W603'!B17 -> 46279 | C17: 74.35 | D17: 0 | E17: 0 | F17: =SUM(C17:E17) -> 74.35
B18: ='00W603'!B18 -> 46280 | C18: 0 | D18: 0 | E18: 0 | F18: =SUM(C18:E18) -> 0
B19: =+'00W603'!B19 -> Extra 1
B20: =+'00W603'!B20 -> Extra 2
B21: Extra 3
B22: Extra 4
B23: Extra 5
B24: Total | C24: =SUM(C9:C23) -> 772.0377 | D24: =SUM(D9:D23) -> 0 | E24: =SUM(E9:E23) -> 0 | F24: =SUM(F9:F23) -> 772.0377
A26: Returns
A27: Cust # | B27: Inv #
F28: 0
F29: 0
F30: 0
F31: =SUM(F28:F30) -> 0
A33: 120 Day Chews
A34: Cust # | B34: Inv #
A35: MSY2025 | B35: 627887 | F35: -75
F36: 0
F37: 0
F38: 0
F39: =SUM(F35:F38) -> -75
A40: Adjustments
A41: Cust # | B41: Inv #
A42: DPD2026 | B42: 629580 | C42: PWWGP 50% - paid in full 9/8/26 | F42: 497.77
A43: EDD2026 | B43: 629756 | C43: PWWGP 50%-paid with CBP 9/15/26 | F43: 492.84
...

Sheet 00W930
A1: SALES COMMISSION RECAP
A2: Start Date | C2: 43164
A3: Salesman Name | C3: ADAM MISUREK
A4: Salesman # | C4: W930
A5: Payperiod Ending | C5: =+'00W603'!C5 -> 46280
E6: COMMISSIONS
C7: DBW | D7: HELIX | E7: MISC | F7: Total
A8: Sales
B9: ='00W603'!B9 -> 46267 | C9: 692.47 | D9: 0 | E9: 0 | F9: =SUM(C9:E9) -> 692.47
B10: ='00W603'!B10 -> 46268 | C10: 27.1775 | D10: 0 | E10: 0 | F10: =SUM(C10:E10) -> 27.1775
B11: ='00W603'!B11 -> 46269 | C11: 0 | D11: 0 | E11: 0 | F11: =SUM(C11:E11) -> 0
B12: ='00W603'!B12 -> 46272 | C12: 0 | D12: 0 | E12: 0 | F12: =SUM(C12:E12) -> 0
B13: ='00W603'!B13 -> 46273 | C13: 0 | D13: 0 | E13: 0 | F13: =SUM(C13:E13) -> 0
B14: ='00W603'!B14 -> 46274 | C14: 780 | D14: 0 | E14: 0 | F14: =SUM(C14:E14) -> 780
B15: ='00W603'!B15 -> 46275 | C15: 209.196 | D15: 0 | E15: 0 | F15: =SUM(C15:E15) -> 209.196
B16: ='00W603'!B16 -> 46276 | C16: 229.125 | D16: 0 | E16: 0 | F16: =SUM(C16:E16) -> 229.125
B17: =+'00W603'!B17 -> 46279 | C17: 0 | D17: 0 | E17: 0 | F17: =SUM(C17:E17) -> 0
B18: ='00W603'!B18 -> 46280 | C18: 774.845 | D18: 0 | E18: 0 | F18: =SUM(C18:E18) -> 774.845
B19: =+'00W603'!B19 -> Extra 1
B20: =+'00W603'!B20 -> Extra 2
B21: Extra 3
B22: Extra 4
B23: Extra 5
B24: Total | C24: =SUM(C9:C23) -> 2712.8135 | D24: =SUM(D9:D23) -> 0 | E24: =SUM(E9:E23) -> 0 | F24: =SUM(F9:F23) -> 2712.8135
A26: Returns
A27: Cust # | B27: Inv #
F28: 0
F29: 0
F30: 0
F31: 0
F32: =SUM(F28:F31) -> 0
A34: 120 day chews
A35: Cust # | B35: Inv #
F36: 0
F37: 0
F38: 0
F39: 0
F40: =SUM(F36:F39) -> 0
A41: Adjustments
F42: 0
...

Sheet 00W934
A1: SALES COMMISSION RECAP
A2: HIRE DATE | C2: 45825
A3: Salesman Name | C3: Les Kubeny
A4: Salesman # | C4: W934
A5: Payperiod Ending | C5: ='00W603'!C5 -> 46280
C7: DBW | D7: HELIX | E7: HELIX TOOLS | F7: Total
A8: Sales
B9: ='00W603'!B9 -> 46267 | C9: 0 | D9: 0 | E9: 0 | F9: =SUM(C9:E9) -> 0
B10: =+'00W603'!B10 -> 46268 | C10: 0 | D10: 0 | E10: 0 | F10: =SUM(C10:E10) -> 0
B11: ='00W603'!B11 -> 46269 | C11: 0 | D11: 0 | E11: 0 | F11: =SUM(C11:E11) -> 0
B12: ='00W603'!B12 -> 46272 | C12: 0 | D12: 0 | E12: 0 | F12: =SUM(C12:E12) -> 0
B13: ='00W603'!B13 -> 46273 | C13: 0 | D13: 0 | E13: 0 | F13: =SUM(C13:E13) -> 0
B14: ='00W603'!B14 -> 46274 | C14: 187.11 | D14: 0 | E14: 0 | F14: =SUM(C14:E14) -> 187.11
B15: ='00W603'!B15 -> 46275 | C15: 0 | D15: 0 | E15: 0 | F15: =SUM(C15:E15) -> 0
B16: ='00W603'!B16 -> 46276 | C16: 1.38 | D16: 0 | E16: 0 | F16: =SUM(C16:E16) -> 1.38
B17: =+'00W603'!B17 -> 46279 | C17: 0 | D17: 0 | E17: 0 | F17: =SUM(C17:E17) -> 0
B18: ='00W603'!B18 -> 46280 | C18: 0 | D18: 0 | E18: 0 | F18: =SUM(C18:E18) -> 0
B19: =+'00W603'!B19 -> Extra 1
B20: =+'00W603'!B20 -> Extra 2
B21: Extra 3
B22: Extra 4
B23: Extra 5
B24: Total | C24: =SUM(C9:C23) -> 188.49 | D24: =SUM(D9:D23) -> 0 | E24: =SUM(E9:E23) -> 0 | F24: =SUM(F9:F23) -> 188.49
A26: Returns
A27: Cust # | B27: Inv #
F28: 0
F29: 0
F30: 0
F31: 0
F32: =SUM(F28:F31) -> 0
A34: 120 Day Chews
A35: Cust # | B35: Inv #
F36: 0
F37: 0
F38: 0
F39: 0
F40: 0
F41: 0
F42: =SUM(F36:F41) -> 0
A43: Adjustments
...

Sheet 00W938
A1: SALES COMMISSION RECAP
A2: HIRE DATE | C2: 1/6/25 - REHIRE
A3: Salesperson Name | C3: GEOFFREY NURSE
A4: Salesperson # | C4: W938
A5: Payperiod Ending | C5: ='00W603'!C5 -> 46280
C7: DBW | D7: HELIX | E7: HELIX TOOLS | F7: Total
A8: Sales
B9: ='00W603'!B9 -> 46267 | C9: 0 | D9: 0 | E9: 0 | F9: =SUM(C9:E9) -> 0
B10: =+'00W603'!B10 -> 46268 | C10: 0 | D10: 0 | E10: 0 | F10: =SUM(C10:E10) -> 0
B11: ='00W603'!B11 -> 46269 | C11: 0 | D11: 0 | E11: 0 | F11: =SUM(C11:E11) -> 0
B12: ='00W603'!B12 -> 46272 | C12: 0 | D12: 0 | E12: 0 | F12: =SUM(C12:E12) -> 0
B13: ='00W603'!B13 -> 46273 | C13: 0 | D13: 0 | E13: 0 | F13: =SUM(C13:E13) -> 0
B14: ='00W603'!B14 -> 46274 | C14: 0 | D14: 0 | E14: 0 | F14: =SUM(C14:E14) -> 0
B15: ='00W603'!B15 -> 46275 | C15: 0 | D15: 0 | E15: 0 | F15: =SUM(C15:E15) -> 0
B16: ='00W603'!B16 -> 46276 | C16: 0 | D16: 0 | E16: 0 | F16: =SUM(C16:E16) -> 0
B17: =+'00W603'!B17 -> 46279 | C17: 74.35 | D17: 0 | E17: 0 | F17: =SUM(C17:E17) -> 74.35
B18: ='00W603'!B18 -> 46280 | C18: 0 | D18: 0 | E18: 0 | F18: =SUM(C18:E18) -> 0
B19: =+'00W603'!B19 -> Extra 1
B20: =+'00W603'!B20 -> Extra 2
B21: Extra 3
B22: Extra 4
B23: Extra 5
B24: Total | C24: =SUM(C9:C23) -> 74.35 | D24: =SUM(D9:D23) -> 0 | E24: =SUM(E9:E23) -> 0 | F24: =SUM(F9:F23) -> 74.35
A26: Returns
A27: Cust # | B27: Inv #
F28: 0
F29: 0
F30: 0
F31: 0
F32: =SUM(F28:F31) -> 0
A34: 120 Day Chews
A35: Cust # | B35: Inv #
F36: 0
F37: 0
F38: 0
F39: 0
F40: 0
F41: =SUM(F36:F40) -> 0
A42: Adjustments
A43: Cust # | B43: Inv #
...

Sheet 00W959
A1: SALES COMMISSION RECAP
A2: HIRE DATE | C2: 45936
A3: Salesperson Name | C3: CASSANDRA KOLHOUSE
A4: Salesperson # | C4: W959
A5: Payperiod Ending | C5: ='00W603'!C5 -> 46280
C7: DBW | D7: HELIX | E7: HELIX TOOLS | F7: Total
A8: Sales
B9: ='00W603'!B9 -> 46267 | C9: 41.18 | D9: 0 | E9: 0 | F9: =SUM(C9:E9) -> 41.18
B10: =+'00W603'!B10 -> 46268 | C10: 126.61 | D10: 0 | E10: 0 | F10: =SUM(C10:E10) -> 126.61
B11: ='00W603'!B11 -> 46269 | C11: 109.36 | D11: 0 | E11: 0 | F11: =SUM(C11:E11) -> 109.36
B12: ='00W603'!B12 -> 46272 | C12: 0 | D12: 0 | E12: 0 | F12: =SUM(C12:E12) -> 0
B13: ='00W603'!B13 -> 46273 | C13: 0 | D13: 0 | E13: 0 | F13: =SUM(C13:E13) -> 0
B14: ='00W603'!B14 -> 46274 | C14: 0 | D14: 0 | E14: 0 | F14: =SUM(C14:E14) -> 0
B15: ='00W603'!B15 -> 46275 | C15: 485.605 | D15: 0 | E15: 0 | F15: =SUM(C15:E15) -> 485.605
B16: ='00W603'!B16 -> 46276 | C16: 0 | D16: 0 | E16: 0 | F16: =SUM(C16:E16) -> 0
B17: =+'00W603'!B17 -> 46279 | C17: 0 | D17: 0 | E17: 0 | F17: =SUM(C17:E17) -> 0
B18: ='00W603'!B18 -> 46280 | C18: 0 | D18: 0 | E18: 0 | F18: =SUM(C18:E18) -> 0
B19: =+'00W603'!B19 -> Extra 1
B20: =+'00W603'!B20 -> Extra 2
B21: Extra 3
B22: Extra 4
B23: Extra 5
B24: Total | C24: =SUM(C9:C23) -> 762.755 | D24: =SUM(D9:D23) -> 0 | E24: =SUM(E9:E23) -> 0 | F24: =SUM(F9:F23) -> 762.755
A26: Returns
A27: Cust # | B27: Inv #
F28: 0
F29: 0
F30: 0
F31: 0
F32: =SUM(F28:F31) -> 0
A34: 120 Day Chews
A35: Cust # | B35: Inv #
F36: 0
F37: 0
F38: 0
F39: 0
F40: 0
F41: 0
F42: =SUM(F36:F41) -> 0
A43: Adjustments
...

Sheet 00W962
A1: SALES COMMISSION RECAP
A2: HIRE DATE | C2: 45960
A3: Salesperson Name | C3: CHRISTOPHER KUSSROW
A4: Salesperson # | C4: W962
A5: Payperiod Ending | C5: ='00W603'!C5 -> 46280
C7: DBW | D7: HELIX | E7: HELIX TOOLS | F7: Total
A8: Sales
B9: ='00W603'!B9 -> 46267 | C9: 71.6794 | D9: 0 | E9: 0 | F9: =SUM(C9:E9) -> 71.6794
B10: =+'00W603'!B10 -> 46268 | C10: 0 | D10: 0 | E10: 0 | F10: =SUM(C10:E10) -> 0
B11: ='00W603'!B11 -> 46269 | C11: 245.7825 | D11: 0 | E11: 0 | F11: =SUM(C11:E11) -> 245.7825
B12: ='00W603'!B12 -> 46272 | C12: 0 | D12: 0 | E12: 0 | F12: =SUM(C12:E12) -> 0
B13: ='00W603'!B13 -> 46273 | C13: 405 | D13: 0 | E13: 0 | F13: =SUM(C13:E13) -> 405
B14: ='00W603'!B14 -> 46274 | C14: 67.5 | D14: 0 | E14: 0 | F14: =SUM(C14:E14) -> 67.5
B15: ='00W603'!B15 -> 46275 | C15: 0 | D15: 0 | E15: 0 | F15: =SUM(C15:E15) -> 0
B16: ='00W603'!B16 -> 46276 | C16: 0 | D16: 0 | E16: 0 | F16: =SUM(C16:E16) -> 0
B17: =+'00W603'!B17 -> 46279 | C17: 0 | D17: 0 | E17: 0 | F17: =SUM(C17:E17) -> 0
B18: ='00W603'!B18 -> 46280 | C18: 62.5 | D18: 0 | E18: 0 | F18: =SUM(C18:E18) -> 62.5
B19: =+'00W603'!B19 -> Extra 1
B20: =+'00W603'!B20 -> Extra 2
B21: Extra 3
B22: Extra 4
B23: Extra 5
B24: Total | C24: =SUM(C9:C23) -> 852.4619 | D24: =SUM(D9:D23) -> 0 | E24: =SUM(E9:E23) -> 0 | F24: =SUM(F9:F23) -> 852.4619
A26: Returns
A27: Cust # | B27: Inv #
A28: CGC2933 | B28: 629901 | F28: -22.5
A29: CRL2020 | B29: 633667 | F29: -405
F30: 0
F31: 0
F32: =SUM(F28:F31) -> -427.5
A34: 120 Day Chews
A35: Cust # | B35: Inv #
A36: AJD1380 | B36: 628389 | F36: -18.25
F37: 0
F38: 0
F39: 0
F40: 0
F41: 0
F42: =SUM(F36:F41) -> -18.25
A43: Adjustments
...

Sheet 00W973
A1: SALES COMMISSION RECAP
A2: HIRE DATE | C2: 43887
A3: Salesman Name | C3: ANTHONY SUTTON
A4: Salesman # | C4: 00W973
A5: Payperiod Ending | C5: ='00W603'!C5 -> 46280
C7: DBW | D7: HELIX | E7: MISC | F7: Total
A8: Sales
B9: ='00W603'!B9 -> 46267 | C9: 0 | D9: 0 | E9: 0 | F9: =SUM(C9:E9) -> 0
B10: =+'00W603'!B10 -> 46268 | C10: 0 | D10: 0 | E10: 0 | F10: =SUM(C10:E10) -> 0
B11: ='00W603'!B11 -> 46269 | C11: 0 | D11: 0 | E11: 0 | F11: =SUM(C11:E11) -> 0
B12: ='00W603'!B12 -> 46272 | C12: 0 | D12: 0 | E12: 0 | F12: =SUM(C12:E12) -> 0
B13: ='00W603'!B13 -> 46273 | C13: 0 | D13: 0 | E13: 0 | F13: =SUM(C13:E13) -> 0
B14: ='00W603'!B14 -> 46274 | C14: 0 | D14: 0 | E14: 0 | F14: =SUM(C14:E14) -> 0
B15: ='00W603'!B15 -> 46275 | C15: 1022.5707 | D15: 0 | E15: 0 | F15: =SUM(C15:E15) -> 1022.5707
B16: ='00W603'!B16 -> 46276 | C16: 0 | D16: 0 | E16: 0 | F16: =SUM(C16:E16) -> 0
B17: ='00W603'!B17 -> 46279 | C17: 0 | D17: 0 | E17: 0 | F17: =SUM(C17:E17) -> 0
B18: ='00W603'!B18 -> 46280 | C18: 210.92 | D18: 0 | E18: 0 | F18: =SUM(C18:E18) -> 210.92
B19: =+'00W603'!B19 -> Extra 1
B20: =+'00W603'!B20 -> Extra 2
B21: Extra 3
B22: Extra 4
B23: Extra 5
B24: Total | C24: =SUM(C9:C23) -> 1233.4907 | D24: =SUM(D9:D23) -> 0 | E24: =SUM(E9:E23) -> 0 | F24: =SUM(F9:F23) -> 1233.4907
A26: Returns
A27: Cust # | B27: Inv #
F28: 0
F29: 0
F30: 0
F31: 0
F32: =SUM(F28:F31) -> 0
A34: 120 Day Chews
A35: Cust # | B35: Inv #
F36: 0
F37: 0
F38: 0
F39: 0
F40: 0
F41: =SUM(F36:F40) -> 0
A42: Adjustments
A43: Cust # | B43: Inv #
...

Sheet 00W983
A1: SALES COMMISSION RECAP
A2: HIRE DATE | C2: 44067
A3: Salesman Name | C3: SCOTT TOPORSH
A4: Salesman # | C4: W983
A5: Payperiod Ending | C5: =+'00W603'!C5 -> 46280
C7: DBW | D7: HELIX | E7: HELIX TOOLS | F7: Total
A8: Sales
B9: ='00W603'!B9 -> 46267 | C9: 0 | D9: 0 | E9: 0 | F9: =SUM(C9:E9) -> 0
B10: =+'00W603'!B10 -> 46268 | C10: 66.96 | D10: 0 | E10: 0 | F10: =SUM(C10:E10) -> 66.96
B11: ='00W603'!B11 -> 46269 | C11: 1173.2 | D11: 0 | E11: 0 | F11: =SUM(C11:E11) -> 1173.2
B12: ='00W603'!B12 -> 46272 | C12: 0 | D12: 0 | E12: 0 | F12: =SUM(C12:E12) -> 0
B13: ='00W603'!B13 -> 46273 | C13: 0 | D13: 0 | E13: 0 | F13: =SUM(C13:E13) -> 0
B14: ='00W603'!B14 -> 46274 | C14: 67.5 | D14: 0 | E14: 0 | F14: =SUM(C14:E14) -> 67.5
B15: ='00W603'!B15 -> 46275 | C15: 0 | D15: 0 | E15: 0 | F15: =SUM(C15:E15) -> 0
B16: ='00W603'!B16 -> 46276 | C16: 712.05 | D16: 0 | E16: 0 | F16: =SUM(C16:E16) -> 712.05
B17: =+'00W603'!B17 -> 46279 | C17: 253.0238 | D17: 0 | E17: 0 | F17: =SUM(C17:E17) -> 253.0238
B18: ='00W603'!B18 -> 46280 | C18: 0 | D18: 0 | E18: 0 | F18: =SUM(C18:E18) -> 0
B19: =+'00W603'!B19 -> Extra 1
B20: =+'00W603'!B20 -> Extra 2
B21: Extra 3
B22: Extra 4
B23: Extra 5
B24: Total | C24: =SUM(C9:C23) -> 2272.7338 | D24: =SUM(D9:D23) -> 0 | E24: =SUM(E9:E23) -> 0 | F24: =SUM(F9:F23) -> 2272.7338
A26: Returns
A27: Cust # | B27: Inv #
A28: CGC2933 | B28: 629901 | F28: -90
A29: MID4444 | B29: 633991 | F29: -253.14
F30: 0
F31: 0
F32: =SUM(F28:F31) -> -343.14
A34: 120 Day Chews
A35: Cust # | B35: Inv #
F36: 0
F37: 0
F38: 0
F39: 0
F40: 0
F41: =SUM(F36:F40) -> 0
A42: Adjustments
A43: Cust # | B43: Inv #
...
