Workbook
Name ross: ' JULY IL'!$C$21
Name sam: ' JULY IL'!$C$22

Sheet  JULY AZ
A1: 46234
A3: ARIZONA DIV00 | H3: NET
C4: SALES $ | D4: COGS | E4: M/U | F4: RTNS | G4: COLLECTIONS | H4: SALES | I4: RTN %
A5: ADAM R | B5: A550 | C5: =205+6932+1875+1600+3390+3007.5+5116+650+9485.5+709.5+545+1512.75+300+935.98+498+6020+2232.5+2232 -> 47246.73 | D5: =120+5010+975+625+2200+1704.5+2720+304+5237+379+306+859.5+159+527+270+3685+1175+1121.6 -> 27377.6 | E5: =C5/D5 -> 1.725744 | F5: 0 | G5: =812.44 -> 812.44 | H5: =+C5-F5-G5 -> 46434.29 | I5: =F5/C5 -> 0
A6: LEANDER H | B6: A605 | C6: 0 | D6: 0 | E6: =C6/D6 -> #DIV/0! | F6: 0 | G6: =0 -> 0 | H6: =+C6-F6-G6 -> 0 | I6: =F6/C6 -> #DIV/0!
A7: JACOB M | B7: A607 | C7: =180 -> 180 | D7: =100 -> 100 | E7: =C7/D7 -> 1.8 | F7: 0 | G7: =0 -> 0 | H7: =+C7-F7-G7 -> 180 | I7: =F7/C7 -> 0
A8: LARRY A | B8: A654 | C8: =9611.6+1696.6+548+3274.2+2613.85+665+944.19+1732+3920.1+1484 -> 26489.54 | D8: =4887+998+322+1814+1361+350+492.5+1135+2095+872 -> 14326.5 | E8: =C8/D8 -> 1.8489889 | F8: =1645.4 -> 1645.4 | G8: =0 -> 0 | H8: =+C8-F8-G8 -> 24844.14 | I8: =F8/C8 -> 0.062115084
A9: MARK F | B9: A701 | C9: =2499.5+1631.82+5249.75+1496.97+3144.96+5961.83+2859.9 -> 22844.73 | D9: =1412.5+822+3495+663+1758+3502.12+1680 -> 13332.62 | E9: =C9/D9 -> 1.7134464 | F9: 0 | G9: =0 -> 0 | H9: =+C9-F9-G9 -> 22844.73 | I9: =F9/C9 -> 0
A10: OLIN M | B10: A702 | C10: =931+6480+2268+328+540+2012.5+1298+3026+2952.5+709.5+545+7812.75+8800+1343+270+315+2232.5+1848 -> 43711.75 | D10: =417.6+4980+1512+166+300+1356.5+625+2104+1659+379+306+3289.5+5745+764+150+156.5+1175+924 -> 26009.1 | E10: =C10/D10 -> 1.6806329 | F10: =114 -> 114 | G10: =0 -> 0 | H10: =+C10-F10-G10 -> 43597.75 | I10: =F10/C10 -> 0.0026079944
A11: ALEX B | B11: A777 | C11: 0 | D11: 0 | E11: =C11/D11 -> #DIV/0! | F11: 0 | G11: =0 -> 0 | H11: =+C11-F11-G11 -> 0 | I11: =F11/C11 -> #DIV/0!
A12: AZ HOUSE | B12: A111 | C12: 0 | D12: 0 | E12: =C12/D12 -> #DIV/0! | F12: 0 | G12: =0 -> 0 | H12: =+C12-F12-G12 -> 0 | I12: =F12/C12 -> #DIV/0!
A13: TERM | C13: 0 | D13: 0 | E13: =C13/D13 -> #DIV/0! | F13: =330+360 -> 690 | G13: =3200.89 -> 3200.89 | H13: =+C13-F13-G13 -> -3890.89 | I13: =F13/C13 -> #DIV/0!
A14: AZ DIV 00 TOTAL | C14: =SUM(C5:C13) -> 140472.75 | D14: =SUM(D5:D13) -> 81145.82 | E14: =C14/D14 -> 1.731115 | F14: =SUM(F5:F13) -> 2449.4 | G14: =SUM(G5:G13) -> 4013.33 | H14: =+C14-F14-G14 -> 134010.02 | I14: =F14/C14 -> 0.017436834
A16: ARIZONA DIV22
A17: ADAM R | B17: A550 | C17: 0 | D17: 0 | E17: =C17/D17 -> #DIV/0! | F17: 0 | G17: 0 | H17: =+C17-F17-G17 -> 0 | I17: =F17/C17 -> #DIV/0!
A18: LARRY A | B18: A654 | C18: =2465+377 -> 2842 | D18: =1722.27+290 -> 2012.27 | E18: =C18/D18 -> 1.4123353 | F18: 0 | G18: 0 | H18: =+C18-F18-G18 -> 2842 | I18: =F18/C18 -> 0
A19: MARK F | B19: A701 | C19: =336.6+2051.94 -> 2388.54 | D19: =198+1206 -> 1404 | E19: =C19/D19 -> 1.7012393 | F19: 0 | G19: 0 | H19: =+C19-F19-G19 -> 2388.54 | I19: =F19/C19 -> 0
A20: OLIN M | B20: A702 | C20: =190 -> 190 | D20: =76 -> 76 | E20: =C20/D20 -> 2.5 | F20: 0 | G20: 0 | H20: =+C20-F20-G20 -> 190 | I20: =F20/C20 -> 0
A21: ALEX B | B21: A777 | C21: =12780.2+2245+1292.5+225+1341+38.75+450+2266.75+242.5+26509.5+3040+14898.5+170.85+320+348+381+322.59+847 -> 67719.14 | D21: =7507.3+1462.9+769.1+118.45+793.7+25.61+236.9+1654.05+142.5+15069.75+1638.1+8731.95+100.5+182+211.7+229.5+189.75+508.1 -> 39571.86 | E21: =C21/D21 -> 1.7112953 | F21: =465+242.5+321 -> 1028.5 | G21: 0 | H21: =+C21-F21-G21 -> 66690.64 | I21: =F21/C21 -> 0.01518773
A22: TERM | C22: 0 | D22: 0 | E22: =C22/D22 -> #DIV/0! | F22: 0 | G22: 0 | H22: =+C22-F22-G22 -> 0 | I22: =F22/C22 -> #DIV/0!
A23: AZ DIV 22 TOTAL | C23: =SUM(C17:C22) -> 73139.68 | D23: =SUM(D17:D22) -> 43064.13 | E23: =C23/D23 -> 1.6983898 | F23: =SUM(F17:F22) -> 1028.5 | G23: =SUM(G17:G22) -> 0 | H23: =+C23-F23-G23 -> 72111.18 | I23: =F23/C23 -> 0.014062134
A25: AZ DIV 33
A26: ADAM R | B26: A550 | C26: 0 | D26: 0 | E26: =C26/D26 -> #DIV/0! | F26: 0 | G26: 0 | H26: =+C26-F26-G26 -> 0 | I26: =F26/C26 -> #DIV/0!
A27: MARK F | B27: A701 | C27: 0 | D27: 0 | E27: =C27/D27 -> #DIV/0! | F27: 0 | G27: 0 | H27: =+C27-F27-G27 -> 0 | I27: =F27/C27 -> #DIV/0!
A28: OLIN M | B28: A702 | C28: =342+1080+342+972+312 -> 3048 | D28: =144+499.5+164.25+479.25+238.8 -> 1525.8 | E28: =C28/D28 -> 1.9976406 | F28: 0 | G28: 0 | H28: =+C28-F28-G28 -> 3048 | I28: =F28/C28 -> 0
A29: AZ DIV 33 TOTAL | C29: =SUM(C26:C28) -> 3048 | D29: =SUM(D26:D28) -> 1525.8 | E29: =C29/D29 -> 1.9976406 | F29: =SUM(F26:F28) -> 0 | G29: =SUM(G26:G28) -> 0 | H29: =SUM(H26:H28) -> 3048 | I29: 0
A31: TOTAL AZ | C31: =C29+C23+C14 -> 216660.43 | D31: =D29+D23+D14 -> 125735.75 | E31: =C31/D31 -> 1.723141 | F31: =F29+F23+F14 -> 3477.9 | G31: =G29+G23+G14 -> 4013.33 | H31: =+C31-F31-G31 -> 209169.2 | I31: =F31/C31 -> 0.016052308

Sheet  JULY IL
A1: =' JULY AZ'!A1 -> 46234
A3: ILLINOIS DIV00 | H3: NET
C4: SALES | D4: COGS | E4: M/U | F4: RTNS | G4: COLLECTIONS | H4: SALES | I4: RTN %
A5: HOUSE | B5: I001 | C5: =222+177.1+1580.55+2488.96+462.3+167.78+367.7+345+225.56 -> 6036.95 | D5: =27.5+148+161+1422.5+2240+416+151+306+55+345+203 -> 5475 | E5: =C5/D5 -> 1.1026393 | F5: 0 | G5: 0 | H5: =C5-F5-G5 -> 6036.95 | I5: =F5/C5 -> 0
A6: TOM C | B6: I033 | C6: =20947.09 -> 20947.09 | D6: =13959.4 -> 13959.4 | E6: =C6/D6 -> 1.5005724 | F6: 0 | G6: 0 | H6: =C6-F6-G6 -> 20947.09 | I6: =F6/C6 -> 0
A7: JASON M | B7: I069 | C7: =2617+2617+658+156.88 -> 6048.88 | D7: =2275+2275+506+96.29 -> 5152.29 | E7: =C7/D7 -> 1.1740178 | F7: 0 | G7: 0 | H7: =C7-F7-G7 -> 6048.88 | I7: =F7/C7 -> 0
A8: FRANK S | B8: I155 | C8: =882.5 -> 882.5 | D8: =562.5 -> 562.5 | E8: =C8/D8 -> 1.5688889 | F8: 0 | G8: 0 | H8: =C8-F8-G8 -> 882.5 | I8: =F8/C8 -> 0
A9: JORDAN M | B9: I272 | C9: =4184.3+439+960+2802+16142+1891.6+12187.5+3081.56+4343+293.8+692+7756.2+162.4+546+1914+1350 -> 58745.36 | D9: =2732.5+274+564+1473.18+10328.5+1159+7240+2058.8+2744.8+225.4+406+5192.5+124.8+345+1275+600 -> 36743.48 | E9: =C9/D9 -> 1.5987968 | F9: =1590 -> 1590 | G9: 0 | H9: =C9-F9-G9 -> 57155.36 | I9: =F9/C9 -> 0.027065967
A10: JIMMY M | B10: I281 | C10: =1024+4122+1034 -> 6180 | D10: =512+2608.86+608 -> 3728.86 | E10: =C10/D10 -> 1.657343 | F10: 0 | G10: 0 | H10: =C10-F10-G10 -> 6180 | I10: =F10/C10 -> 0
A11: CHRIS Z | B11: I393 | C11: =12264.4+4115+9414.42+7001.6+9313.5+13269.86+11698+811.5+8199.32+25027+5540+3846.9+939+10986.9+6901+1812.5+10248+1489+3872 -> 146749.9 | D11: =7753+2577.4+6494.94+4414.38+5634+9385.9+7378+552+4482.6+15136+3416+2433.5+518+7604.1+4695+1097+6628+867+2411 -> 93477.82 | E11: =C11/D11 -> 1.5698901 | F11: =699 -> 699 | G11: 0 | H11: =C11-F11-G11 -> 146050.9 | I11: =F11/C11 -> 0.004763206
A12: JEFF J | B12: I436 | C12: =3817.96+8093.4+4970.8+299.97+7411.5+493.99+3161.76+1854+2550+6830.98+437.5+4140.4+538+3100+43.75+1254+2872.9+7982.99+14062+2816 -> 76731.9 | D12: =2229+5571+2758.5+180+4699.5+262+2100.66+1086+1445+3648.5+261.5+2578.4+394+1871.5+13.5+862+1529.4+5189+8568.9+1335 -> 46583.36 | E12: =C12/D12 -> 1.6471955 | F12: =594 -> 594 | G12: 0 | H12: =C12-F12-G12 -> 76137.9 | I12: =F12/C12 -> 0.0077412393
A13: IAIR Z | B13: I462 | C13: =2613.9+2443+27536.7+9075+2613.9 -> 44282.5 | D13: =2010.6+1427+18922+5670+2010.6 -> 30040.2 | E13: =C13/D13 -> 1.474108 | F13: 0 | G13: 0 | H13: =C13-F13-G13 -> 44282.5 | I13: =F13/C13 -> 0
A14: RICO C | B14: I478 | C14: =378+1281.2+524 -> 2183.2 | D14: =210+793+304 -> 1307 | E14: =C14/D14 -> 1.6703902 | F14: 0 | G14: 0 | H14: =C14-F14-G14 -> 2183.2 | I14: =F14/C14 -> 0
A15: DAN M | B15: I501 | C15: =4792+900+8450+2970+9730+465+6800+4737+3587.1+5220+1376+7697+10281+5199+6975+4825+1700+630+798 -> 87132.1 | D15: =3044+558+5302.02+1850+6208+300+5225+2808+2221.9+3693+900+5113.5+7289+3844+4091.5+3168+1016+360+584 -> 57575.92 | E15: =C15/D15 -> 1.5133427 | F15: 0 | G15: 0 | H15: =C15-F15-G15 -> 87132.1 | I15: =F15/C15 -> 0
A16: CHRIS T | B16: I664 | C16: =145+1786.5+432+1304.8+1896+6016.9+2730+8244+750+3111.42+5300.4 -> 31717.02 | D16: =96.25+1374.19+300+950.43+1264+3647+1820+5496+447+2247.25+4026 -> 21668.12 | E16: =C16/D16 -> 1.4637643 | F16: 0 | G16: 0 | H16: =C16-F16-G16 -> 31717.02 | I16: =F16/C16 -> 0
A17: MARK S | B17: I729 | C17: 0 | D17: 0 | E17: =C17/D17 -> #DIV/0! | F17: 0 | G17: 0 | H17: =C17-F17-G17 -> 0 | I17: =F17/C17 -> #DIV/0!
A18: JAY M | B18: I769 | C18: 0 | D18: 0 | E18: =C18/D18 -> #DIV/0! | F18: 0 | G18: 0 | H18: =C18-F18-G18 -> 0 | I18: =F18/C18 -> #DIV/0!
A19: AL S | B19: I801 | C19: =154+719.4+2225+1069.8+179.85+587+509.8+360+971.3 -> 6776.15 | D19: =96+324+876+611+99+277+237+180+516.5 -> 3216.5 | E19: =C19/D19 -> 2.1066843 | F19: 0 | G19: 0 | H19: =C19-F19-G19 -> 6776.15 | I19: =F19/C19 -> 0
A20: SAMUEL J | B20: I815 | C20: =6399.5+1190+1062.5+635.94+851.98+392.5+768+2781.51+102+179.85+258+1509+467.94+150 -> 16748.72 | D20: =4220.5+658.5+625+360+500+232.32+483+1927.5+62+99+135+873+270+67.5 -> 10513.32 | E20: =C20/D20 -> 1.5930952 | F20: 0 | G20: =134.75+175.6+267.5 -> 577.85 | H20: =C20-F20-G20 -> 16170.87 | I20: =F20/C20 -> 0
A21: DAVID S | B21: I830 | C21: 0 | D21: 0 | E21: =C21/D21 -> #DIV/0! | F21: 0 | G21: 0 | H21: =C21-F21-G21 -> 0 | I21: =F21/C21 -> #DIV/0!
A22: ROSS S | B22: I848 | C22: =450+987+2370+1706+175+325+1250+175+1175+1645+1175+4583+975+350 -> 17341 | D22: =252+547+1812+929+96+167+656+100+564+915+564+3048+525+200 -> 10375 | E22: =C22/D22 -> 1.6714217 | F22: 0 | G22: 0 | H22: =C22-F22-G22 -> 17341 | I22: =F22/C22 -> 0
A23: CARL L | B23: I850 | C23: =4165+147.75+660+630+432+115+132.5 -> 6282.25 | D23: =2450+91.5+360+360+234+60+77.5 -> 3633 | E23: =C23/D23 -> 1.7292183 | F23: =4080 -> 4080 | G23: 0 | H23: =C23-F23-G23 -> 2202.25 | I23: =F23/C23 -> 0.64944884
A24: ANTOINETTE V | B24: I856 | C24: =1500.9+3209.82+2361.73+6143.76+332.97+494.98+947.7+102+150+399.8+396.15+1272.55 -> 17312.36 | D24: =873+1434+1297+3635+183+301.32+618+62+100+196+217.25+730 -> 9646.57 | E24: =C24/D24 -> 1.7946648 | F24: 0 | G24: =256.55 -> 256.55 | H24: =C24-F24-G24 -> 17055.81 | I24: =F24/C24 -> 0
A25: JAVIER C | B25: I865 | C25: =1345.5+1065+987+2328.96+318+864+2004+2272.5+247.5+642.5+240+1096.5+1100+260 -> 14771.46 | D25: =783+585+572+1320+183+489+1251+1464+148.5+377.5+135+645+610+151 -> 8714 | E25: =C25/D25 -> 1.6951412 | F25: =720 -> 720 | G25: =134.75+256.55+267.5+196 -> 854.8 | H25: =C25-F25-G25 -> 13196.66 | I25: =F25/C25 -> 0.048742643
A26: TIMOTHY C | B26: I867 | C26: =670+877+125+565+482.8+1350+2320.98+231+390+3920.88+240+432.8+808.98+1326+1170+150+199.98 -> 15260.42 | D26: =380+513+73.5+330+277+900+1364+135+300+2589+135+250.5+472+776+810+67.5+120 -> 9492.5 | E26: =C26/D26 -> 1.6076292 | F26: 0 | G26: =175.6+196 -> 371.6 | H26: =C26-F26-G26 -> 14888.82 | I26: =F26/C26 -> 0
A27: KELLSTEIN G | B27: I879 | C27: =93.5 -> 93.5 | D27: =53 -> 53 | E27: =C27/D27 -> 1.7641509 | F27: 0 | G27: 0 | H27: =C27-F27-G27 -> 93.5 | I27: =F27/C27 -> 0
A28: JOSE S | B28: I887 | C28: 0 | D28: 0 | E28: =C28/D28 -> #DIV/0! | F28: 0 | G28: 0 | H28: =C28-F28-G28 -> 0 | I28: =F28/C28 -> #DIV/0!
A29: BRONSON B | B29: I893 | C29: 0 | D29: 0 | E29: =C29/D29 -> #DIV/0! | F29: 0 | G29: 0 | H29: =C29-F29-G29 -> 0 | I29: =F29/C29 -> #DIV/0!
A30: NICO L | B30: I896 | C30: =147.75+478 -> 625.75 | D30: =91.5+233 -> 324.5 | E30: =C30/D30 -> 1.9283513 | F30: 0 | G30: 0 | H30: =C30-F30-G30 -> 625.75 | I30: =F30/C30 -> 0
A31: VINCENZO G | B31: I897 | C31: =629.07+315+665.94+243+236.97 -> 2089.98 | D31: =366+183+366+135+135 -> 1185 | E31: =C31/D31 -> 1.7636962 | F31: 0 | G31: 0 | H31: =C31-F31-G31 -> 2089.98 | I31: =F31/C31 -> 0
A32: MARTIN A | B32: I898 | C32: =219+125.97 -> 344.97 | D32: =100+90 -> 190 | E32: =C32/D32 -> 1.8156316 | F32: 0 | G32: 0 | H32: =C32-F32-G32 -> 344.97 | I32: =F32/C32 -> 0
A33: MATT G | B33: I902 | C33: =161+450 -> 611 | D33: =100.5+236.9 -> 337.4 | E33: =C33/D33 -> 1.8109069 | F33: 0 | G33: 0 | H33: =C33-F33-G33 -> 611 | I33: =F33/C33 -> 0
A34: JERRY S | B34: I924 | C34: =3350+1171+4855+4128 -> 13504 | D34: =1839+575.95+3671+2316 -> 8401.95 | E34: =C34/D34 -> 1.6072459 | F34: 0 | G34: =212.7+503.48+458.54+348.97 -> 1523.69 | H34: =C34-F34-G34 -> 11980.31 | I34: =F34/C34 -> 0
A35: TERM S/P | C35: 0 | D35: 0 | E35: =C35/D35 -> #DIV/0! | F35: 0 | G35: 0 | H35: =C35-F35-G35 -> 0 | I35: =F35/C35 -> #DIV/0!
A36: IL DIV 00 TOTAL | C36: =SUM(C5:C35) -> 599398.96 | D36: =SUM(D5:D35) -> 382356.69 | E36: =C36/D36 -> 1.5676434 | F36: =SUM(F5:F35) -> 7683 | G36: =SUM(G5:G35) -> 3584.49 | H36: =C36-F36-G36 -> 588131.47 | I36: =F36/C36 -> 0.01281784
A38: ILLINOIS DIV22
A39: TOM C | B39: I033 | C39: 0 | D39: 0 | E39: =C39/D39 -> #DIV/0! | F39: 0 | G39: 0 | H39: =C39-F39-G39 -> 0 | I39: =F39/C39 -> #DIV/0!
A40: JASON M | B40: I069 | C40: 0 | D40: 0 | E40: =C40/D40 -> #DIV/0! | F40: 0 | G40: 0 | H40: =C40-F40-G40 -> 0 | I40: =F40/C40 -> #DIV/0!
A41: JORDAN M. | B41: I272 | C41: =194.7+118+1197+411 -> 1920.7 | D41: =120.25+68.9+795.51+225.33 -> 1209.99 | E41: =C41/D41 -> 1.5873685 | F41: 0 | G41: =483.91 -> 483.91 | H41: =C41-F41-G41 -> 1436.79 | I41: =F41/C41 -> 0
A42: JIMMY M | B42: I281 | C42: =6119.6+15060.8+5257.56+12412.62+3154.14+350+2986.8+5488.3+3087.5+1034.4+14819.63+556.5+2418.7+6617.98+3216.75+1204.95+8767.1+7446.75+1266.8+6199.1 -> 107465.98 | D42: =3927.8+9155.8+4873.92+7622.6+1874.6+163.8+1631+3105.1+1932+747+8838+326.3+1389.6+3822.07+1846.25+722.65+5218.85+4134.6+779.8+3749.1 -> 65860.84 | E42: =C42/D42 -> 1.6317129 | F42: =371+440+996 -> 1807 | G42: 0 | H42: =C42-F42-G42 -> 105658.98 | I42: =F42/C42 -> 0.016814624
...

Sheet JULY WI
A1: =+' JULY AZ'!A1 -> 46234
A3: WISCONSIN DIV00 | H3: NET
C4: SALES $ | D4: COGS | E4: M/U | F4: RTNS | G4: COLLECTIONS | H4: SALES | I4: RTN %
A5: ADAM W | B5: W603 | C5: =450+390+2700+8030.8+1712.5+590.06+1213.8+7091.2+5260+1132.3+1815+2139.98+314 -> 32839.64 | D5: =204.15+192+1224+5011+1104.93+364.5+933+4276.8+2742+649.1+1067.5+1226+241 -> 19235.98 | E5: =C5/D5 -> 1.7071987 | F5: =986 -> 986 | G5: =632.82 -> 632.82 | H5: =C5-F5-G5 -> 31220.82 | I5: =F5/C5 -> 0.03002469
A6: KERRY S | B6: W762 | C6: =960+2982.4+960+165 -> 5067.4 | D6: =609+2236+609+110 -> 3564 | E6: =C6/D6 -> 1.4218294 | F6: 0 | G6: 0 | H6: =C6-F6-G6 -> 5067.4 | I6: =F6/C6 -> 0
A7: JUSTIN | B7: W784 | C7: =450+5079.84+2700+2880+2267.5+2250+1835+1320+8705+783.75+2025.87+165 -> 30461.96 | D7: =204.15+3142.5+1224+1796+1421.5+1175+1046.5+768+4767+387.75+1183+110 -> 17225.4 | E7: =C7/D7 -> 1.7684327 | F7: 0 | G7: 0 | H7: =C7-F7-G7 -> 30461.96 | I7: =F7/C7 -> 0
A8: RON B | B8: W839 | C8: =3733.56+1290+4660+300+6049.88+9131.88+2612.8+437.5+2079.6+43.75 -> 30338.97 | D8: =2484+661+2536.5+108+3598+5274+1481.9+261.5+1207+13.5 -> 17625.4 | E8: =C8/D8 -> 1.7213209 | F8: =1199.88 -> 1199.88 | G8: 0 | H8: =C8-F8-G8 -> 29139.09 | I8: =F8/C8 -> 0.039549134
A9: JOHN B | B9: W849 | C9: =276+3754.99+5325+165+207.25+4944.97+942+600+150+2161.8 -> 18527.01 | D9: =126+2598+3285+1125+78.5+112+2819+473+252+85+932 -> 11885.5 | E9: =C9/D9 -> 1.558791 | F9: 0 | G9: 0 | H9: =C9-F9-G9 -> 18527.01 | I9: =F9/C9 -> 0
A10: LUIS M | B10: W909 | C10: =783.75+4500 -> 5283.75 | D10: =387.75+3300 -> 3687.75 | E10: =C10/D10 -> 1.4327842 | F10: 0 | G10: 0 | H10: =C10-F10-G10 -> 5283.75 | I10: =F10/C10 -> 0
A11: ADAM M | B11: W930 | C11: =1754.99+2649.91+7419.75+3526.76+3775+86.99+507+3559.85+2719.96+2339.94+6105.94+4347+2565 -> 41358.09 | D11: =850+995+3635+1630.9+2050+47.7+168.75+1496.95+990+993+3070+1507+1404 -> 18838.3 | E11: =C11/D11 -> 2.1954258 | F11: 0 | G11: =3984.33 -> 3984.33 | H11: =C11-F11-G11 -> 37373.76 | I11: =F11/C11 -> 0
A12: LES K | B12: W934 | C12: =180+1379.94+399.98 -> 1959.92 | D12: =100+768+195 -> 1063 | E12: =C12/D12 -> 1.8437629 | F12: 0 | G12: 0 | H12: =C12-F12-G12 -> 1959.92 | I12: =F12/C12 -> 0
A13: GEOFFREY N | B13: W938 | C13: =276+150+285 -> 711 | D13: =126+85+150 -> 361 | E13: =C13/D13 -> 1.9695291 | F13: 0 | G13: 0 | H13: =C13-F13-G13 -> 711 | I13: =F13/C13 -> 0
A14: JAMEL L | B14: W953 | C14: 0 | D14: 0 | E14: =C14/D14 -> #DIV/0! | F14: =140 -> 140 | G14: 0 | H14: =C14-F14-G14 -> -140 | I14: =F14/C14 -> #DIV/0!
A15: CASSANDRA K | B15: W959 | C15: =150+2868+936.4+69+245.98 -> 4269.38 | D15: =86+1668+449.9+39.6+122 -> 2365.5 | E15: =C15/D15 -> 1.8048531 | F15: =8750 -> 8750 | G15: =632.82 -> 632.82 | H15: =C15-F15-G15 -> -5113.44 | I15: =F15/C15 -> 2.0494779
A16: CHRIS K | B16: W962 | C16: =2500+899.97+499.99+195+781+4000+1000+299.98+780 -> 10955.94 | D16: =1175+324+180+108+454+2350+587.5+192+241.8 -> 5612.3 | E16: =C16/D16 -> 1.9521301 | F16: 0 | G16: 0 | H16: =C16-F16-G16 -> 10955.94 | I16: =F16/C16 -> 0
A17: NICO T | B17: W963 | C17: 0 | D17: 0 | E17: =C17/D17 -> #DIV/0! | F17: 0 | G17: =1756.34 -> 1756.34 | H17: =C17-F17-G17 -> -1756.34 | I17: =F17/C17 -> #DIV/0!
A18: BLAKE M | B18: W966 | C18: =125+140+597+405 -> 1267 | D18: =43.5+62.4+282+204 -> 591.9 | E18: =C18/D18 -> 2.1405643 | F18: 0 | G18: 0 | H18: =C18-F18-G18 -> 1267 | I18: =F18/C18 -> 0
A19: JAMES B | B19: W967 | C19: =150 -> 150 | D19: =97.5 -> 97.5 | E19: =C19/D19 -> 1.5384615 | F19: =1129.95+564.98 -> 1694.93 | G19: 0 | H19: =C19-F19-G19 -> -1544.93 | I19: =F19/C19 -> 11.299533
A20: ANTHONYS | B20: W973 | C20: =2280+453+622.2+2250+1810+413.6+1185.6+3914.4 -> 12928.8 | D20: =1200+222.5+366+1175+755.5+244+624+1519 -> 6106 | E20: =C20/D20 -> 2.1173927 | F20: 0 | G20: 0 | H20: =C20-F20-G20 -> 12928.8 | I20: =F20/C20 -> 0
A21: SCOT T | B21: W983 | C21: =2500+139.9+1199.5+507+5929+7047.94+4381.25+931+4000+4639.72+780+2549.85 -> 34605.16 | D21: =1175+62.4+425+168.75+2882.05+5150+3370+551.5+2350+3697+241.8+1770 -> 21843.5 | E21: =C21/D21 -> 1.5842315 | F21: =659.94+1129.95+564.98+1699.9+1175.51 -> 5230.28 | G21: =1756.34+1296.98+4795.45 -> 7848.77 | H21: =C21-F21-G21 -> 21526.11 | I21: =F21/C21 -> 0.15114162
A22: TERMINATED | C22: 0 | D22: 0 | E22: =C22/D22 -> #DIV/0! | F22: 0 | G22: 0 | H22: =C22-F22-G22 -> 0 | I22: =F22/C22 -> #DIV/0!
A23: WI DIV 00 TOTAL | C23: =SUM(C5:C22) -> 230724.02 | D23: =SUM(D5:D22) -> 130103.03 | E23: =C23/D23 -> 1.7733947 | F23: =SUM(F5:F22) -> 18001.09 | G23: =SUM(G5:G22) -> 14855.08 | H23: =C23-F23-G23 -> 197867.85 | I23: =F23/C23 -> 0.078020008
A25: WISCONSIN DIV22
A26: ADAM W | B26: W603 | C26: 0 | D26: 0 | E26: =C26/D26 -> #DIV/0! | F26: 0 | G26: 0 | H26: =C26-F26-G26 -> 0 | I26: =F26/C26 -> #DIV/0!
A27: KERRY S | B27: W762 | C27: 0 | D27: 0 | E27: =C27/D27 -> #DIV/0! | F27: 0 | G27: 0 | H27: =C27-F27-G27 -> 0 | I27: =F27/C27 -> #DIV/0!
A28: JUSTIN G | B28: W784 | C28: 0 | D28: 0 | E28: =C28/D28 -> #DIV/0! | F28: 0 | G28: 0 | H28: =C28-F28-G28 -> 0 | I28: =F28/C28 -> #DIV/0!
A29: RONALD B | B29: W839 | C29: 0 | D29: 0 | E29: =C29/D29 -> #DIV/0! | F29: 0 | G29: 0 | H29: =C29-F29-G29 -> 0 | I29: =F29/C29 -> #DIV/0!
A30: JOHN B | B30: W849 | C30: 0 | D30: 0 | E30: =C30/D30 -> #DIV/0! | F30: 0 | G30: 0 | H30: =C30-F30-G30 -> 0 | I30: =F30/C30 -> #DIV/0!
A31: FOREST C | B31: W923 | C31: 0 | D31: 0 | E31: =C31/D31 -> #DIV/0! | F31: 0 | G31: 0 | H31: =C31-F31-G31 -> 0 | I31: =F31/C31 -> #DIV/0!
A32: ADAM M | B32: W930 | C32: 0 | D32: 0 | E32: =C32/D32 -> #DIV/0! | F32: 0 | G32: 0 | H32: =C32-F32-G32 -> 0 | I32: =F32/C32 -> #DIV/0!
A33: LES K | B33: W934 | C33: 0 | D33: 0 | E33: =C33/D33 -> #DIV/0! | F33: 0 | G33: 0 | H33: =C33-F33-G33 -> 0 | I33: =F33/C33 -> #DIV/0!
A34: GEOFFREY N | B34: W938 | C34: 0 | D34: 0 | E34: =C34/D34 -> #DIV/0! | F34: 0 | G34: 0 | H34: =C34-F34-G34 -> 0 | I34: =F34/C34 -> #DIV/0!
A35: ANTHONYS | B35: W973 | C35: 0 | D35: 0 | E35: =C35/D35 -> #DIV/0! | F35: 0 | G35: 0 | H35: =C35-F35-G35 -> 0 | I35: =F35/C35 -> #DIV/0!
A36: SCOT T | B36: W983 | C36: 0 | D36: 0 | E36: =C36/D36 -> #DIV/0! | F36: 0 | G36: 0 | H36: =C36-F36-G36 -> 0 | I36: =F36/C36 -> #DIV/0!
A37: TERM | C37: 0 | D37: 0 | E37: =C37/D37 -> #DIV/0! | F37: 0 | G37: 0 | H37: =C37-F37-G37 -> 0 | I37: =F37/C37 -> #DIV/0!
A38: WI DIV 22 TOTAL | C38: =SUM(C26:C37) -> 0 | D38: =SUM(D26:D37) -> 0 | E38: =C38/D38 -> #DIV/0! | F38: =SUM(F26:F37) -> 0 | G38: =SUM(G26:G37) -> 0 | H38: =C38-F38-G38 -> 0 | I38: =F38/C38 -> #DIV/0!
A40: WISCONSIN DIV33
A41: ADAM W | B41: W603 | C41: 0 | D41: 0 | E41: =C41/D41 -> #DIV/0! | F41: 0 | G41: 0 | H41: =C41-F41-G41 -> 0 | I41: =F41/C41 -> #DIV/0!
A42: KERRY S | B42: W762 | C42: 0 | D42: 0 | E42: =C42/D42 -> #DIV/0! | F42: 0 | G42: 0 | H42: =C42-F42-G42 -> 0 | I42: =F42/C42 -> #DIV/0!
A43: FRANK G | B43: W784 | C43: 0 | D43: 0 | E43: =C43/D43 -> #DIV/0! | F43: 0 | G43: 0 | H43: =C43-F43-G43 -> 0 | I43: =F43/C43 -> #DIV/0!
...

Sheet JULY 2026 Div Totals
D2: JULY FINAL NUMBERS
A4: =+' JULY AZ'!A1 -> 46234 | H4: NET
C5: SALES | D5: COGS | E5: M/U | F5: RETURNS | G5: COLLECTIONS | H5: SALES | I5: RTN %
A7: DBW | C7: =+' JULY AZ'!C14+' JULY IL'!C36+'JULY WI'!C23 -> 970595.73 | D7: =+' JULY AZ'!D14+' JULY IL'!D36+'JULY WI'!D23 -> 593605.54 | E7: =+C7/D7 -> 1.6350854 | F7: =+' JULY AZ'!F14+' JULY IL'!F36+'JULY WI'!F23 -> 28133.49 | G7: =' JULY AZ'!G14+' JULY IL'!G36+'JULY WI'!G23 -> 22452.9 | H7: =+C7-F7-G7 -> 920009.34 | I7: =+F7/C7 -> 0.028985796
A9: HELIX | C9: =+' JULY AZ'!C23+' JULY IL'!C68+'JULY WI'!C38 -> 385663.3 | D9: =+' JULY AZ'!D23+' JULY IL'!D68+'JULY WI'!D38 -> 241045.84 | E9: =+C9/D9 -> 1.5999583 | F9: =+' JULY AZ'!F23+' JULY IL'!F68+'JULY WI'!F38 -> 8641.8 | G9: =+' JULY AZ'!G23+' JULY IL'!G68+'JULY WI'!G38 -> 483.91 | H9: =+C9-F9-G9 -> 376537.59 | I9: =+F9/C9 -> 0.022407629
A11: HELIX FLOORS | C11: =' JULY IL'!C89+' JULY AZ'!C29+'JULY WI'!C49 -> 309228.07 | D11: =' JULY IL'!D89+' JULY AZ'!D29+'JULY WI'!D49 -> 209224.12 | E11: =+C11/D11 -> 1.4779752 | F11: =' JULY IL'!F89+' JULY AZ'!F29+'JULY WI'!F51 -> 1680 | G11: =' JULY IL'!G89+' JULY AZ'!G29+'JULY WI'!G49 -> 0 | H11: =+C11-F11-G11 -> 307548.07 | I11: =+F11/C11 -> 0.0054328832
A13: HELIX TOOLING | C13: =+'JULY WI'!C57 -> 0 | D13: =+'JULY WI'!D57 -> 0 | E13: =+C13/D13 -> #DIV/0! | F13: =+'JULY WI'!F57 -> 0 | G13: =+'JULY WI'!G57 -> 0 | H13: =+C13-F13-G13 -> 0 | I13: =+F13/C13 -> #DIV/0!
A15: 4COREBIZ | C15: =' JULY IL'!C97 -> 37313.29 | D15: =' JULY IL'!D97 -> 17498.9 | E15: =' JULY IL'!E97 -> 2.132322 | F15: =' JULY IL'!F97 -> 189.9 | G15: =' JULY IL'!G97 -> 0 | H15: =+C15-F15-G15 -> 37123.39 | I15: =' JULY IL'!I92 -> 0.0059991091
A17: STRATUS | C17: =+' JULY IL'!C104 -> 0 | D17: =+' JULY IL'!D104 -> 0 | E17: =+C17/D17 -> #DIV/0! | F17: =+' JULY IL'!F104 -> 0 | G17: =+' JULY IL'!G104 -> 0 | H17: =+C17-F17-G17 -> 0 | I17: =+F17/C17 -> #DIV/0!
A19: TOTAL | C19: =SUM(C3:C18) -> 1702800.4 | D19: =SUM(D3:D18) -> 1061374.4 | E19: =C19/D19 -> 1.6043353 | F19: =SUM(F3:F18) -> 38645.19 | G19: =SUM(G3:G18) -> 22936.81 | H19: =+C19-F19-G19 -> 1641218.4 | I19: =+F19/C19 -> 0.022695079
D59: =60027.25+0.25+80760.66+0.56+67271.79+0.27+81921.85+0.5+92023.63+0.02+97834.55+0.37+109385.67+0.56+84643.82+0.12+78182.76+0.19+60257.96+0.8+102419.9+0.24+109077.88-11838.27+64161.9+0.12+79479.04+0.55+88154.63+0.05 -> 1243769.6
A71: W/D 8/22
A72: RETURNS 12/27 | B72: -2939

Sheet INDIVIDUAL NET TOTALS 
A1: =' JULY AZ'!A1 -> 46234
A4: AZ SALESMEN | C4: SALES | D4: COGS | E4: M/U | F4: RETURNS | G4: COLLECTIONS | H4: NET SALES
A5: ADAM R | B5: A550 | C5: =' JULY AZ'!C5+' JULY AZ'!C17+' JULY AZ'!C26 -> 47246.73 | D5: =' JULY AZ'!D5+' JULY AZ'!D17+' JULY AZ'!D26 -> 27377.6 | E5: =SUM(C5/D5) -> 1.725744 | F5: =' JULY AZ'!F5+' JULY AZ'!F17+' JULY AZ'!F26 -> 0 | G5: =' JULY AZ'!G5+' JULY AZ'!G17+' JULY AZ'!G26 -> 812.44 | H5: =' JULY AZ'!H5+' JULY AZ'!H17+' JULY AZ'!H26 -> 46434.29
A6: LEANDER H | B6: A605 | C6: =' JULY AZ'!C6 -> 0 | D6: =' JULY AZ'!D6 -> 0 | E6: =SUM(C6/D6) -> #DIV/0! | F6: =' JULY AZ'!F6 -> 0 | G6: =' JULY AZ'!G6 -> 0 | H6: =' JULY AZ'!H6 -> 0
A7: JACOB M | B7: A607 | C7: =' JULY AZ'!C7 -> 180 | D7: =' JULY AZ'!D7 -> 100 | E7: =SUM(C7/D7) -> 1.8 | F7: =' JULY AZ'!F7 -> 0 | G7: =' JULY AZ'!G7 -> 0 | H7: =' JULY AZ'!H7 -> 180
A8: LARRY A | B8: A654 | C8: =' JULY AZ'!C8+' JULY AZ'!C18 -> 29331.54 | D8: =' JULY AZ'!D8+' JULY AZ'!D18 -> 16338.77 | E8: =SUM(C8/D8) -> 1.795211 | F8: =' JULY AZ'!F8+' JULY AZ'!F18 -> 1645.4 | G8: =' JULY AZ'!G8+' JULY AZ'!G18 -> 0 | H8: =' JULY AZ'!H8+' JULY AZ'!H18 -> 27686.14
A9: MARK F | B9: A701 | C9: =' JULY AZ'!C9+' JULY AZ'!C19+' JULY AZ'!C27 -> 25233.27 | D9: =' JULY AZ'!D9+' JULY AZ'!D19+' JULY AZ'!D27 -> 14736.62 | E9: =SUM(C9/D9) -> 1.7122834 | F9: =' JULY AZ'!F9+' JULY AZ'!F19+' JULY AZ'!F27 -> 0 | G9: =' JULY AZ'!G9+' JULY AZ'!G19+' JULY AZ'!G27 -> 0 | H9: =' JULY AZ'!H9+' JULY AZ'!H19+' JULY AZ'!H27 -> 25233.27
A10: OLIN M | B10: A702 | C10: =' JULY AZ'!C10+' JULY AZ'!C20+' JULY AZ'!C28 -> 46949.75 | D10: =' JULY AZ'!D10+' JULY AZ'!D20+' JULY AZ'!D28 -> 27610.9 | E10: =SUM(C10/D10) -> 1.7004064 | F10: =' JULY AZ'!F10+' JULY AZ'!F20+' JULY AZ'!F28 -> 114 | G10: =' JULY AZ'!G10+' JULY AZ'!G20+' JULY AZ'!G28 -> 0 | H10: =' JULY AZ'!H10+' JULY AZ'!H20+' JULY AZ'!H28 -> 46835.75
A11: ALEX B | B11: A777 | C11: =' JULY AZ'!C11+' JULY AZ'!C21 -> 67719.14 | D11: =' JULY AZ'!D11+' JULY AZ'!D21 -> 39571.86 | E11: =SUM(C11/D11) -> 1.7112953 | F11: =' JULY AZ'!F11+' JULY AZ'!F21 -> 1028.5 | G11: =' JULY AZ'!G11+' JULY AZ'!G21 -> 0 | H11: =' JULY AZ'!H11+' JULY AZ'!H21 -> 66690.64
A12: AZ HOUSE | B12: A111 | C12: =' JULY AZ'!C12 -> 0 | D12: =' JULY AZ'!D12 -> 0 | E12: =SUM(C12/D12) -> #DIV/0! | F12: =' JULY AZ'!F12 -> 0 | G12: =' JULY AZ'!G12 -> 0 | H12: =' JULY AZ'!H12 -> 0
A13: TERM | C13: =' JULY AZ'!C13 -> 0 | D13: =' JULY AZ'!D13 -> 0 | F13: =' JULY AZ'!F13 -> 690 | G13: =' JULY AZ'!G13 -> 3200.89 | H13: =' JULY AZ'!H13 -> -3890.89
A14: AZ TOTALS | C14: =SUM(C5:C13) -> 216660.43 | D14: =SUM(D5:D13) -> 125735.75 | E14: =+C14/D14 -> 1.723141 | F14: =SUM(F5:F13) -> 3477.9 | G14: =SUM(G5:G13) -> 4013.33 | H14: =SUM(H5:H13) -> 209169.2
A17: IL SALESMEN | C17: SALES | D17: COGS | E17: M/U | F17: RETURNS | G17: COLLECTIONS | H17: NET SALES
A18: HOUSE | B18: I001 | C18: =' JULY IL'!C5 -> 6036.95 | D18: =' JULY IL'!D5 -> 5475 | E18: =SUM(C18/D18) -> 1.1026393 | F18: =' JULY IL'!F5 -> 0 | G18: =' JULY IL'!G5 -> 0 | H18: =' JULY IL'!H5 -> 6036.95
A19: TOM C | B19: I033 | C19: =' JULY IL'!C6+' JULY IL'!C39+' JULY IL'!C101+' JULY IL'!C72 -> 20947.09 | D19: =' JULY IL'!D6+' JULY IL'!D39+' JULY IL'!D101+' JULY IL'!D72 -> 13959.4 | E19: =SUM(C19/D19) -> 1.5005724 | F19: =' JULY IL'!F6+' JULY IL'!F39+' JULY IL'!F100+' JULY IL'!F72 -> 0 | G19: =' JULY IL'!G6+' JULY IL'!G39+' JULY IL'!G100+' JULY IL'!G72 -> 0 | H19: =' JULY IL'!H6+' JULY IL'!H39+' JULY IL'!H100+' JULY IL'!H101+' JULY IL'!H72 -> 20947.09
A20: JASON M | B20: I069 | C20: =+' JULY IL'!C7+' JULY IL'!C40 -> 6048.88 | D20: =' JULY IL'!D7+' JULY IL'!D40 -> 5152.29 | E20: =SUM(C20/D20) -> 1.1740178 | F20: =+' JULY IL'!F7+' JULY IL'!F40 -> 0 | G20: =+' JULY IL'!G7+' JULY IL'!G40 -> 0 | H20: =' JULY IL'!H7+' JULY IL'!H40 -> 6048.88
A21: FRANK S | B21: I155 | C21: =' JULY IL'!C8 -> 882.5 | D21: =' JULY IL'!D8 -> 562.5 | E21: =SUM(C21/D21) -> 1.5688889 | F21: =' JULY IL'!F8 -> 0 | G21: =' JULY IL'!G8 -> 0 | H21: =' JULY IL'!H8 -> 882.5
A22: JORDAN M | B22: I272 | C22: =' JULY IL'!C9+' JULY IL'!C41+' JULY IL'!C73 -> 117159.84 | D22: =' JULY IL'!D9+' JULY IL'!D41+' JULY IL'!D73 -> 77133.46 | E22: =SUM(C22/D22) -> 1.5189237 | F22: =' JULY IL'!F9+' JULY IL'!F41+' JULY IL'!F73 -> 2016 | G22: =' JULY IL'!G9+' JULY IL'!G41+' JULY IL'!G73 -> 483.91 | H22: =' JULY IL'!H9+' JULY IL'!H41+' JULY IL'!H73 -> 114659.93
A23: JIMMY M | B23: I281 | C23: =' JULY IL'!C10+' JULY IL'!C42+' JULY IL'!C74 -> 113645.98 | D23: =' JULY IL'!D10+' JULY IL'!D42+' JULY IL'!D74 -> 69589.7 | E23: =SUM(C23/D23) -> 1.6330862 | F23: =' JULY IL'!F10+' JULY IL'!F42+' JULY IL'!F74 -> 1807 | G23: =' JULY IL'!G10+' JULY IL'!G42+' JULY IL'!G74 -> 0 | H23: =' JULY IL'!H10+' JULY IL'!H42+' JULY IL'!H74 -> 111838.98
A24: CHRIS Z | B24: I393 | C24: =' JULY IL'!C11+' JULY IL'!C43+' JULY IL'!C75+' JULY IL'!C102+' JULY IL'!C93 -> 148369.4 | D24: =' JULY IL'!D11+' JULY IL'!D43+' JULY IL'!D75+' JULY IL'!D102+' JULY IL'!D93 -> 94373 | E24: =SUM(C24/D24) -> 1.5721594 | F24: =' JULY IL'!F11+' JULY IL'!F43+' JULY IL'!F75+' JULY IL'!F93 -> 1051 | G24: =' JULY IL'!G11+' JULY IL'!G43+' JULY IL'!G75+' JULY IL'!G93 -> 0 | H24: =' JULY IL'!H11+' JULY IL'!H43+' JULY IL'!H75+' JULY IL'!H102+' JULY IL'!H93 -> 147318.4
A25: JEFF J | B25: I436 | C25: =' JULY IL'!C12+' JULY IL'!C44+' JULY IL'!C76+' JULY IL'!C103 -> 78186.4 | D25: =' JULY IL'!D12+' JULY IL'!D44+' JULY IL'!D76+' JULY IL'!D103 -> 47522.78 | E25: =SUM(C25/D25) -> 1.6452405 | F25: =' JULY IL'!F12+' JULY IL'!F76 -> 594 | G25: =' JULY IL'!G12+' JULY IL'!G76 -> 0 | H25: =' JULY IL'!H12+' JULY IL'!H44+' JULY IL'!H76+' JULY IL'!H103 -> 77592.4
A26: IAIR Z | B26: I462 | C26: =' JULY IL'!C13+' JULY IL'!C45 -> 44282.5 | D26: =' JULY IL'!D13+' JULY IL'!D45 -> 30040.2 | E26: =SUM(C26/D26) -> 1.474108 | F26: =' JULY IL'!F13+' JULY IL'!F45 -> 0 | G26: =' JULY IL'!G13+' JULY IL'!G45 -> 0 | H26: =' JULY IL'!H13+' JULY IL'!H45 -> 44282.5
A27: RICO | B27: I478 | C27: =' JULY IL'!C46+' JULY IL'!C14 -> 6754.19 | D27: =' JULY IL'!D14+' JULY IL'!D46 -> 4109.15 | E27: =SUM(C27/D27) -> 1.6436952 | F27: =' JULY IL'!F14+' JULY IL'!F46 -> 0 | G27: =' JULY IL'!G14+' JULY IL'!G46 -> 0 | H27: =' JULY IL'!H14+' JULY IL'!H46 -> 6754.19
A28: DAN M | B28: I501 | C28: =' JULY IL'!C15+' JULY IL'!C77+' JULY IL'!C47 -> 104001.39 | D28: =' JULY IL'!D15+' JULY IL'!D47+' JULY IL'!D77 -> 69399.34 | E28: =SUM(C28/D28) -> 1.4985934 | F28: =' JULY IL'!F15+' JULY IL'!F47+' JULY IL'!F77 -> 0 | G28: =' JULY IL'!G15+' JULY IL'!G47+' JULY IL'!G77 -> 0 | H28: =' JULY IL'!H15+' JULY IL'!H47+' JULY IL'!H77 -> 104001.39
A29: CHRIS T | B29: I664 | C29: =' JULY IL'!C16+' JULY IL'!C78+' JULY IL'!C48 -> 31717.02 | D29: =+' JULY IL'!D16+' JULY IL'!D48+' JULY IL'!D78 -> 21668.12 | E29: =SUM(C29/D29) -> 1.4637643 | F29: =+' JULY IL'!F16+' JULY IL'!F48+' JULY IL'!F78 -> 0 | G29: =+' JULY IL'!G16+' JULY IL'!G48+' JULY IL'!G78 -> 0 | H29: =' JULY IL'!H16+' JULY IL'!H78+' JULY IL'!H48 -> 31717.02
A30: MARK S | B30: I729 | C30: =+' JULY IL'!C17+' JULY IL'!C49+' JULY IL'!C79 -> 49401.7 | D30: =+' JULY IL'!D17+' JULY IL'!D49+' JULY IL'!D79 -> 32517.38 | E30: =SUM(C30/D30) -> 1.5192399 | F30: =+' JULY IL'!F17+' JULY IL'!F49+' JULY IL'!F79 -> 1575 | G30: =+' JULY IL'!G17+' JULY IL'!G49+' JULY IL'!G79 -> 0 | H30: =+' JULY IL'!H17+' JULY IL'!H49+' JULY IL'!H79 -> 47826.7
A31: ALAN S | B31: I801 | C31: =' JULY IL'!C19+' JULY IL'!C81+' JULY IL'!C92+' JULY IL'!C50 -> 40105.15 | D31: =' JULY IL'!D19+' JULY IL'!D81+' JULY IL'!D92+' JULY IL'!D50 -> 18627.05 | E31: =SUM(C31/D31) -> 2.1530597 | F31: =' JULY IL'!F81+' JULY IL'!F50+' JULY IL'!F92+' JULY IL'!F19 -> 189.9 | G31: =' JULY IL'!G81+' JULY IL'!G50+' JULY IL'!G92+' JULY IL'!G19 -> 0 | H31: =' JULY IL'!H19+' JULY IL'!H81+' JULY IL'!H92+' JULY IL'!H50 -> 39915.25
A32: SAMUEL J | B32: I815 | C32: =' JULY IL'!C20+' JULY IL'!C82+' JULY IL'!C51 -> 16748.72 | D32: =' JULY IL'!D20+' JULY IL'!D82+' JULY IL'!D51 -> 10513.32 | E32: =SUM(C32/D32) -> 1.5930952 | F32: =' JULY IL'!F82+' JULY IL'!F20+' JULY IL'!F51 -> 0 | G32: =' JULY IL'!G82+' JULY IL'!G20+' JULY IL'!G51 -> 577.85 | H32: =' JULY IL'!H20+' JULY IL'!H82+' JULY IL'!H51 -> 16170.87
A33: ANDREY K | B33: I816 | C33: =' JULY IL'!C52 -> 1331.4 | D33: =' JULY IL'!D52 -> 792.1 | E33: =SUM(C33/D33) -> 1.6808484 | F33: =' JULY IL'!F52 -> 0 | G33: =' JULY IL'!G52 -> 0 | H33: =' JULY IL'!H52 -> 1331.4
A34: DAVID S | B34: I830 | C34: =' JULY IL'!C53+' JULY IL'!C21+' JULY IL'!C83 -> 38485.33 | D34: =' JULY IL'!D53+' JULY IL'!D21+' JULY IL'!D83 -> 24800.3 | E34: =SUM(C34/D34) -> 1.5518091 | F34: =' JULY IL'!F53+' JULY IL'!F21+' JULY IL'!F83 -> 0 | G34: =' JULY IL'!G53+' JULY IL'!G21+' JULY IL'!G83 -> 0 | H34: =' JULY IL'!H53+' JULY IL'!H21+' JULY IL'!H83 -> 38485.33
A35: ROSS S | B35: I848 | C35: =' JULY IL'!C22 -> 17341 | D35: =' JULY IL'!D22 -> 10375 | E35: =SUM(C35/D35) -> 1.6714217 | F35: =' JULY IL'!F22 -> 0 | G35: =' JULY IL'!G22 -> 0 | H35: =' JULY IL'!H22 -> 17341
A36: CARL L | B36: I850 | C36: =' JULY IL'!C23+' JULY IL'!C54 -> 6282.25 | D36: =' JULY IL'!D23+' JULY IL'!D54 -> 3633 | E36: =SUM(C36/D36) -> 1.7292183 | F36: =' JULY IL'!F23+' JULY IL'!F54 -> 4139 | G36: =' JULY IL'!G23+' JULY IL'!G54 -> 0 | H36: =' JULY IL'!H23+' JULY IL'!H54 -> 2143.25
A37: ANTOINETTE V | B37: I856 | C37: =' JULY IL'!C94+' JULY IL'!C24+' JULY IL'!C84 -> 22970.95 | D37: =' JULY IL'!D94+' JULY IL'!D24+' JULY IL'!D84 -> 12695.67 | E37: =SUM(C37/D37) -> 1.8093531 | F37: =' JULY IL'!F94+' JULY IL'!F24+' JULY IL'!F84 -> 0 | G37: =' JULY IL'!G94+' JULY IL'!G24+' JULY IL'!G84 -> 256.55 | H37: =' JULY IL'!H94+' JULY IL'!H24+' JULY IL'!H84 -> 22714.4
A38: JAVIER C | B38: I865 | C38: =' JULY IL'!C25+' JULY IL'!C55+' JULY IL'!C85 -> 14771.46 | D38: =' JULY IL'!D25+' JULY IL'!D55+' JULY IL'!D85 -> 8714 | E38: =SUM(C38/D38) -> 1.6951412 | F38: =' JULY IL'!F25+' JULY IL'!F55+' JULY IL'!F85 -> 720 | G38: =' JULY IL'!G25+' JULY IL'!G55+' JULY IL'!G85 -> 854.8 | H38: =' JULY IL'!H25+' JULY IL'!H55+' JULY IL'!H85 -> 13196.66
A39: TIMOTHY C | B39: I867 | C39: =' JULY IL'!C26 -> 15260.42 | D39: =' JULY IL'!D26 -> 9492.5 | E39: =SUM(C39/D39) -> 1.6076292 | F39: =' JULY IL'!F26 -> 0 | G39: =' JULY IL'!G26 -> 371.6 | H39: =' JULY IL'!H26 -> 14888.82
A40: KELLSTEIN G | B40: I879 | C40: =' JULY IL'!C86+' JULY IL'!C27+' JULY IL'!C56 -> 786.5 | D40: =' JULY IL'!D86+' JULY IL'!D27+' JULY IL'!D56 -> 363.5 | E40: =SUM(C40/D40) -> 2.1636864 | F40: =' JULY IL'!F86+' JULY IL'!F27+' JULY IL'!F56 -> 0 | G40: =' JULY IL'!G86+' JULY IL'!G27+' JULY IL'!G56 -> 0 | H40: =' JULY IL'!H86+' JULY IL'!H27+' JULY IL'!H56 -> 786.5
A41: JOSE S | B41: I887 | C41: =' JULY IL'!C57+' JULY IL'!C28 -> 25356.2 | D41: =' JULY IL'!D57+' JULY IL'!D28 -> 14824.76 | E41: =SUM(C41/D41) -> 1.7103953 | F41: =' JULY IL'!F57+' JULY IL'!F28 -> 1652.8 | G41: =' JULY IL'!G57+' JULY IL'!G28 -> 0 | H41: =' JULY IL'!H57+' JULY IL'!H28 -> 23703.4
A42: MARSHALL H | B42: I891 | C42: =' JULY IL'!C58 -> 7597.9 | D42: =' JULY IL'!D58 -> 4154.35 | E42: =SUM(C42/D42) -> 1.8289022 | F42: =' JULY IL'!F58 -> 108 | G42: =' JULY IL'!G58 -> 0 | H42: =' JULY IL'!H58 -> 7489.9
A43: BENJI C | B43: I892 | C43: =' JULY IL'!C59 -> 0 | D43: =' JULY IL'!D59 -> 0 | E43: =SUM(C43/D43) -> #DIV/0! | F43: =' JULY IL'!F59 -> 0 | G43: =' JULY IL'!G59 -> 0 | H43: =' JULY IL'!H59 -> 0
A44: BRONSON B | B44: I893 | C44: =' JULY IL'!C29+' JULY IL'!C60 -> 0 | D44: =' JULY IL'!D29+' JULY IL'!D60 -> 0 | E44: =SUM(C44/D44) -> #DIV/0! | F44: =' JULY IL'!F29 -> 0 | G44: =' JULY IL'!G29+' JULY IL'!G60 -> 0 | H44: =' JULY IL'!H29+' JULY IL'!H60 -> 0
...

Sheet JULY 2026 Totals
A1: =' JULY AZ'!A1 -> 46234
A2: TOTALS
A4: DBW
A6: AZ | C6: =' JULY AZ'!H14 -> 134010.02
A7: IL | C7: =' JULY IL'!H36 -> 588131.47
A8: WI | C8: ='JULY WI'!H23 -> 197867.85
C10: =SUM(C6:C9) -> 920009.34
A12: HELIX -22
A14: AZ | C14: =' JULY AZ'!H23 -> 72111.18
A15: IL | C15: =' JULY IL'!H68 -> 304426.41
A16: WI | C16: ='JULY WI'!H38 -> 0
C17: =SUM(C14:C16) -> 376537.59
A19: HELIX FL - 33
A21: AZ | C21: =' JULY AZ'!H29 -> 3048
A22: IL | C22: =' JULY IL'!H89 -> 304400.07
A23: WI | C23: ='JULY WI'!H49 -> 100
C24: =SUM(C21:C23) -> 307548.07
A26: HELIX TOOL - 44
A28: WI | C28: ='JULY WI'!H57 -> 0
C30: =SUM(C28:C29) -> 0
A32: 4COREBIZ-55
A34: IL | C34: =' JULY IL'!H97 -> 37123.39
A36: STRATUS -77
A38: IL | C38: =' JULY IL'!H104 -> 0
C40: =SUM(C38:C39) -> 0
A43: TOTAL | C43: =C10+C17+C24+C40+C30+C34 -> 1641218.4
A51: BATCH/DATE
A52: 7/6 W/D | B52: 95661.38
A53: 7/7 W/D | B53: 95873.72
A54: 7/8 W/D | B54: 74737.43
A55: 7/9 W/D | B55: 90024.29
A56: 7/10 W/D | B56: 91586.34
A57: 7/13 W/D | B57: 62441.94
A58: 7/14 RETURNS | B58: -6377.82
A59: 7/14 W/D | B59: 59096.89 | D59: =95661.38+0.53+95873.72+0.09+74737.43+0.56+90024.29+0.1+91586.34+0.09+62441.94-6377.82+59096.89+0.06+88000.28+0.6+61466.22+0.62+161557.63+2.65+134646.17+0.06-14606.1-22936.81+101160.84+0.32+92216.36+1.21+63962.26+0.56-7857.37+95445.42+0.25+84422.26+0.06+73569.4+73280.27+0.12+59968.29+0.13-9803.9+43674.99 -> 1641218.4 | E59: SHIPSHEETS
A60: 7/16 W/D | B60: 61466.22 | D60: =C43 -> 1641218.4
A61: 7/17 W/D | B61: 161557.63
A62: 7/20 W/D | B62: 134646.17 | D62: =+D59-D60 -> 0 | E62: DIFF
A63: 7/20 RETURNS | B63: -14606.1
A64: 7/21 COLLECTIONS | B64: -22936.81
...
